Workbook

Sheet Inicio
B2: Modelo de Madurez · Mesa de Servicios de Nueva Generación
B3: PersonalSoft · ITIL v5 · 4 Dimensiones · 17 Prácticas Operativas + 4 de Negocio · Escala N0–N5
B5: ESTRUCTURA DEL ARCHIVO
B6: Hoja | C6: Contenido
B7: Inicio | C7: Esta hoja — instrucciones y estructura general
B8: Listas | C8: Listas paramétricas: tipos de mesa, sectores, herramientas, prioridades, horarios
B9: Rúbrica | C9: Descripción completa de qué significa cada nivel (N0–N5) en cada práctica
B10: SURA_Cotizadores … BCO_GIOTI_4 | C10: 8 hojas de evaluación — una por mesa de servicio
B11: Dashboard | C11: Consolidado visual: barras de nivel global, radar por dimensión y barras comparativas
B13: DIMENSIONES EVALUADAS (ITIL v5) — 4 dimensiones · 17 prácticas operativas
B14: D1 · Organizaciones y Personas | C14: 1. Gobierno de roles (RACI) · 2. Capacidad y dimensionamiento del equipo
B15: D2 · Información y Tecnología | C15: 3. Herramientas y automatización · 4. Gestión del conocimiento (KEDB) · 5. Gestión de integraciones · 6. Monitoreo y gestión de eventos ★
B16: D3 · Socios y Proveedores | C16: 7. Service Desk — punto único de contacto ★ · 8. Catálogo de servicios · 9. SLA / ANS + XLA por prioridad · 10. Disponibilidad y cobertura horaria
B17: D4 · Flujos de Valor y Procesos | C17: 11. Gestión de incidentes · 12. Gestión de solicitudes · 13. Gestión de problemas (causa raíz) · 14. Change Enablement ★ · 15. Transición y onboarding · 16. Mejora continua ★ · 17. CX / NPS / CSAT / XLA
B18: Dimensión de Negocio PS | C18: 18. Salud financiera · 19. Retención y cuenta · 20. NPS / CSAT / XLA · 21. Eficiencia de costo operativo
B19: ★ Nuevas desde ITIL v5 (2026)
B20: ESCALA DE MADUREZ — 6 niveles
B21: N0 · Autoservicio | C21: Portal + KEDB + IA generativa activa. Sin intervención humana.
B22: N1 · Inicial | C22: Reactivo total. Depende de personas, no de procesos. Bus factor alto.
B23: N2 · Administrado | C23: Procesos por mesa, sin estandarizar entre clientes. Nivel mínimo Mesa de Ayuda.
B24: N3 · Definido | C24: Estandarización entre mesas. Roles, RACI, catálogo y ANS documentados. Nivel mínimo Mesa de Soporte.
B25: N4 · Cuantitativo | C25: Gestión basada en datos: ANS medidos, KPIs reales, tendencias analizadas.
B26: N5 · Optimizado | C26: IA activa. Anticipación de problemas, mejora continua automatizada, AIOps.
B28: INSTRUCCIONES DE USO
B29: 1. | C29: En la hoja de cada mesa: diligencia los datos generales y selecciona el nivel actual (N0–N5) para cada práctica usando el dropdown.
B30: 2. | C30: Las celdas en ROJO indican que el nivel actual está por debajo del mínimo esperado para ese tipo de mesa (N2 para Ayuda, N3 para Soporte).
B31: 3. | C31: La columna Evidencia es clave: escribe qué observaste concretamente para sustentar el nivel — no opiniones, hechos.
B32: 4. | C32: El Dashboard consolida automáticamente los niveles de las 8 mesas en gráficas comparativas.
B33: 5. | C33: Consulta la hoja Rúbrica para saber exactamente qué significa cada nivel en cada práctica antes de evaluar.
B34: 6. | C34: La hoja Listas contiene todos los valores de los dropdowns — modifícalos allá para que se actualicen en todo el archivo.

Sheet Listas
B2: Listas paramétricas · Modelo de Madurez v1.0
B3: Modifica los valores en estas listas — se actualizan automáticamente en todo el archivo
B5: Tipo de mesa | C5: Sector | D5: Cliente | E5: Nivel de servicio | F5: N0 activo | G5: Herramienta de tickets | H5: Prioridad de ticket | I5: Horario de servicio
B6: Mesa de Ayuda | C6: Banca | D6: SURA | E6: N0 · Autoservicio | F6: Sí | G6: ServiceNow | H6: Crítico — PDN <1h | I6: L-V 7:30AM–5PM
B7: Mesa de Soporte | C7: Salud (EPS) | D7: Bancolombia | E7: N1 · Inicial | F7: No | G7: Jira Service Management | H7: Alto — múltiples usuarios <4h | I7: L-V 8AM–6PM
C8: Seguros | D8: XM | E8: N2 · Administrado | F8: En construcción | G8: Freshservice | H8: Medio — un usuario, workaround <8h | I8: L-S 7AM–7PM
C9: Retail | D9: AES | E9: N3 · Definido | G9: VMC (SURA) | H9: Bajo — consulta/mejora <24h | I9: 24x7 guardia humana
C10: Manufactura | D10: Medicarte | E10: N4 · Cuantitativo | G10: Computer Associates | I10: 24x7 N0/IA + guardia parcial
C11: Gobierno | D11: Otro | E11: N5 · Optimizado | G11: Zendesk | I11: Best effort
C12: Otro | G12: Azure DevOps
G13: Herramienta propia PS
G14: Sin herramienta definida

Sheet Rúbrica
B2: Rúbrica de evaluación · v1.0 · 17 prácticas operativas + 4 de negocio · Escala N0–N5
B3: 4 Dimensiones ITIL v5: D1 Organizaciones y Personas · D2 Información y Tecnología · D3 Socios y Proveedores · D4 Flujos de Valor y Procesos
B5: # | C5: Práctica | D5: Origen | E5: N0·Autoservicio | F5: N1·Inicial | G5: N2·Administrado | H5: N3·Definido | I5: N4·Cuantitativo | J5: N5·Optimizado
B6: D1 · Organizaciones y Personas — Gobierno, roles y cultura del equipo
B7: 1 | C7: Gobierno de roles (RACI) | D7: Feedback operativo | E7: — | F7: Héroes aislados | G7: Roles informales | H7: RACI documentado: Coordinador, Líder Técnico, Especialista | I7: Desempeño medido por rol, RACI ajustado con datos | J7: IA sugiere reasignación según carga y disponibilidad
B8: 2 | C8: Capacidad y dimensionamiento del equipo | D8: ITIL Foundation | E8: — | F8: Cálculo a ojo | G8: Criterio estático que no se revisa | H8: Calculadora FTE basada en volumen histórico | I8: Se mide % GAP de tiempo muerto y se ajusta capacidad | J8: Dimensionamiento dinámico: IA anticipa picos
B9: D2 · Información y Tecnología — Herramientas, automatización y datos
B10: 3 | C10: Herramientas y automatización | D10: ITIL Foundation | E10: — | F10: Dispersas: Excel, correo, chats | G10: Solo como bitácora | H10: Flujos integrados: escalamiento y notificación automática | I10: Se mide % de automatización e impacto en tiempos | J10: Agentes IA clasifican, sugieren y resuelven tickets
B11: 4 | C11: Gestión del conocimiento (KEDB) | D11: Monitor, Support & Fulfill | E11: KEDB activa y accesible al usuario (base del N0) | F11: En la cabeza — bus factor | G11: Notas aisladas | H11: KEDB centralizada, estructurada y con dueño | I11: Uso correlacionado con reducción de tiempo de resolución | J11: Auto-sugerencia IA antes de que el humano busque
B12: 5 | C12: Gestión de integraciones y entorno de aplicaciones | D12: Feedback operativo | E12: — | F12: Sin documentar | G12: Lista básica sin arquitectura | H12: Mapa de APIs, dependencias y owner documentado | I12: Alertas por criticidad de API afectada | J12: Monitoreo AIOps: detecta caídas antes que el usuario
B13: 6 | C13: Monitoreo y gestión de eventos | D13: Monitor, Support & Fulfill | E13: — | F13: Sin monitoreo. El usuario reporta los problemas | G13: Alertas manuales básicas | H13: Monitoreo sistemático con umbrales y alertas automáticas | I13: Correlación de eventos para detectar patrones | J13: AIOps: predicción y resolución proactiva antes del impacto
B14: D3 · Socios y Proveedores — Niveles de servicio, contratos y límites del alcance
B15: 7 | C15: Service Desk — punto único de contacto | D15: Monitor, Support & Fulfill | E15: — | F15: Sin punto único. Usuarios contactan por cualquier canal | G15: Mesa existe sin roles ni procesos claros | H15: Punto único definido: canales, horarios y escalamiento documentado | I15: Mesa medida como unidad de negocio: ANS, CSAT, costo/ticket | J15: Mesa orquestada por IA: N0 deflecta, N1 clasifica, N2/N3 solo casos complejos
B16: 8 | C16: Catálogo de servicios y límites del alcance | D16: ITIL Service | E16: — | F16: Informal, solo verbal | G16: Firmado y olvidado, desactualizado | H16: Catálogo vivo: el equipo lo usa como referencia real | I16: Costeo por servicio, identifica rentabilidad de cada módulo | J16: Ajuste dinámico según demanda real
B17: 9 | C17: SLA / ANS + XLA por prioridad | D17: ITIL Service | E17: — | F17: No medidos o aspiracionales | G17: Medición manual al recibir reclamo | H17: ANS por prioridad: Crítico <1h · Alto <4h · Medio <8h · Bajo <24h. XLA definido | I17: ANS con análisis de tendencia + XLA correlacionado con experiencia real | J17: Alertas predictivas de ANS + XLA en tiempo real
B18: 10 | C18: Disponibilidad y cobertura horaria | D18: Feedback operativo | E18: N0 activo = cobertura 24x7 para solicitudes frecuentes | F18: Best effort sin compromiso | G18: Horario conocido pero no contractual | H18: Horario pactado (ej. L-V 7:30-5PM), GAP administrativo negociado | I18: Cumplimiento de cobertura medido y reportado al cliente | J18: N0/N1 gestionado por IA fuera de horario: 24x7 efectivo
B19: D4 · Flujos de Valor y Procesos — Soporte, incidentes, cambios, transición y CX
B20: 11 | C20: Gestión de incidentes | D20: Monitor, Support & Fulfill | E20: — | F20: Reactivo / apagar incendios, sin trazabilidad | G20: Registro básico, categorización inconsistente | H20: Proceso estándar de registro, triaje y escalamiento N1→N2→N3 | I20: Tiempos medidos por categoría y nivel con metas claras | J20: Auto-resolución IA: clasifica, sugiere, escala solo si confianza baja
B21: 12 | C21: Gestión de solicitudes | D21: Monitor, Support & Fulfill | E21: Portal N0 resuelve solicitudes frecuentes sin abrir ticket | F21: Mezcladas con incidentes, sin distinción | G21: Flujo completamente manual | H21: Catálogo estándar con tiempos de cumplimiento por tipo | I21: ANS medido en tiempo real por tipo de solicitud | J21: Portal N0 expandido con IA: resuelve y aprende de cada interacción
B22: 13 | C22: Gestión de problemas (causa raíz) | D22: Monitor, Support & Fulfill | E22: — | F22: No existe. Cada incidente se resuelve aislado | G22: A voluntad del analista, sin proceso formal | H22: Análisis formal cuando incidente se repite más de X veces | I22: Se mide reducción de tickets recurrentes tras resolver causa raíz | J22: IA detecta patrones ocultos proactivamente
B23: 14 | C23: Gestión del cambio (Change Enablement) | D23: ITIL Service | E23: — | F23: Cambios en producción sin control ni trazabilidad | G23: Registro básico sin aprobación formal | H23: Proceso documentado: quién solicita, aprueba y despliega (segregación de funciones) | I23: Se mide impacto de cambios en incidentes y se ajusta el proceso | J23: Cambios evaluados automáticamente por IA según riesgo calculado
B24: 15 | C24: Transición y onboarding | D24: ITIL Service | E24: — | F24: Improvisada, se reinventa con cada cliente | G24: Pasos sueltos, no replicables | H24: Playbook exacto: inducción, documentación, acuerdos, KEDB | I24: Métrica 30 días: calidad del arranque medida con datos reales | J24: Plantillas IA aceleran la transición (carga automática)
B25: 16 | C25: Mejora continua del servicio | D25: Collaborate, Assure & Improve | E25: — | F25: Sin proceso de mejora. Solo se reacciona ante crisis | G25: Mejoras identificadas sin priorización ni seguimiento | H25: Backlog de mejoras activo: priorizado con owner y fecha de revisión | I25: Mejoras medidas: antes vs. después con datos reales | J25: IA detecta oportunidades de mejora a partir de patrones de operación
B26: 17 | C26: Experiencia del cliente (CX / NPS / CSAT / XLA) | D26: ITIL Experience | E26: Satisfacción medida por tasa de resolución autónoma (% sin escalar) | F26: Cero quejas = todo OK, sin medición | G26: Encuesta anual esporádica sin seguimiento | H26: CSAT continuo por ticket + XLA: experiencia percibida medida | I26: Cruce operacional: CSAT/XLA correlacionado con tiempos, reincidencia y NPS | J26: CX en tiempo real: ajuste proactivo antes de que la insatisfacción se formalice
B27: Dimensión de Negocio · Éxito comercial y rentabilidad de PS
B28: 18 | C28: Salud financiera del contrato | D28: Negocio PS | E28: — | F28: Pérdida oculta: margen desconocido | G28: Rentabilidad plana, sin optimización | H28: Margen por FTE identificado y monitoreado | I28: Eficiencia de costo medida: costo/ticket | J28: Upselling automatizado: IA detecta oportunidades de expansión
B29: 19 | C29: Retención y crecimiento de cuenta | D29: Negocio PS | E29: — | F29: Riesgo de churn no detectado | G29: Renovación incierta, sin plan de cuenta | H29: Plan de cuenta activo, renovación gestionada proactivamente | I29: Expansión medida: servicios adicionales por cliente | J29: Expansión automática: modelo detecta señales de crecimiento
B30: 20 | C30: NPS / CSAT / XLA del cliente final | D30: Negocio PS | E30: — | F30: Cliente silencioso: no se mide lealtad | G30: Reactivo: solo se actúa ante queja formal | H30: CSAT + XLA sistemáticos, NPS periódico | I30: Promotor activo: cliente referencia el servicio con datos | J30: Predicción de churn: IA detecta señales antes de la queja
B31: 21 | C31: Eficiencia de costo operativo | D31: Negocio PS | E31: — | F31: Costo/ticket alto e invisible | G31: GAP de tiempo muerto sin medir | H31: Costo/ticket calculado y comparado contra línea base | I31: Reducción medida de costo por automatización incremental | J31: Automatización escala sola: costo marginal baja con cada ticket IA

Sheet SURA_Cotizadores
C2: Evaluación de Madurez · Cotizadores
C3: PersonalSoft · SURA · Modelo de Madurez v1.0 · ITIL v5
C5: Nombre de la mesa: | D5: Cotizadores
C6: Cliente: | D6: SURA
C7: Sector: | D7: Banca/Seguros
C8: Tipo de mesa:
C9: ¿N0 activo?: | D9: No
C10: Evaluador:
C11: Fecha de evaluación:
C12: Herramienta de tickets:
C13: Horario de servicio:
C15: Nivel mínimo esperado: | D15: =IF(D8="Mesa de Ayuda","N2 · Administrado",IF(D8="Mesa de Soporte","N3 · Definido","— Seleccionar tipo")) -> — Seleccionar tipo | I15: Nivel global operativo (promedio): | J15: =IFERROR(AVERAGEIF(F20:F39,"<>"),"")
C16: Nivel mínimo (número): | D16: =IF(D8="Mesa de Ayuda",2,IF(D8="Mesa de Soporte",3,0)) -> 0
B18: # | C18: Práctica | D18: Origen | E18: Nivel mínimo esperado | F18: Nivel actual (N0–N5) | G18: Nivel objetivo (N0–N5) | H18: Brecha | I18: Evidencia / observación | J18: Herramienta / Nota
B19: D1 · Organizaciones y Personas
B20: 1 | C20: Gobierno de roles (RACI) | D20: Feedback operativo | E20: =IF($D$8="Mesa de Ayuda","N2 · Administrado",IF($D$8="Mesa de Soporte","N3 · Definido","—")) -> — | H20: =IF(AND(F20<>"",G20<>""),G20-F20,"")
B21: 2 | C21: Capacidad y dimensionamiento del equipo | D21: ITIL Foundation | E21: =IF($D$8="Mesa de Ayuda","N2 · Administrado",IF($D$8="Mesa de Soporte","N3 · Definido","—")) -> — | H21: =IF(AND(F21<>"",G21<>""),G21-F21,"")
B22: D2 · Información y Tecnología
B23: 3 | C23: Herramientas y automatización | D23: ITIL Foundation | E23: =IF($D$8="Mesa de Ayuda","N2 · Administrado",IF($D$8="Mesa de Soporte","N3 · Definido","—")) -> — | H23: =IF(AND(F23<>"",G23<>""),G23-F23,"")
B24: 4 | C24: Gestión del conocimiento (KEDB) | D24: Monitor, Support & Fulfill | E24: =IF($D$8="Mesa de Ayuda","N2 · Administrado",IF($D$8="Mesa de Soporte","N3 · Definido","—")) -> — | H24: =IF(AND(F24<>"",G24<>""),G24-F24,"")
B25: 5 | C25: Gestión de integraciones y entorno de aplicaciones | D25: Feedback operativo | E25: =IF($D$8="Mesa de Ayuda","N2 · Administrado",IF($D$8="Mesa de Soporte","N3 · Definido","—")) -> — | H25: =IF(AND(F25<>"",G25<>""),G25-F25,"")
B26: 6 | C26: Monitoreo y gestión de eventos | D26: Monitor, Support & Fulfill | E26: =IF($D$8="Mesa de Ayuda","N2 · Administrado",IF($D$8="Mesa de Soporte","N3 · Definido","—")) -> — | H26: =IF(AND(F26<>"",G26<>""),G26-F26,"")
B27: D3 · Socios y Proveedores
B28: 7 | C28: Service Desk — punto único de contacto | D28: Monitor, Support & Fulfill | E28: =IF($D$8="Mesa de Ayuda","N2 · Administrado",IF($D$8="Mesa de Soporte","N3 · Definido","—")) -> — | H28: =IF(AND(F28<>"",G28<>""),G28-F28,"")
B29: 8 | C29: Catálogo de servicios y límites del alcance | D29: ITIL Service | E29: =IF($D$8="Mesa de Ayuda","N2 · Administrado",IF($D$8="Mesa de Soporte","N3 · Definido","—")) -> — | H29: =IF(AND(F29<>"",G29<>""),G29-F29,"")
B30: 9 | C30: SLA / ANS + XLA por prioridad | D30: ITIL Service | E30: =IF($D$8="Mesa de Ayuda","N2 · Administrado",IF($D$8="Mesa de Soporte","N3 · Definido","—")) -> — | H30: =IF(AND(F30<>"",G30<>""),G30-F30,"")
B31: 10 | C31: Disponibilidad y cobertura horaria | D31: Feedback operativo | E31: =IF($D$8="Mesa de Ayuda","N2 · Administrado",IF($D$8="Mesa de Soporte","N3 · Definido","—")) -> — | H31: =IF(AND(F31<>"",G31<>""),G31-F31,"")
B32: D4 · Flujos de Valor y Procesos
B33: 11 | C33: Gestión de incidentes | D33: Monitor, Support & Fulfill | E33: =IF($D$8="Mesa de Ayuda","N2 · Administrado",IF($D$8="Mesa de Soporte","N3 · Definido","—")) -> — | H33: =IF(AND(F33<>"",G33<>""),G33-F33,"")
B34: 12 | C34: Gestión de solicitudes | D34: Monitor, Support & Fulfill | E34: =IF($D$8="Mesa de Ayuda","N2 · Administrado",IF($D$8="Mesa de Soporte","N3 · Definido","—")) -> — | H34: =IF(AND(F34<>"",G34<>""),G34-F34,"")
B35: 13 | C35: Gestión de problemas (causa raíz) | D35: Monitor, Support & Fulfill | E35: =IF($D$8="Mesa de Ayuda","N2 · Administrado",IF($D$8="Mesa de Soporte","N3 · Definido","—")) -> — | H35: =IF(AND(F35<>"",G35<>""),G35-F35,"")
B36: 14 | C36: Gestión del cambio (Change Enablement) | D36: ITIL Service | E36: =IF($D$8="Mesa de Ayuda","N2 · Administrado",IF($D$8="Mesa de Soporte","N3 · Definido","—")) -> — | H36: =IF(AND(F36<>"",G36<>""),G36-F36,"")
B37: 15 | C37: Transición y onboarding | D37: ITIL Service | E37: =IF($D$8="Mesa de Ayuda","N2 · Administrado",IF($D$8="Mesa de Soporte","N3 · Definido","—")) -> — | H37: =IF(AND(F37<>"",G37<>""),G37-F37,"")
B38: 16 | C38: Mejora continua del servicio | D38: Collaborate, Assure & Improve | E38: =IF($D$8="Mesa de Ayuda","N2 · Administrado",IF($D$8="Mesa de Soporte","N3 · Definido","—")) -> — | H38: =IF(AND(F38<>"",G38<>""),G38-F38,"")
B39: 17 | C39: Experiencia del cliente (CX / NPS / CSAT / XLA) | D39: ITIL Experience | E39: =IF($D$8="Mesa de Ayuda","N2 · Administrado",IF($D$8="Mesa de Soporte","N3 · Definido","—")) -> — | H39: =IF(AND(F39<>"",G39<>""),G39-F39,"")
B40: Dimensión de Negocio · Éxito comercial y rentabilidad PS
B41: 18 | C41: Salud financiera del contrato | D41: Negocio PS | E41: — | H41: =IF(AND(F41<>"",G41<>""),G41-F41,"")
B42: 19 | C42: Retención y crecimiento de cuenta | D42: Negocio PS | E42: — | H42: =IF(AND(F42<>"",G42<>""),G42-F42,"")
B43: 20 | C43: NPS / CSAT / XLA del cliente final | D43: Negocio PS | E43: — | H43: =IF(AND(F43<>"",G43<>""),G43-F43,"")
B44: 21 | C44: Eficiencia de costo operativo | D44: Negocio PS | E44: — | H44: =IF(AND(F44<>"",G44<>""),G44-F44,"")

Sheet SURA_VentaDigital
C2: Evaluación de Madurez · Venta Canal Digital
C3: PersonalSoft · SURA · Modelo de Madurez v1.0 · ITIL v5
C5: Nombre de la mesa: | D5: Venta Canal Digital
C6: Cliente: | D6: SURA
C7: Sector: | D7: Banca/Seguros
C8: Tipo de mesa:
C9: ¿N0 activo?: | D9: No
C10: Evaluador:
C11: Fecha de evaluación:
C12: Herramienta de tickets:
C13: Horario de servicio:
C15: Nivel mínimo esperado: | D15: =IF(D8="Mesa de Ayuda","N2 · Administrado",IF(D8="Mesa de Soporte","N3 · Definido","— Seleccionar tipo")) -> — Seleccionar tipo | I15: Nivel global operativo (promedio): | J15: =IFERROR(AVERAGEIF(F20:F39,"<>"),"")
C16: Nivel mínimo (número): | D16: =IF(D8="Mesa de Ayuda",2,IF(D8="Mesa de Soporte",3,0)) -> 0
B18: # | C18: Práctica | D18: Origen | E18: Nivel mínimo esperado | F18: Nivel actual (N0–N5) | G18: Nivel objetivo (N0–N5) | H18: Brecha | I18: Evidencia / observación | J18: Herramienta / Nota
B19: D1 · Organizaciones y Personas
B20: 1 | C20: Gobierno de roles (RACI) | D20: Feedback operativo | E20: =IF($D$8="Mesa de Ayuda","N2 · Administrado",IF($D$8="Mesa de Soporte","N3 · Definido","—")) -> — | H20: =IF(AND(F20<>"",G20<>""),G20-F20,"")
B21: 2 | C21: Capacidad y dimensionamiento del equipo | D21: ITIL Foundation | E21: =IF($D$8="Mesa de Ayuda","N2 · Administrado",IF($D$8="Mesa de Soporte","N3 · Definido","—")) -> — | H21: =IF(AND(F21<>"",G21<>""),G21-F21,"")
B22: D2 · Información y Tecnología
B23: 3 | C23: Herramientas y automatización | D23: ITIL Foundation | E23: =IF($D$8="Mesa de Ayuda","N2 · Administrado",IF($D$8="Mesa de Soporte","N3 · Definido","—")) -> — | H23: =IF(AND(F23<>"",G23<>""),G23-F23,"")
B24: 4 | C24: Gestión del conocimiento (KEDB) | D24: Monitor, Support & Fulfill | E24: =IF($D$8="Mesa de Ayuda","N2 · Administrado",IF($D$8="Mesa de Soporte","N3 · Definido","—")) -> — | H24: =IF(AND(F24<>"",G24<>""),G24-F24,"")
B25: 5 | C25: Gestión de integraciones y entorno de aplicaciones | D25: Feedback operativo | E25: =IF($D$8="Mesa de Ayuda","N2 · Administrado",IF($D$8="Mesa de Soporte","N3 · Definido","—")) -> — | H25: =IF(AND(F25<>"",G25<>""),G25-F25,"")
B26: 6 | C26: Monitoreo y gestión de eventos | D26: Monitor, Support & Fulfill | E26: =IF($D$8="Mesa de Ayuda","N2 · Administrado",IF($D$8="Mesa de Soporte","N3 · Definido","—")) -> — | H26: =IF(AND(F26<>"",G26<>""),G26-F26,"")
B27: D3 · Socios y Proveedores
B28: 7 | C28: Service Desk — punto único de contacto | D28: Monitor, Support & Fulfill | E28: =IF($D$8="Mesa de Ayuda","N2 · Administrado",IF($D$8="Mesa de Soporte","N3 · Definido","—")) -> — | H28: =IF(AND(F28<>"",G28<>""),G28-F28,"")
B29: 8 | C29: Catálogo de servicios y límites del alcance | D29: ITIL Service | E29: =IF($D$8="Mesa de Ayuda","N2 · Administrado",IF($D$8="Mesa de Soporte","N3 · Definido","—")) -> — | H29: =IF(AND(F29<>"",G29<>""),G29-F29,"")
B30: 9 | C30: SLA / ANS + XLA por prioridad | D30: ITIL Service | E30: =IF($D$8="Mesa de Ayuda","N2 · Administrado",IF($D$8="Mesa de Soporte","N3 · Definido","—")) -> — | H30: =IF(AND(F30<>"",G30<>""),G30-F30,"")
B31: 10 | C31: Disponibilidad y cobertura horaria | D31: Feedback operativo | E31: =IF($D$8="Mesa de Ayuda","N2 · Administrado",IF($D$8="Mesa de Soporte","N3 · Definido","—")) -> — | H31: =IF(AND(F31<>"",G31<>""),G31-F31,"")
B32: D4 · Flujos de Valor y Procesos
B33: 11 | C33: Gestión de incidentes | D33: Monitor, Support & Fulfill | E33: =IF($D$8="Mesa de Ayuda","N2 · Administrado",IF($D$8="Mesa de Soporte","N3 · Definido","—")) -> — | H33: =IF(AND(F33<>"",G33<>""),G33-F33,"")
B34: 12 | C34: Gestión de solicitudes | D34: Monitor, Support & Fulfill | E34: =IF($D$8="Mesa de Ayuda","N2 · Administrado",IF($D$8="Mesa de Soporte","N3 · Definido","—")) -> — | H34: =IF(AND(F34<>"",G34<>""),G34-F34,"")
B35: 13 | C35: Gestión de problemas (causa raíz) | D35: Monitor, Support & Fulfill | E35: =IF($D$8="Mesa de Ayuda","N2 · Administrado",IF($D$8="Mesa de Soporte","N3 · Definido","—")) -> — | H35: =IF(AND(F35<>"",G35<>""),G35-F35,"")
B36: 14 | C36: Gestión del cambio (Change Enablement) | D36: ITIL Service | E36: =IF($D$8="Mesa de Ayuda","N2 · Administrado",IF($D$8="Mesa de Soporte","N3 · Definido","—")) -> — | H36: =IF(AND(F36<>"",G36<>""),G36-F36,"")
B37: 15 | C37: Transición y onboarding | D37: ITIL Service | E37: =IF($D$8="Mesa de Ayuda","N2 · Administrado",IF($D$8="Mesa de Soporte","N3 · Definido","—")) -> — | H37: =IF(AND(F37<>"",G37<>""),G37-F37,"")
B38: 16 | C38: Mejora continua del servicio | D38: Collaborate, Assure & Improve | E38: =IF($D$8="Mesa de Ayuda","N2 · Administrado",IF($D$8="Mesa de Soporte","N3 · Definido","—")) -> — | H38: =IF(AND(F38<>"",G38<>""),G38-F38,"")
B39: 17 | C39: Experiencia del cliente (CX / NPS / CSAT / XLA) | D39: ITIL Experience | E39: =IF($D$8="Mesa de Ayuda","N2 · Administrado",IF($D$8="Mesa de Soporte","N3 · Definido","—")) -> — | H39: =IF(AND(F39<>"",G39<>""),G39-F39,"")
B40: Dimensión de Negocio · Éxito comercial y rentabilidad PS
B41: 18 | C41: Salud financiera del contrato | D41: Negocio PS | E41: — | H41: =IF(AND(F41<>"",G41<>""),G41-F41,"")
B42: 19 | C42: Retención y crecimiento de cuenta | D42: Negocio PS | E42: — | H42: =IF(AND(F42<>"",G42<>""),G42-F42,"")
B43: 20 | C43: NPS / CSAT / XLA del cliente final | D43: Negocio PS | E43: — | H43: =IF(AND(F43<>"",G43<>""),G43-F43,"")
B44: 21 | C44: Eficiencia de costo operativo | D44: Negocio PS | E44: — | H44: =IF(AND(F44<>"",G44<>""),G44-F44,"")

Sheet SURA_TorreControl
C2: Evaluación de Madurez · Torre de Control
C3: PersonalSoft · SURA · Modelo de Madurez v1.0 · ITIL v5
C5: Nombre de la mesa: | D5: Torre de Control
C6: Cliente: | D6: SURA
C7: Sector: | D7: Banca/Seguros
C8: Tipo de mesa:
C9: ¿N0 activo?: | D9: No
C10: Evaluador:
C11: Fecha de evaluación:
C12: Herramienta de tickets:
C13: Horario de servicio:
C15: Nivel mínimo esperado: | D15: =IF(D8="Mesa de Ayuda","N2 · Administrado",IF(D8="Mesa de Soporte","N3 · Definido","— Seleccionar tipo")) -> — Seleccionar tipo | I15: Nivel global operativo (promedio): | J15: =IFERROR(AVERAGEIF(F20:F39,"<>"),"")
C16: Nivel mínimo (número): | D16: =IF(D8="Mesa de Ayuda",2,IF(D8="Mesa de Soporte",3,0)) -> 0
B18: # | C18: Práctica | D18: Origen | E18: Nivel mínimo esperado | F18: Nivel actual (N0–N5) | G18: Nivel objetivo (N0–N5) | H18: Brecha | I18: Evidencia / observación | J18: Herramienta / Nota
B19: D1 · Organizaciones y Personas
B20: 1 | C20: Gobierno de roles (RACI) | D20: Feedback operativo | E20: =IF($D$8="Mesa de Ayuda","N2 · Administrado",IF($D$8="Mesa de Soporte","N3 · Definido","—")) -> — | H20: =IF(AND(F20<>"",G20<>""),G20-F20,"")
B21: 2 | C21: Capacidad y dimensionamiento del equipo | D21: ITIL Foundation | E21: =IF($D$8="Mesa de Ayuda","N2 · Administrado",IF($D$8="Mesa de Soporte","N3 · Definido","—")) -> — | H21: =IF(AND(F21<>"",G21<>""),G21-F21,"")
B22: D2 · Información y Tecnología
B23: 3 | C23: Herramientas y automatización | D23: ITIL Foundation | E23: =IF($D$8="Mesa de Ayuda","N2 · Administrado",IF($D$8="Mesa de Soporte","N3 · Definido","—")) -> — | H23: =IF(AND(F23<>"",G23<>""),G23-F23,"")
B24: 4 | C24: Gestión del conocimiento (KEDB) | D24: Monitor, Support & Fulfill | E24: =IF($D$8="Mesa de Ayuda","N2 · Administrado",IF($D$8="Mesa de Soporte","N3 · Definido","—")) -> — | H24: =IF(AND(F24<>"",G24<>""),G24-F24,"")
B25: 5 | C25: Gestión de integraciones y entorno de aplicaciones | D25: Feedback operativo | E25: =IF($D$8="Mesa de Ayuda","N2 · Administrado",IF($D$8="Mesa de Soporte","N3 · Definido","—")) -> — | H25: =IF(AND(F25<>"",G25<>""),G25-F25,"")
B26: 6 | C26: Monitoreo y gestión de eventos | D26: Monitor, Support & Fulfill | E26: =IF($D$8="Mesa de Ayuda","N2 · Administrado",IF($D$8="Mesa de Soporte","N3 · Definido","—")) -> — | H26: =IF(AND(F26<>"",G26<>""),G26-F26,"")
B27: D3 · Socios y Proveedores
B28: 7 | C28: Service Desk — punto único de contacto | D28: Monitor, Support & Fulfill | E28: =IF($D$8="Mesa de Ayuda","N2 · Administrado",IF($D$8="Mesa de Soporte","N3 · Definido","—")) -> — | H28: =IF(AND(F28<>"",G28<>""),G28-F28,"")
B29: 8 | C29: Catálogo de servicios y límites del alcance | D29: ITIL Service | E29: =IF($D$8="Mesa de Ayuda","N2 · Administrado",IF($D$8="Mesa de Soporte","N3 · Definido","—")) -> — | H29: =IF(AND(F29<>"",G29<>""),G29-F29,"")
B30: 9 | C30: SLA / ANS + XLA por prioridad | D30: ITIL Service | E30: =IF($D$8="Mesa de Ayuda","N2 · Administrado",IF($D$8="Mesa de Soporte","N3 · Definido","—")) -> — | H30: =IF(AND(F30<>"",G30<>""),G30-F30,"")
B31: 10 | C31: Disponibilidad y cobertura horaria | D31: Feedback operativo | E31: =IF($D$8="Mesa de Ayuda","N2 · Administrado",IF($D$8="Mesa de Soporte","N3 · Definido","—")) -> — | H31: =IF(AND(F31<>"",G31<>""),G31-F31,"")
B32: D4 · Flujos de Valor y Procesos
B33: 11 | C33: Gestión de incidentes | D33: Monitor, Support & Fulfill | E33: =IF($D$8="Mesa de Ayuda","N2 · Administrado",IF($D$8="Mesa de Soporte","N3 · Definido","—")) -> — | H33: =IF(AND(F33<>"",G33<>""),G33-F33,"")
B34: 12 | C34: Gestión de solicitudes | D34: Monitor, Support & Fulfill | E34: =IF($D$8="Mesa de Ayuda","N2 · Administrado",IF($D$8="Mesa de Soporte","N3 · Definido","—")) -> — | H34: =IF(AND(F34<>"",G34<>""),G34-F34,"")
B35: 13 | C35: Gestión de problemas (causa raíz) | D35: Monitor, Support & Fulfill | E35: =IF($D$8="Mesa de Ayuda","N2 · Administrado",IF($D$8="Mesa de Soporte","N3 · Definido","—")) -> — | H35: =IF(AND(F35<>"",G35<>""),G35-F35,"")
B36: 14 | C36: Gestión del cambio (Change Enablement) | D36: ITIL Service | E36: =IF($D$8="Mesa de Ayuda","N2 · Administrado",IF($D$8="Mesa de Soporte","N3 · Definido","—")) -> — | H36: =IF(AND(F36<>"",G36<>""),G36-F36,"")
B37: 15 | C37: Transición y onboarding | D37: ITIL Service | E37: =IF($D$8="Mesa de Ayuda","N2 · Administrado",IF($D$8="Mesa de Soporte","N3 · Definido","—")) -> — | H37: =IF(AND(F37<>"",G37<>""),G37-F37,"")
B38: 16 | C38: Mejora continua del servicio | D38: Collaborate, Assure & Improve | E38: =IF($D$8="Mesa de Ayuda","N2 · Administrado",IF($D$8="Mesa de Soporte","N3 · Definido","—")) -> — | H38: =IF(AND(F38<>"",G38<>""),G38-F38,"")
B39: 17 | C39: Experiencia del cliente (CX / NPS / CSAT / XLA) | D39: ITIL Experience | E39: =IF($D$8="Mesa de Ayuda","N2 · Administrado",IF($D$8="Mesa de Soporte","N3 · Definido","—")) -> — | H39: =IF(AND(F39<>"",G39<>""),G39-F39,"")
B40: Dimensión de Negocio · Éxito comercial y rentabilidad PS
B41: 18 | C41: Salud financiera del contrato | D41: Negocio PS | E41: — | H41: =IF(AND(F41<>"",G41<>""),G41-F41,"")
B42: 19 | C42: Retención y crecimiento de cuenta | D42: Negocio PS | E42: — | H42: =IF(AND(F42<>"",G42<>""),G42-F42,"")
B43: 20 | C43: NPS / CSAT / XLA del cliente final | D43: Negocio PS | E43: — | H43: =IF(AND(F43<>"",G43<>""),G43-F43,"")
B44: 21 | C44: Eficiencia de costo operativo | D44: Negocio PS | E44: — | H44: =IF(AND(F44<>"",G44<>""),G44-F44,"")

Sheet SURA_Mesa4
C2: Evaluación de Madurez · Mesa 4
C3: PersonalSoft · SURA · Modelo de Madurez v1.0 · ITIL v5
C5: Nombre de la mesa: | D5: Mesa 4
C6: Cliente: | D6: SURA
C7: Sector: | D7: Banca/Seguros
C8: Tipo de mesa:
C9: ¿N0 activo?: | D9: No
C10: Evaluador:
C11: Fecha de evaluación:
C12: Herramienta de tickets:
C13: Horario de servicio:
C15: Nivel mínimo esperado: | D15: =IF(D8="Mesa de Ayuda","N2 · Administrado",IF(D8="Mesa de Soporte","N3 · Definido","— Seleccionar tipo")) -> — Seleccionar tipo | I15: Nivel global operativo (promedio): | J15: =IFERROR(AVERAGEIF(F20:F39,"<>"),"")
C16: Nivel mínimo (número): | D16: =IF(D8="Mesa de Ayuda",2,IF(D8="Mesa de Soporte",3,0)) -> 0
B18: # | C18: Práctica | D18: Origen | E18: Nivel mínimo esperado | F18: Nivel actual (N0–N5) | G18: Nivel objetivo (N0–N5) | H18: Brecha | I18: Evidencia / observación | J18: Herramienta / Nota
B19: D1 · Organizaciones y Personas
B20: 1 | C20: Gobierno de roles (RACI) | D20: Feedback operativo | E20: =IF($D$8="Mesa de Ayuda","N2 · Administrado",IF($D$8="Mesa de Soporte","N3 · Definido","—")) -> — | H20: =IF(AND(F20<>"",G20<>""),G20-F20,"")
B21: 2 | C21: Capacidad y dimensionamiento del equipo | D21: ITIL Foundation | E21: =IF($D$8="Mesa de Ayuda","N2 · Administrado",IF($D$8="Mesa de Soporte","N3 · Definido","—")) -> — | H21: =IF(AND(F21<>"",G21<>""),G21-F21,"")
B22: D2 · Información y Tecnología
B23: 3 | C23: Herramientas y automatización | D23: ITIL Foundation | E23: =IF($D$8="Mesa de Ayuda","N2 · Administrado",IF($D$8="Mesa de Soporte","N3 · Definido","—")) -> — | H23: =IF(AND(F23<>"",G23<>""),G23-F23,"")
B24: 4 | C24: Gestión del conocimiento (KEDB) | D24: Monitor, Support & Fulfill | E24: =IF($D$8="Mesa de Ayuda","N2 · Administrado",IF($D$8="Mesa de Soporte","N3 · Definido","—")) -> — | H24: =IF(AND(F24<>"",G24<>""),G24-F24,"")
B25: 5 | C25: Gestión de integraciones y entorno de aplicaciones | D25: Feedback operativo | E25: =IF($D$8="Mesa de Ayuda","N2 · Administrado",IF($D$8="Mesa de Soporte","N3 · Definido","—")) -> — | H25: =IF(AND(F25<>"",G25<>""),G25-F25,"")
B26: 6 | C26: Monitoreo y gestión de eventos | D26: Monitor, Support & Fulfill | E26: =IF($D$8="Mesa de Ayuda","N2 · Administrado",IF($D$8="Mesa de Soporte","N3 · Definido","—")) -> — | H26: =IF(AND(F26<>"",G26<>""),G26-F26,"")
B27: D3 · Socios y Proveedores
B28: 7 | C28: Service Desk — punto único de contacto | D28: Monitor, Support & Fulfill | E28: =IF($D$8="Mesa de Ayuda","N2 · Administrado",IF($D$8="Mesa de Soporte","N3 · Definido","—")) -> — | H28: =IF(AND(F28<>"",G28<>""),G28-F28,"")
B29: 8 | C29: Catálogo de servicios y límites del alcance | D29: ITIL Service | E29: =IF($D$8="Mesa de Ayuda","N2 · Administrado",IF($D$8="Mesa de Soporte","N3 · Definido","—")) -> — | H29: =IF(AND(F29<>"",G29<>""),G29-F29,"")
B30: 9 | C30: SLA / ANS + XLA por prioridad | D30: ITIL Service | E30: =IF($D$8="Mesa de Ayuda","N2 · Administrado",IF($D$8="Mesa de Soporte","N3 · Definido","—")) -> — | H30: =IF(AND(F30<>"",G30<>""),G30-F30,"")
B31: 10 | C31: Disponibilidad y cobertura horaria | D31: Feedback operativo | E31: =IF($D$8="Mesa de Ayuda","N2 · Administrado",IF($D$8="Mesa de Soporte","N3 · Definido","—")) -> — | H31: =IF(AND(F31<>"",G31<>""),G31-F31,"")
B32: D4 · Flujos de Valor y Procesos
B33: 11 | C33: Gestión de incidentes | D33: Monitor, Support & Fulfill | E33: =IF($D$8="Mesa de Ayuda","N2 · Administrado",IF($D$8="Mesa de Soporte","N3 · Definido","—")) -> — | H33: =IF(AND(F33<>"",G33<>""),G33-F33,"")
B34: 12 | C34: Gestión de solicitudes | D34: Monitor, Support & Fulfill | E34: =IF($D$8="Mesa de Ayuda","N2 · Administrado",IF($D$8="Mesa de Soporte","N3 · Definido","—")) -> — | H34: =IF(AND(F34<>"",G34<>""),G34-F34,"")
B35: 13 | C35: Gestión de problemas (causa raíz) | D35: Monitor, Support & Fulfill | E35: =IF($D$8="Mesa de Ayuda","N2 · Administrado",IF($D$8="Mesa de Soporte","N3 · Definido","—")) -> — | H35: =IF(AND(F35<>"",G35<>""),G35-F35,"")
B36: 14 | C36: Gestión del cambio (Change Enablement) | D36: ITIL Service | E36: =IF($D$8="Mesa de Ayuda","N2 · Administrado",IF($D$8="Mesa de Soporte","N3 · Definido","—")) -> — | H36: =IF(AND(F36<>"",G36<>""),G36-F36,"")
B37: 15 | C37: Transición y onboarding | D37: ITIL Service | E37: =IF($D$8="Mesa de Ayuda","N2 · Administrado",IF($D$8="Mesa de Soporte","N3 · Definido","—")) -> — | H37: =IF(AND(F37<>"",G37<>""),G37-F37,"")
B38: 16 | C38: Mejora continua del servicio | D38: Collaborate, Assure & Improve | E38: =IF($D$8="Mesa de Ayuda","N2 · Administrado",IF($D$8="Mesa de Soporte","N3 · Definido","—")) -> — | H38: =IF(AND(F38<>"",G38<>""),G38-F38,"")
B39: 17 | C39: Experiencia del cliente (CX / NPS / CSAT / XLA) | D39: ITIL Experience | E39: =IF($D$8="Mesa de Ayuda","N2 · Administrado",IF($D$8="Mesa de Soporte","N3 · Definido","—")) -> — | H39: =IF(AND(F39<>"",G39<>""),G39-F39,"")
B40: Dimensión de Negocio · Éxito comercial y rentabilidad PS
B41: 18 | C41: Salud financiera del contrato | D41: Negocio PS | E41: — | H41: =IF(AND(F41<>"",G41<>""),G41-F41,"")
B42: 19 | C42: Retención y crecimiento de cuenta | D42: Negocio PS | E42: — | H42: =IF(AND(F42<>"",G42<>""),G42-F42,"")
B43: 20 | C43: NPS / CSAT / XLA del cliente final | D43: Negocio PS | E43: — | H43: =IF(AND(F43<>"",G43<>""),G43-F43,"")
B44: 21 | C44: Eficiencia de costo operativo | D44: Negocio PS | E44: — | H44: =IF(AND(F44<>"",G44<>""),G44-F44,"")

Sheet BCO_GIOTI_1
C2: Evaluación de Madurez · GIOTI 1
C3: PersonalSoft · Bancolombia · Modelo de Madurez v1.0 · ITIL v5
C5: Nombre de la mesa: | D5: GIOTI 1
C6: Cliente: | D6: Bancolombia
C7: Sector: | D7: Banca
C8: Tipo de mesa:
C9: ¿N0 activo?: | D9: No
C10: Evaluador:
C11: Fecha de evaluación:
C12: Herramienta de tickets:
C13: Horario de servicio:
C15: Nivel mínimo esperado: | D15: =IF(D8="Mesa de Ayuda","N2 · Administrado",IF(D8="Mesa de Soporte","N3 · Definido","— Seleccionar tipo")) -> — Seleccionar tipo | I15: Nivel global operativo (promedio): | J15: =IFERROR(AVERAGEIF(F20:F39,"<>"),"")
C16: Nivel mínimo (número): | D16: =IF(D8="Mesa de Ayuda",2,IF(D8="Mesa de Soporte",3,0)) -> 0
B18: # | C18: Práctica | D18: Origen | E18: Nivel mínimo esperado | F18: Nivel actual (N0–N5) | G18: Nivel objetivo (N0–N5) | H18: Brecha | I18: Evidencia / observación | J18: Herramienta / Nota
B19: D1 · Organizaciones y Personas
B20: 1 | C20: Gobierno de roles (RACI) | D20: Feedback operativo | E20: =IF($D$8="Mesa de Ayuda","N2 · Administrado",IF($D$8="Mesa de Soporte","N3 · Definido","—")) -> — | H20: =IF(AND(F20<>"",G20<>""),G20-F20,"")
B21: 2 | C21: Capacidad y dimensionamiento del equipo | D21: ITIL Foundation | E21: =IF($D$8="Mesa de Ayuda","N2 · Administrado",IF($D$8="Mesa de Soporte","N3 · Definido","—")) -> — | H21: =IF(AND(F21<>"",G21<>""),G21-F21,"")
B22: D2 · Información y Tecnología
B23: 3 | C23: Herramientas y automatización | D23: ITIL Foundation | E23: =IF($D$8="Mesa de Ayuda","N2 · Administrado",IF($D$8="Mesa de Soporte","N3 · Definido","—")) -> — | H23: =IF(AND(F23<>"",G23<>""),G23-F23,"")
B24: 4 | C24: Gestión del conocimiento (KEDB) | D24: Monitor, Support & Fulfill | E24: =IF($D$8="Mesa de Ayuda","N2 · Administrado",IF($D$8="Mesa de Soporte","N3 · Definido","—")) -> — | H24: =IF(AND(F24<>"",G24<>""),G24-F24,"")
B25: 5 | C25: Gestión de integraciones y entorno de aplicaciones | D25: Feedback operativo | E25: =IF($D$8="Mesa de Ayuda","N2 · Administrado",IF($D$8="Mesa de Soporte","N3 · Definido","—")) -> — | H25: =IF(AND(F25<>"",G25<>""),G25-F25,"")
B26: 6 | C26: Monitoreo y gestión de eventos | D26: Monitor, Support & Fulfill | E26: =IF($D$8="Mesa de Ayuda","N2 · Administrado",IF($D$8="Mesa de Soporte","N3 · Definido","—")) -> — | H26: =IF(AND(F26<>"",G26<>""),G26-F26,"")
B27: D3 · Socios y Proveedores
B28: 7 | C28: Service Desk — punto único de contacto | D28: Monitor, Support & Fulfill | E28: =IF($D$8="Mesa de Ayuda","N2 · Administrado",IF($D$8="Mesa de Soporte","N3 · Definido","—")) -> — | H28: =IF(AND(F28<>"",G28<>""),G28-F28,"")
B29: 8 | C29: Catálogo de servicios y límites del alcance | D29: ITIL Service | E29: =IF($D$8="Mesa de Ayuda","N2 · Administrado",IF($D$8="Mesa de Soporte","N3 · Definido","—")) -> — | H29: =IF(AND(F29<>"",G29<>""),G29-F29,"")
B30: 9 | C30: SLA / ANS + XLA por prioridad | D30: ITIL Service | E30: =IF($D$8="Mesa de Ayuda","N2 · Administrado",IF($D$8="Mesa de Soporte","N3 · Definido","—")) -> — | H30: =IF(AND(F30<>"",G30<>""),G30-F30,"")
B31: 10 | C31: Disponibilidad y cobertura horaria | D31: Feedback operativo | E31: =IF($D$8="Mesa de Ayuda","N2 · Administrado",IF($D$8="Mesa de Soporte","N3 · Definido","—")) -> — | H31: =IF(AND(F31<>"",G31<>""),G31-F31,"")
B32: D4 · Flujos de Valor y Procesos
B33: 11 | C33: Gestión de incidentes | D33: Monitor, Support & Fulfill | E33: =IF($D$8="Mesa de Ayuda","N2 · Administrado",IF($D$8="Mesa de Soporte","N3 · Definido","—")) -> — | H33: =IF(AND(F33<>"",G33<>""),G33-F33,"")
B34: 12 | C34: Gestión de solicitudes | D34: Monitor, Support & Fulfill | E34: =IF($D$8="Mesa de Ayuda","N2 · Administrado",IF($D$8="Mesa de Soporte","N3 · Definido","—")) -> — | H34: =IF(AND(F34<>"",G34<>""),G34-F34,"")
B35: 13 | C35: Gestión de problemas (causa raíz) | D35: Monitor, Support & Fulfill | E35: =IF($D$8="Mesa de Ayuda","N2 · Administrado",IF($D$8="Mesa de Soporte","N3 · Definido","—")) -> — | H35: =IF(AND(F35<>"",G35<>""),G35-F35,"")
B36: 14 | C36: Gestión del cambio (Change Enablement) | D36: ITIL Service | E36: =IF($D$8="Mesa de Ayuda","N2 · Administrado",IF($D$8="Mesa de Soporte","N3 · Definido","—")) -> — | H36: =IF(AND(F36<>"",G36<>""),G36-F36,"")
B37: 15 | C37: Transición y onboarding | D37: ITIL Service | E37: =IF($D$8="Mesa de Ayuda","N2 · Administrado",IF($D$8="Mesa de Soporte","N3 · Definido","—")) -> — | H37: =IF(AND(F37<>"",G37<>""),G37-F37,"")
B38: 16 | C38: Mejora continua del servicio | D38: Collaborate, Assure & Improve | E38: =IF($D$8="Mesa de Ayuda","N2 · Administrado",IF($D$8="Mesa de Soporte","N3 · Definido","—")) -> — | H38: =IF(AND(F38<>"",G38<>""),G38-F38,"")
B39: 17 | C39: Experiencia del cliente (CX / NPS / CSAT / XLA) | D39: ITIL Experience | E39: =IF($D$8="Mesa de Ayuda","N2 · Administrado",IF($D$8="Mesa de Soporte","N3 · Definido","—")) -> — | H39: =IF(AND(F39<>"",G39<>""),G39-F39,"")
B40: Dimensión de Negocio · Éxito comercial y rentabilidad PS
B41: 18 | C41: Salud financiera del contrato | D41: Negocio PS | E41: — | H41: =IF(AND(F41<>"",G41<>""),G41-F41,"")
B42: 19 | C42: Retención y crecimiento de cuenta | D42: Negocio PS | E42: — | H42: =IF(AND(F42<>"",G42<>""),G42-F42,"")
B43: 20 | C43: NPS / CSAT / XLA del cliente final | D43: Negocio PS | E43: — | H43: =IF(AND(F43<>"",G43<>""),G43-F43,"")
B44: 21 | C44: Eficiencia de costo operativo | D44: Negocio PS | E44: — | H44: =IF(AND(F44<>"",G44<>""),G44-F44,"")

Sheet BCO_GIOTI_2
C2: Evaluación de Madurez · GIOTI 2
C3: PersonalSoft · Bancolombia · Modelo de Madurez v1.0 · ITIL v5
C5: Nombre de la mesa: | D5: GIOTI 2
C6: Cliente: | D6: Bancolombia
C7: Sector: | D7: Banca
C8: Tipo de mesa:
C9: ¿N0 activo?: | D9: No
C10: Evaluador:
C11: Fecha de evaluación:
C12: Herramienta de tickets:
C13: Horario de servicio:
C15: Nivel mínimo esperado: | D15: =IF(D8="Mesa de Ayuda","N2 · Administrado",IF(D8="Mesa de Soporte","N3 · Definido","— Seleccionar tipo")) -> — Seleccionar tipo | I15: Nivel global operativo (promedio): | J15: =IFERROR(AVERAGEIF(F20:F39,"<>"),"")
C16: Nivel mínimo (número): | D16: =IF(D8="Mesa de Ayuda",2,IF(D8="Mesa de Soporte",3,0)) -> 0
B18: # | C18: Práctica | D18: Origen | E18: Nivel mínimo esperado | F18: Nivel actual (N0–N5) | G18: Nivel objetivo (N0–N5) | H18: Brecha | I18: Evidencia / observación | J18: Herramienta / Nota
B19: D1 · Organizaciones y Personas
B20: 1 | C20: Gobierno de roles (RACI) | D20: Feedback operativo | E20: =IF($D$8="Mesa de Ayuda","N2 · Administrado",IF($D$8="Mesa de Soporte","N3 · Definido","—")) -> — | H20: =IF(AND(F20<>"",G20<>""),G20-F20,"")
B21: 2 | C21: Capacidad y dimensionamiento del equipo | D21: ITIL Foundation | E21: =IF($D$8="Mesa de Ayuda","N2 · Administrado",IF($D$8="Mesa de Soporte","N3 · Definido","—")) -> — | H21: =IF(AND(F21<>"",G21<>""),G21-F21,"")
B22: D2 · Información y Tecnología
B23: 3 | C23: Herramientas y automatización | D23: ITIL Foundation | E23: =IF($D$8="Mesa de Ayuda","N2 · Administrado",IF($D$8="Mesa de Soporte","N3 · Definido","—")) -> — | H23: =IF(AND(F23<>"",G23<>""),G23-F23,"")
B24: 4 | C24: Gestión del conocimiento (KEDB) | D24: Monitor, Support & Fulfill | E24: =IF($D$8="Mesa de Ayuda","N2 · Administrado",IF($D$8="Mesa de Soporte","N3 · Definido","—")) -> — | H24: =IF(AND(F24<>"",G24<>""),G24-F24,"")
B25: 5 | C25: Gestión de integraciones y entorno de aplicaciones | D25: Feedback operativo | E25: =IF($D$8="Mesa de Ayuda","N2 · Administrado",IF($D$8="Mesa de Soporte","N3 · Definido","—")) -> — | H25: =IF(AND(F25<>"",G25<>""),G25-F25,"")
B26: 6 | C26: Monitoreo y gestión de eventos | D26: Monitor, Support & Fulfill | E26: =IF($D$8="Mesa de Ayuda","N2 · Administrado",IF($D$8="Mesa de Soporte","N3 · Definido","—")) -> — | H26: =IF(AND(F26<>"",G26<>""),G26-F26,"")
B27: D3 · Socios y Proveedores
B28: 7 | C28: Service Desk — punto único de contacto | D28: Monitor, Support & Fulfill | E28: =IF($D$8="Mesa de Ayuda","N2 · Administrado",IF($D$8="Mesa de Soporte","N3 · Definido","—")) -> — | H28: =IF(AND(F28<>"",G28<>""),G28-F28,"")
B29: 8 | C29: Catálogo de servicios y límites del alcance | D29: ITIL Service | E29: =IF($D$8="Mesa de Ayuda","N2 · Administrado",IF($D$8="Mesa de Soporte","N3 · Definido","—")) -> — | H29: =IF(AND(F29<>"",G29<>""),G29-F29,"")
B30: 9 | C30: SLA / ANS + XLA por prioridad | D30: ITIL Service | E30: =IF($D$8="Mesa de Ayuda","N2 · Administrado",IF($D$8="Mesa de Soporte","N3 · Definido","—")) -> — | H30: =IF(AND(F30<>"",G30<>""),G30-F30,"")
B31: 10 | C31: Disponibilidad y cobertura horaria | D31: Feedback operativo | E31: =IF($D$8="Mesa de Ayuda","N2 · Administrado",IF($D$8="Mesa de Soporte","N3 · Definido","—")) -> — | H31: =IF(AND(F31<>"",G31<>""),G31-F31,"")
B32: D4 · Flujos de Valor y Procesos
B33: 11 | C33: Gestión de incidentes | D33: Monitor, Support & Fulfill | E33: =IF($D$8="Mesa de Ayuda","N2 · Administrado",IF($D$8="Mesa de Soporte","N3 · Definido","—")) -> — | H33: =IF(AND(F33<>"",G33<>""),G33-F33,"")
B34: 12 | C34: Gestión de solicitudes | D34: Monitor, Support & Fulfill | E34: =IF($D$8="Mesa de Ayuda","N2 · Administrado",IF($D$8="Mesa de Soporte","N3 · Definido","—")) -> — | H34: =IF(AND(F34<>"",G34<>""),G34-F34,"")
B35: 13 | C35: Gestión de problemas (causa raíz) | D35: Monitor, Support & Fulfill | E35: =IF($D$8="Mesa de Ayuda","N2 · Administrado",IF($D$8="Mesa de Soporte","N3 · Definido","—")) -> — | H35: =IF(AND(F35<>"",G35<>""),G35-F35,"")
B36: 14 | C36: Gestión del cambio (Change Enablement) | D36: ITIL Service | E36: =IF($D$8="Mesa de Ayuda","N2 · Administrado",IF($D$8="Mesa de Soporte","N3 · Definido","—")) -> — | H36: =IF(AND(F36<>"",G36<>""),G36-F36,"")
B37: 15 | C37: Transición y onboarding | D37: ITIL Service | E37: =IF($D$8="Mesa de Ayuda","N2 · Administrado",IF($D$8="Mesa de Soporte","N3 · Definido","—")) -> — | H37: =IF(AND(F37<>"",G37<>""),G37-F37,"")
B38: 16 | C38: Mejora continua del servicio | D38: Collaborate, Assure & Improve | E38: =IF($D$8="Mesa de Ayuda","N2 · Administrado",IF($D$8="Mesa de Soporte","N3 · Definido","—")) -> — | H38: =IF(AND(F38<>"",G38<>""),G38-F38,"")
B39: 17 | C39: Experiencia del cliente (CX / NPS / CSAT / XLA) | D39: ITIL Experience | E39: =IF($D$8="Mesa de Ayuda","N2 · Administrado",IF($D$8="Mesa de Soporte","N3 · Definido","—")) -> — | H39: =IF(AND(F39<>"",G39<>""),G39-F39,"")
B40: Dimensión de Negocio · Éxito comercial y rentabilidad PS
B41: 18 | C41: Salud financiera del contrato | D41: Negocio PS | E41: — | H41: =IF(AND(F41<>"",G41<>""),G41-F41,"")
B42: 19 | C42: Retención y crecimiento de cuenta | D42: Negocio PS | E42: — | H42: =IF(AND(F42<>"",G42<>""),G42-F42,"")
B43: 20 | C43: NPS / CSAT / XLA del cliente final | D43: Negocio PS | E43: — | H43: =IF(AND(F43<>"",G43<>""),G43-F43,"")
B44: 21 | C44: Eficiencia de costo operativo | D44: Negocio PS | E44: — | H44: =IF(AND(F44<>"",G44<>""),G44-F44,"")

Sheet BCO_GIOTI_3
C2: Evaluación de Madurez · GIOTI 3
C3: PersonalSoft · Bancolombia · Modelo de Madurez v1.0 · ITIL v5
C5: Nombre de la mesa: | D5: GIOTI 3
C6: Cliente: | D6: Bancolombia
C7: Sector: | D7: Banca
C8: Tipo de mesa:
C9: ¿N0 activo?: | D9: No
C10: Evaluador:
C11: Fecha de evaluación:
C12: Herramienta de tickets:
C13: Horario de servicio:
C15: Nivel mínimo esperado: | D15: =IF(D8="Mesa de Ayuda","N2 · Administrado",IF(D8="Mesa de Soporte","N3 · Definido","— Seleccionar tipo")) -> — Seleccionar tipo | I15: Nivel global operativo (promedio): | J15: =IFERROR(AVERAGEIF(F20:F39,"<>"),"")
C16: Nivel mínimo (número): | D16: =IF(D8="Mesa de Ayuda",2,IF(D8="Mesa de Soporte",3,0)) -> 0
B18: # | C18: Práctica | D18: Origen | E18: Nivel mínimo esperado | F18: Nivel actual (N0–N5) | G18: Nivel objetivo (N0–N5) | H18: Brecha | I18: Evidencia / observación | J18: Herramienta / Nota
B19: D1 · Organizaciones y Personas
B20: 1 | C20: Gobierno de roles (RACI) | D20: Feedback operativo | E20: =IF($D$8="Mesa de Ayuda","N2 · Administrado",IF($D$8="Mesa de Soporte","N3 · Definido","—")) -> — | H20: =IF(AND(F20<>"",G20<>""),G20-F20,"")
B21: 2 | C21: Capacidad y dimensionamiento del equipo | D21: ITIL Foundation | E21: =IF($D$8="Mesa de Ayuda","N2 · Administrado",IF($D$8="Mesa de Soporte","N3 · Definido","—")) -> — | H21: =IF(AND(F21<>"",G21<>""),G21-F21,"")
B22: D2 · Información y Tecnología
B23: 3 | C23: Herramientas y automatización | D23: ITIL Foundation | E23: =IF($D$8="Mesa de Ayuda","N2 · Administrado",IF($D$8="Mesa de Soporte","N3 · Definido","—")) -> — | H23: =IF(AND(F23<>"",G23<>""),G23-F23,"")
B24: 4 | C24: Gestión del conocimiento (KEDB) | D24: Monitor, Support & Fulfill | E24: =IF($D$8="Mesa de Ayuda","N2 · Administrado",IF($D$8="Mesa de Soporte","N3 · Definido","—")) -> — | H24: =IF(AND(F24<>"",G24<>""),G24-F24,"")
B25: 5 | C25: Gestión de integraciones y entorno de aplicaciones | D25: Feedback operativo | E25: =IF($D$8="Mesa de Ayuda","N2 · Administrado",IF($D$8="Mesa de Soporte","N3 · Definido","—")) -> — | H25: =IF(AND(F25<>"",G25<>""),G25-F25,"")
B26: 6 | C26: Monitoreo y gestión de eventos | D26: Monitor, Support & Fulfill | E26: =IF($D$8="Mesa de Ayuda","N2 · Administrado",IF($D$8="Mesa de Soporte","N3 · Definido","—")) -> — | H26: =IF(AND(F26<>"",G26<>""),G26-F26,"")
B27: D3 · Socios y Proveedores
B28: 7 | C28: Service Desk — punto único de contacto | D28: Monitor, Support & Fulfill | E28: =IF($D$8="Mesa de Ayuda","N2 · Administrado",IF($D$8="Mesa de Soporte","N3 · Definido","—")) -> — | H28: =IF(AND(F28<>"",G28<>""),G28-F28,"")
B29: 8 | C29: Catálogo de servicios y límites del alcance | D29: ITIL Service | E29: =IF($D$8="Mesa de Ayuda","N2 · Administrado",IF($D$8="Mesa de Soporte","N3 · Definido","—")) -> — | H29: =IF(AND(F29<>"",G29<>""),G29-F29,"")
B30: 9 | C30: SLA / ANS + XLA por prioridad | D30: ITIL Service | E30: =IF($D$8="Mesa de Ayuda","N2 · Administrado",IF($D$8="Mesa de Soporte","N3 · Definido","—")) -> — | H30: =IF(AND(F30<>"",G30<>""),G30-F30,"")
B31: 10 | C31: Disponibilidad y cobertura horaria | D31: Feedback operativo | E31: =IF($D$8="Mesa de Ayuda","N2 · Administrado",IF($D$8="Mesa de Soporte","N3 · Definido","—")) -> — | H31: =IF(AND(F31<>"",G31<>""),G31-F31,"")
B32: D4 · Flujos de Valor y Procesos
B33: 11 | C33: Gestión de incidentes | D33: Monitor, Support & Fulfill | E33: =IF($D$8="Mesa de Ayuda","N2 · Administrado",IF($D$8="Mesa de Soporte","N3 · Definido","—")) -> — | H33: =IF(AND(F33<>"",G33<>""),G33-F33,"")
B34: 12 | C34: Gestión de solicitudes | D34: Monitor, Support & Fulfill | E34: =IF($D$8="Mesa de Ayuda","N2 · Administrado",IF($D$8="Mesa de Soporte","N3 · Definido","—")) -> — | H34: =IF(AND(F34<>"",G34<>""),G34-F34,"")
B35: 13 | C35: Gestión de problemas (causa raíz) | D35: Monitor, Support & Fulfill | E35: =IF($D$8="Mesa de Ayuda","N2 · Administrado",IF($D$8="Mesa de Soporte","N3 · Definido","—")) -> — | H35: =IF(AND(F35<>"",G35<>""),G35-F35,"")
B36: 14 | C36: Gestión del cambio (Change Enablement) | D36: ITIL Service | E36: =IF($D$8="Mesa de Ayuda","N2 · Administrado",IF($D$8="Mesa de Soporte","N3 · Definido","—")) -> — | H36: =IF(AND(F36<>"",G36<>""),G36-F36,"")
B37: 15 | C37: Transición y onboarding | D37: ITIL Service | E37: =IF($D$8="Mesa de Ayuda","N2 · Administrado",IF($D$8="Mesa de Soporte","N3 · Definido","—")) -> — | H37: =IF(AND(F37<>"",G37<>""),G37-F37,"")
B38: 16 | C38: Mejora continua del servicio | D38: Collaborate, Assure & Improve | E38: =IF($D$8="Mesa de Ayuda","N2 · Administrado",IF($D$8="Mesa de Soporte","N3 · Definido","—")) -> — | H38: =IF(AND(F38<>"",G38<>""),G38-F38,"")
B39: 17 | C39: Experiencia del cliente (CX / NPS / CSAT / XLA) | D39: ITIL Experience | E39: =IF($D$8="Mesa de Ayuda","N2 · Administrado",IF($D$8="Mesa de Soporte","N3 · Definido","—")) -> — | H39: =IF(AND(F39<>"",G39<>""),G39-F39,"")
B40: Dimensión de Negocio · Éxito comercial y rentabilidad PS
B41: 18 | C41: Salud financiera del contrato | D41: Negocio PS | E41: — | H41: =IF(AND(F41<>"",G41<>""),G41-F41,"")
B42: 19 | C42: Retención y crecimiento de cuenta | D42: Negocio PS | E42: — | H42: =IF(AND(F42<>"",G42<>""),G42-F42,"")
B43: 20 | C43: NPS / CSAT / XLA del cliente final | D43: Negocio PS | E43: — | H43: =IF(AND(F43<>"",G43<>""),G43-F43,"")
B44: 21 | C44: Eficiencia de costo operativo | D44: Negocio PS | E44: — | H44: =IF(AND(F44<>"",G44<>""),G44-F44,"")

Sheet BCO_GIOTI_4
C2: Evaluación de Madurez · GIOTI 4
C3: PersonalSoft · Bancolombia · Modelo de Madurez v1.0 · ITIL v5
C5: Nombre de la mesa: | D5: GIOTI 4
C6: Cliente: | D6: Bancolombia
C7: Sector: | D7: Banca
C8: Tipo de mesa:
C9: ¿N0 activo?: | D9: No
C10: Evaluador:
C11: Fecha de evaluación:
C12: Herramienta de tickets:
C13: Horario de servicio:
C15: Nivel mínimo esperado: | D15: =IF(D8="Mesa de Ayuda","N2 · Administrado",IF(D8="Mesa de Soporte","N3 · Definido","— Seleccionar tipo")) -> — Seleccionar tipo | I15: Nivel global operativo (promedio): | J15: =IFERROR(AVERAGEIF(F20:F39,"<>"),"")
C16: Nivel mínimo (número): | D16: =IF(D8="Mesa de Ayuda",2,IF(D8="Mesa de Soporte",3,0)) -> 0
B18: # | C18: Práctica | D18: Origen | E18: Nivel mínimo esperado | F18: Nivel actual (N0–N5) | G18: Nivel objetivo (N0–N5) | H18: Brecha | I18: Evidencia / observación | J18: Herramienta / Nota
B19: D1 · Organizaciones y Personas
B20: 1 | C20: Gobierno de roles (RACI) | D20: Feedback operativo | E20: =IF($D$8="Mesa de Ayuda","N2 · Administrado",IF($D$8="Mesa de Soporte","N3 · Definido","—")) -> — | H20: =IF(AND(F20<>"",G20<>""),G20-F20,"")
B21: 2 | C21: Capacidad y dimensionamiento del equipo | D21: ITIL Foundation | E21: =IF($D$8="Mesa de Ayuda","N2 · Administrado",IF($D$8="Mesa de Soporte","N3 · Definido","—")) -> — | H21: =IF(AND(F21<>"",G21<>""),G21-F21,"")
B22: D2 · Información y Tecnología
B23: 3 | C23: Herramientas y automatización | D23: ITIL Foundation | E23: =IF($D$8="Mesa de Ayuda","N2 · Administrado",IF($D$8="Mesa de Soporte","N3 · Definido","—")) -> — | H23: =IF(AND(F23<>"",G23<>""),G23-F23,"")
B24: 4 | C24: Gestión del conocimiento (KEDB) | D24: Monitor, Support & Fulfill | E24: =IF($D$8="Mesa de Ayuda","N2 · Administrado",IF($D$8="Mesa de Soporte","N3 · Definido","—")) -> — | H24: =IF(AND(F24<>"",G24<>""),G24-F24,"")
B25: 5 | C25: Gestión de integraciones y entorno de aplicaciones | D25: Feedback operativo | E25: =IF($D$8="Mesa de Ayuda","N2 · Administrado",IF($D$8="Mesa de Soporte","N3 · Definido","—")) -> — | H25: =IF(AND(F25<>"",G25<>""),G25-F25,"")
B26: 6 | C26: Monitoreo y gestión de eventos | D26: Monitor, Support & Fulfill | E26: =IF($D$8="Mesa de Ayuda","N2 · Administrado",IF($D$8="Mesa de Soporte","N3 · Definido","—")) -> — | H26: =IF(AND(F26<>"",G26<>""),G26-F26,"")
B27: D3 · Socios y Proveedores
B28: 7 | C28: Service Desk — punto único de contacto | D28: Monitor, Support & Fulfill | E28: =IF($D$8="Mesa de Ayuda","N2 · Administrado",IF($D$8="Mesa de Soporte","N3 · Definido","—")) -> — | H28: =IF(AND(F28<>"",G28<>""),G28-F28,"")
B29: 8 | C29: Catálogo de servicios y límites del alcance | D29: ITIL Service | E29: =IF($D$8="Mesa de Ayuda","N2 · Administrado",IF($D$8="Mesa de Soporte","N3 · Definido","—")) -> — | H29: =IF(AND(F29<>"",G29<>""),G29-F29,"")
B30: 9 | C30: SLA / ANS + XLA por prioridad | D30: ITIL Service | E30: =IF($D$8="Mesa de Ayuda","N2 · Administrado",IF($D$8="Mesa de Soporte","N3 · Definido","—")) -> — | H30: =IF(AND(F30<>"",G30<>""),G30-F30,"")
B31: 10 | C31: Disponibilidad y cobertura horaria | D31: Feedback operativo | E31: =IF($D$8="Mesa de Ayuda","N2 · Administrado",IF($D$8="Mesa de Soporte","N3 · Definido","—")) -> — | H31: =IF(AND(F31<>"",G31<>""),G31-F31,"")
B32: D4 · Flujos de Valor y Procesos
B33: 11 | C33: Gestión de incidentes | D33: Monitor, Support & Fulfill | E33: =IF($D$8="Mesa de Ayuda","N2 · Administrado",IF($D$8="Mesa de Soporte","N3 · Definido","—")) -> — | H33: =IF(AND(F33<>"",G33<>""),G33-F33,"")
B34: 12 | C34: Gestión de solicitudes | D34: Monitor, Support & Fulfill | E34: =IF($D$8="Mesa de Ayuda","N2 · Administrado",IF($D$8="Mesa de Soporte","N3 · Definido","—")) -> — | H34: =IF(AND(F34<>"",G34<>""),G34-F34,"")
B35: 13 | C35: Gestión de problemas (causa raíz) | D35: Monitor, Support & Fulfill | E35: =IF($D$8="Mesa de Ayuda","N2 · Administrado",IF($D$8="Mesa de Soporte","N3 · Definido","—")) -> — | H35: =IF(AND(F35<>"",G35<>""),G35-F35,"")
B36: 14 | C36: Gestión del cambio (Change Enablement) | D36: ITIL Service | E36: =IF($D$8="Mesa de Ayuda","N2 · Administrado",IF($D$8="Mesa de Soporte","N3 · Definido","—")) -> — | H36: =IF(AND(F36<>"",G36<>""),G36-F36,"")
B37: 15 | C37: Transición y onboarding | D37: ITIL Service | E37: =IF($D$8="Mesa de Ayuda","N2 · Administrado",IF($D$8="Mesa de Soporte","N3 · Definido","—")) -> — | H37: =IF(AND(F37<>"",G37<>""),G37-F37,"")
B38: 16 | C38: Mejora continua del servicio | D38: Collaborate, Assure & Improve | E38: =IF($D$8="Mesa de Ayuda","N2 · Administrado",IF($D$8="Mesa de Soporte","N3 · Definido","—")) -> — | H38: =IF(AND(F38<>"",G38<>""),G38-F38,"")
B39: 17 | C39: Experiencia del cliente (CX / NPS / CSAT / XLA) | D39: ITIL Experience | E39: =IF($D$8="Mesa de Ayuda","N2 · Administrado",IF($D$8="Mesa de Soporte","N3 · Definido","—")) -> — | H39: =IF(AND(F39<>"",G39<>""),G39-F39,"")
B40: Dimensión de Negocio · Éxito comercial y rentabilidad PS
B41: 18 | C41: Salud financiera del contrato | D41: Negocio PS | E41: — | H41: =IF(AND(F41<>"",G41<>""),G41-F41,"")
B42: 19 | C42: Retención y crecimiento de cuenta | D42: Negocio PS | E42: — | H42: =IF(AND(F42<>"",G42<>""),G42-F42,"")
B43: 20 | C43: NPS / CSAT / XLA del cliente final | D43: Negocio PS | E43: — | H43: =IF(AND(F43<>"",G43<>""),G43-F43,"")
B44: 21 | C44: Eficiencia de costo operativo | D44: Negocio PS | E44: — | H44: =IF(AND(F44<>"",G44<>""),G44-F44,"")

Sheet Dashboard
B2: Dashboard Consolidado · Modelo de Madurez · 8 Mesas de Servicio
B3: PersonalSoft · ITIL v5 · 4 Dimensiones · 17 Prácticas Operativas + 4 Negocio · Escala N0–N5
B5: Mesa de servicio | C5: Cliente | D5: Sector | E5: Tipo de mesa | F5: N0 activo | G5: Nivel global operativo | H5: Nivel global negocio | I5: Gobierno de roles | J5: Capacidad y dimens | K5: Herramientas y aut | L5: Gestión del conoci | M5: Gestión de integra | N5: Monitoreo y gestió | O5: Service Desk — pun | P5: Catálogo de servic | Q5: SLA / ANS + XLA po | R5: Disponibilidad y c | S5: Gestión de inciden | T5: Gestión de solicit | U5: Gestión de problem | V5: Gestión del cambio | W5: Transición y onboa | X5: Mejora continua de | Y5: Experiencia del cl | Z5: Salud financiera d | AA5: Retención y crecim | AB5: NPS / CSAT / XLA d | AC5: Eficiencia de cost
B6: Cotizadores | C6: SURA | D6: Banca/Seguros | E6: =SURA_Cotizadores!D8 -> 0 | F6: =SURA_Cotizadores!D9 -> No | G6: =IFERROR(SURA_Cotizadores!J15,"") | H6: =IFERROR((SURA_Cotizadores!F41+SURA_Cotizadores!F42+SURA_Cotizadores!F43+SURA_Cotizadores!F44)/4,"") -> 0 | I6: =IF(SURA_Cotizadores!F20<>"",SURA_Cotizadores!F20,"") | J6: =IF(SURA_Cotizadores!F21<>"",SURA_Cotizadores!F21,"") | K6: =IF(SURA_Cotizadores!F23<>"",SURA_Cotizadores!F23,"") | L6: =IF(SURA_Cotizadores!F24<>"",SURA_Cotizadores!F24,"") | M6: =IF(SURA_Cotizadores!F25<>"",SURA_Cotizadores!F25,"") | N6: =IF(SURA_Cotizadores!F26<>"",SURA_Cotizadores!F26,"") | O6: =IF(SURA_Cotizadores!F28<>"",SURA_Cotizadores!F28,"") | P6: =IF(SURA_Cotizadores!F29<>"",SURA_Cotizadores!F29,"") | Q6: =IF(SURA_Cotizadores!F30<>"",SURA_Cotizadores!F30,"") | R6: =IF(SURA_Cotizadores!F31<>"",SURA_Cotizadores!F31,"") | S6: =IF(SURA_Cotizadores!F33<>"",SURA_Cotizadores!F33,"") | T6: =IF(SURA_Cotizadores!F34<>"",SURA_Cotizadores!F34,"") | U6: =IF(SURA_Cotizadores!F35<>"",SURA_Cotizadores!F35,"") | V6: =IF(SURA_Cotizadores!F36<>"",SURA_Cotizadores!F36,"") | W6: =IF(SURA_Cotizadores!F37<>"",SURA_Cotizadores!F37,"") | X6: =IF(SURA_Cotizadores!F38<>"",SURA_Cotizadores!F38,"") | Y6: =IF(SURA_Cotizadores!F39<>"",SURA_Cotizadores!F39,"") | Z6: =IF(SURA_Cotizadores!F41<>"",SURA_Cotizadores!F41,"") | AA6: =IF(SURA_Cotizadores!F42<>"",SURA_Cotizadores!F42,"") | AB6: =IF(SURA_Cotizadores!F43<>"",SURA_Cotizadores!F43,"") | AC6: =IF(SURA_Cotizadores!F44<>"",SURA_Cotizadores!F44,"")
B7: Venta Canal Digital | C7: SURA | D7: Banca/Seguros | E7: =SURA_VentaDigital!D8 -> 0 | F7: =SURA_VentaDigital!D9 -> No | G7: =IFERROR(SURA_VentaDigital!J15,"") | H7: =IFERROR((SURA_VentaDigital!F41+SURA_VentaDigital!F42+SURA_VentaDigital!F43+SURA_VentaDigital!F44)/4,"") -> 0 | I7: =IF(SURA_VentaDigital!F20<>"",SURA_VentaDigital!F20,"") | J7: =IF(SURA_VentaDigital!F21<>"",SURA_VentaDigital!F21,"") | K7: =IF(SURA_VentaDigital!F23<>"",SURA_VentaDigital!F23,"") | L7: =IF(SURA_VentaDigital!F24<>"",SURA_VentaDigital!F24,"") | M7: =IF(SURA_VentaDigital!F25<>"",SURA_VentaDigital!F25,"") | N7: =IF(SURA_VentaDigital!F26<>"",SURA_VentaDigital!F26,"") | O7: =IF(SURA_VentaDigital!F28<>"",SURA_VentaDigital!F28,"") | P7: =IF(SURA_VentaDigital!F29<>"",SURA_VentaDigital!F29,"") | Q7: =IF(SURA_VentaDigital!F30<>"",SURA_VentaDigital!F30,"") | R7: =IF(SURA_VentaDigital!F31<>"",SURA_VentaDigital!F31,"") | S7: =IF(SURA_VentaDigital!F33<>"",SURA_VentaDigital!F33,"") | T7: =IF(SURA_VentaDigital!F34<>"",SURA_VentaDigital!F34,"") | U7: =IF(SURA_VentaDigital!F35<>"",SURA_VentaDigital!F35,"") | V7: =IF(SURA_VentaDigital!F36<>"",SURA_VentaDigital!F36,"") | W7: =IF(SURA_VentaDigital!F37<>"",SURA_VentaDigital!F37,"") | X7: =IF(SURA_VentaDigital!F38<>"",SURA_VentaDigital!F38,"") | Y7: =IF(SURA_VentaDigital!F39<>"",SURA_VentaDigital!F39,"") | Z7: =IF(SURA_VentaDigital!F41<>"",SURA_VentaDigital!F41,"") | AA7: =IF(SURA_VentaDigital!F42<>"",SURA_VentaDigital!F42,"") | AB7: =IF(SURA_VentaDigital!F43<>"",SURA_VentaDigital!F43,"") | AC7: =IF(SURA_VentaDigital!F44<>"",SURA_VentaDigital!F44,"")
