Workbook

Sheet Control de Cambios
D3: LEVANTAMIENTO DE MESA DE SERVICIOS
D5: Caracterización y Diagnóstico de Mesas de Servicio Operación Actual | G5: Fecha: 2026/07/03
D6: Versión: | E6: 1.0 | G6: Clasificación: Interna
B9: Elaboró | D9: Revisó | F9: Aprobó
B10: Natalia Zartha Junior Architect
B11: Fecha | D11: Fecha | F11: Fecha
B12: 46206
B14: Fecha | C14: Versión | D14: Descripción
B15: 2026/07/03 | C15: 1 | D15: Versión inicial; levantamiento de información actual de las mesas de servicio
C16: 2
C17: 3
C18: 4
C19: 5

Sheet Instrucciones
D2: LECCIONES APRENDIDAS — MESA DE SERVICIOS DE NUEVA GENERACIÓN
D4: Esta herramienta permite caracterizar la mesa de servicios actual en todas sus dimensiones para diseñar el futuro servicio Gen Next | F4: Fecha: 2026/07/03
D5: Versión: 1.0 | F5: Clasificación: Interna
B8: AGENDA DE LA SESIÓN DE LECCIONES APRENDIDAS (~60 minutos)
B9: # | C9: BLOQUE | D9: TIEMPO | E9: DESCRIPCIÓN
B10: ① | C10: INFORMACIÓN GENERAL | D10: 5 min | E10: Registrar datos básicos de la mesa: cliente, nombre del servicio, líder, ubicación, modalidad, contrato, herramientas y participantes.
B11: ② | C11: IDENTIFICAR NIVEL DE MADUREZ ACTUAL | D11: 5 min | E11: Identificar el nivel de madurez actual de la mesa de servicio de TI en una escala N0–N5, identificando el punto de partida operativo.
B12: ③ | C12: 17 PRÁCTICAS ITIL v4 + DIMENSIONES | D12: 5 min | E12: Revisar el cumplimiento de las prácticas ITIL v4 por las 4 dimensiones: organización/personas, información/tecnología, socios/proveedores y valor/mejora.
B13: ④ | C13: VOLUMETRÍA Y KPIs OPERATIVOS | D13: 5 min | E13: Levantar métricas operativas clave: volumen de tickets, FCR, SLA, backlog, tiempos de atención, escalamiento y desempeño general.
B14: ④b | C14: ④b DISTRIBUCIÓN DE INCIDENTES POR CATEGORÍA | D14: 5 min | E14: Analizar la distribución de incidentes por categoría para identificar patrones, servicios críticos, causas recurrentes y oportunidades de mejora.
B15: ⑤ | C15: EXPERIENCIA DEL USUARIO — XLA / DEX | D15: 5 min | E15: Evaluar la experiencia del usuario final mediante indicadores XLA/DEX, satisfacción, percepción del servicio, puntos de dolor y canales de atención.
B16: ⑥ | C16: DOLORES CRÍTICOS DE LA MESA (D1–D22) | D16: 5 min | E16: Identificar y priorizar los dolores críticos de la mesa, su impacto operativo, evidencias disponibles y nivel de urgencia para intervención.
B17: ⑦ | C17: ROTACIÓN Y TALENTO | D17: 5 min | E17: Revisar rotación, perfiles críticos, capacidades del equipo, clima laboral, brechas de conocimiento y necesidades de formación.
B18: ⑧ | C18: TECNOLOGÍA Y HERRAMIENTAS | D18: 5 min | E18: Evaluar herramientas tecnológicas actuales: ITSM, monitoreo, autoservicio, base de conocimiento, automatización, integraciones y reportes.
B19: ⑨ | C19: MODELO ECONÓMICO ACTUAL | D19: 5 min | E19: Analizar el modelo económico actual: FTEs, costos, esquema contractual, capacidad instalada, eficiencia operativa y posibles oportunidades de optimización.
B20: ⑩ | C20: VISIÓN PARA EL NUEVO SERVICIO — ¿QUÉ DEBERÍA CAMBIAR? | D20: 5 min | E20: Definir la visión objetivo del nuevo servicio: cambios esperados, capacidades Gen Next, automatización, experiencia deseada y prioridades de transformación.
B21: ⑪ | C21: CASOS DE EXITO | D21: 5 min | E21: Documentar casos de éxito, buenas prácticas, aprendizajes reutilizables y elementos que deben conservarse o escalarse en el nuevo modelo.
B23: ESCALA DE MADUREZ — N0 a N5
B24: NIVEL | C24: NOMBRE | D24: DESCRIPCIÓN
B25: N0 | C25: Reactivo / Sin estructura | D25: No existe proceso formal. Todo es manual y reactivo. Sin CMDB ni catálogo.
B26: N1 | C26: Inicial / Ad hoc/ Operación reactiva | D26: Procesos básicos documentados. Herramientas mínimas. Cumplimiento inconsistente.
B27: N2 | C27: Definido / Organización funcional | D27: Procesos ITIL definidos y seguidos. Métricas básicas (SLA (Service Level Agreement), FCR (Fondo de Capital Riesgo)). Equipo estable.
B28: N3 | C28: Gestionado / Gestión por servicios | D28: Métricas avanzadas. Automatización parcial. Gestión proactiva de problemas.
B29: N4 | C29: Optimizado / Gestión integrada | D29: Autoservicio maduro. IA/ML básico. XLA (Experience Level Agreement) medidos. Mejora continua activa.
B30: N5 | C30: Innovador / Diferenciador | D30: IA generativa, predicción, hiper-automatización. Referente del sector.
B32: LEYENDA DE RESPUESTAS — PRÁCTICAS ITIL
B33: RESPUESTA | C33: SIGNIFICADO | D33: COLOR | E33: PUNTAJE
B34: Sí | C34: Cumplimiento completo y documentado | D34: 1F7A4D | E34: 1.0
B35: Parcial | C35: Cumplimiento parcial o en proceso | D35: E07B26 | E35: 0.5
B36: No | C36: No existe o no se cumple | D36: C0392B | E36: 0.0
B37: N/A | C37: No aplica a esta mesa | D37: D9D9D9 | E37: —

Sheet Dashboard
C2: DASHBOARD — MESA DE SERVICIOS DE NUEVA GENERACIÓN | I2: Fecha: 2026/07/03 Clasificación: Interna
C3: Resumen consolidado · Julio 2026 · PersonalSoft
C5: Versión: 1.0
B7: RESUMEN POR MESA DE SERVICIOS — 12 MESAS
B8: MESA | C8: Nivel Madurez | D8: Score Prácticas | E8: FCR (%) | F8: SLA (%) | G8: NPS | H8: FTEs | I8: Dolores Activos | J8: Prioridad Global | K8: Estado
B9: SURA Cotizadores | C9: ='SURA Cotizadores'!C12 -> N2 | D9: =IFERROR('SURA Cotizadores'!E56,0) -> 0.52941176 | E9: =IFERROR('SURA Cotizadores'!C66,0) -> N/D | F9: =IFERROR('SURA Cotizadores'!C68,0) -> 0.7 | G9: =IFERROR('SURA Cotizadores'!C86,0) -> 0 | H9: =IFERROR('SURA Cotizadores'!C72,0) -> 8 | I9: =IF(OR('SURA Cotizadores'!C99="Sí",'SURA Cotizadores'!C99="Si"),1,IF('SURA Cotizadores'!C99="Parcial",0.5,0))+IF(OR('SURA Cotizadores'!C100="Sí",'SURA Cotizadores'!C100="Si"),1,IF('SURA Cotizadores'!C100="Parcial",0.5,0))+IF(OR('SURA Cotizadores'!C101="Sí",'SURA Cotizadores'!C101="Si"),1,IF('SURA Cotizadores'!C101="Parcial",0.5,0))+IF(OR('SURA Cotizadores'!C102="Sí",'SURA Cotizadores'!C102="Si"),1,IF('SURA Cotizadores'!C102="Parcial",0.5,0))+IF(OR('SURA Cotizadores'!C103="Sí",'SURA Cotizadores'!C103="Si"),1,IF('SURA Cotizadores'!C103="Parcial",0.5,0))+IF(OR('SURA Cotizadores'!C104="Sí",'SURA Cotizadores'!C104="Si"),1,IF('SURA Cotizadores'!C104="Parcial",0.5,0))+IF(OR('SURA Cotizadores'!C105="Sí",'SURA Cotizadores'!C105="Si"),1,IF('SURA Cotizadores'!C105="Parcial",0.5,0))+IF(OR('SURA Cotizadores'!C106="Sí",'SURA Cotizadores'!C106="Si"),1,IF('SURA Cotizadores'!C106="Parcial",0.5,0))+IF(OR('SURA Cotizadores'!C107="Sí",'SURA Cotizadores'!C107="Si"),1,IF('SURA Cotizadores'!C107="Parcial",0.5,0))+IF(OR('SURA Cotizadores'!C108="Sí",'SURA Cotizadores'!C108="Si"),1,IF('SURA Cotizadores'!C108="Parcial",0.5,0))+IF(OR('SURA Cotizadores'!C109="Sí",'SURA Cotizadores'!C109="Si"),1,IF('SURA Cotizadores'!C109="Parcial",0.5,0))+IF(OR('SURA Cotizadores'!C110="Sí",'SURA Cotizadores'!C110="Si"),1,IF('SURA Cotizadores'!C110="Parcial",0.5,0))+IF(OR('SURA Cotizadores'!C111="Sí",'SURA Cotizadores'!C111="Si"),1,IF('SURA Cotizadores'!C111="Parcial",0.5,0))+IF(OR('SURA Cotizadores'!C112="Sí",'SURA Cotizadores'!C112="Si"),1,IF('SURA Cotizadores'!C112="Parcial",0.5,0))+IF(OR('SURA Cotizadores'!C113="Sí",'SURA Cotizadores'!C113="Si"),1,IF('SURA Cotizadores'!C113="Parcial",0.5,0))+IF(OR('SURA Cotizadores'!C114="Sí",'SURA Cotizadores'!C114="Si"),1,IF('SURA Cotizadores'!C114="Parcial",0.5,0))+IF(OR('SURA Cotizadores'!C115="Sí",'SURA Cotizadores'!C115="Si"),1,IF('SURA Cotizadores'!C115="Parcial",0.5,0))+IF(OR('SURA Cotizadores'!C116="Sí",'SURA Cotizadores'!C116="Si"),1,IF('SURA Cotizadores'!C116="Parcial",0.5,0))+IF(OR('SURA Cotizadores'!C117="Sí",'SURA Cotizadores'!C117="Si"),1,IF('SURA Cotizadores'!C117="Parcial",0.5,0))+IF(OR('SURA Cotizadores'!C118="Sí",'SURA Cotizadores'!C118="Si"),1,IF('SURA Cotizadores'!C118="Parcial",0.5,0))+IF(OR('SURA Cotizadores'!C119="Sí",'SURA Cotizadores'!C119="Si"),1,IF('SURA Cotizadores'!C119="Parcial",0.5,0))+IF(OR('SURA Cotizadores'!C120="Sí",'SURA Cotizadores'!C120="Si"),1,IF('SURA Cotizadores'!C120="Parcial",0.5,0))+IF(OR('SURA Cotizadores'!C121="Sí",'SURA Cotizadores'!C121="Si"),1,IF('SURA Cotizadores'!C121="Parcial",0.5,0)) -> 13 | J9: =IF(D9<30%,"Alta",IF(D9<60%,"Media","Baja")) -> Media | K9: =IF(D9=0,"Pendiente",IF(D9>=70%,"Fuerte",IF(D9>=40%,"En desarrollo","Crítica"))) -> En desarrollo
B10: SURA Digital Venta | C10: ='SURA Digital Venta'!C13 -> N2 | D10: =IFERROR('SURA Digital Venta'!E57,0) -> 0.55882353 | E10: =IFERROR('SURA Digital Venta'!C67,0) -> N/D | F10: =IFERROR('SURA Digital Venta'!C69,0) -> 0.74 | G10: =IFERROR('SURA Digital Venta'!C90,0) -> 0 | H10: =IFERROR('SURA Digital Venta'!C73,0) -> 2 | I10: =IF(OR('SURA Digital Venta'!C100="Sí",'SURA Digital Venta'!C100="Si"),1,IF('SURA Digital Venta'!C100="Parcial",0.5,0))+IF(OR('SURA Digital Venta'!C101="Sí",'SURA Digital Venta'!C101="Si"),1,IF('SURA Digital Venta'!C101="Parcial",0.5,0))+IF(OR('SURA Digital Venta'!C102="Sí",'SURA Digital Venta'!C102="Si"),1,IF('SURA Digital Venta'!C102="Parcial",0.5,0))+IF(OR('SURA Digital Venta'!C103="Sí",'SURA Digital Venta'!C103="Si"),1,IF('SURA Digital Venta'!C103="Parcial",0.5,0))+IF(OR('SURA Digital Venta'!C104="Sí",'SURA Digital Venta'!C104="Si"),1,IF('SURA Digital Venta'!C104="Parcial",0.5,0))+IF(OR('SURA Digital Venta'!C105="Sí",'SURA Digital Venta'!C105="Si"),1,IF('SURA Digital Venta'!C105="Parcial",0.5,0))+IF(OR('SURA Digital Venta'!C106="Sí",'SURA Digital Venta'!C106="Si"),1,IF('SURA Digital Venta'!C106="Parcial",0.5,0))+IF(OR('SURA Digital Venta'!C107="Sí",'SURA Digital Venta'!C107="Si"),1,IF('SURA Digital Venta'!C107="Parcial",0.5,0))+IF(OR('SURA Digital Venta'!C108="Sí",'SURA Digital Venta'!C108="Si"),1,IF('SURA Digital Venta'!C108="Parcial",0.5,0))+IF(OR('SURA Digital Venta'!C109="Sí",'SURA Digital Venta'!C109="Si"),1,IF('SURA Digital Venta'!C109="Parcial",0.5,0))+IF(OR('SURA Digital Venta'!C110="Sí",'SURA Digital Venta'!C110="Si"),1,IF('SURA Digital Venta'!C110="Parcial",0.5,0))+IF(OR('SURA Digital Venta'!C111="Sí",'SURA Digital Venta'!C111="Si"),1,IF('SURA Digital Venta'!C111="Parcial",0.5,0))+IF(OR('SURA Digital Venta'!C112="Sí",'SURA Digital Venta'!C112="Si"),1,IF('SURA Digital Venta'!C112="Parcial",0.5,0))+IF(OR('SURA Digital Venta'!C113="Sí",'SURA Digital Venta'!C113="Si"),1,IF('SURA Digital Venta'!C113="Parcial",0.5,0))+IF(OR('SURA Digital Venta'!C114="Sí",'SURA Digital Venta'!C114="Si"),1,IF('SURA Digital Venta'!C114="Parcial",0.5,0))+IF(OR('SURA Digital Venta'!C115="Sí",'SURA Digital Venta'!C115="Si"),1,IF('SURA Digital Venta'!C115="Parcial",0.5,0))+IF(OR('SURA Digital Venta'!C116="Sí",'SURA Digital Venta'!C116="Si"),1,IF('SURA Digital Venta'!C116="Parcial",0.5,0))+IF(OR('SURA Digital Venta'!C117="Sí",'SURA Digital Venta'!C117="Si"),1,IF('SURA Digital Venta'!C117="Parcial",0.5,0))+IF(OR('SURA Digital Venta'!C118="Sí",'SURA Digital Venta'!C118="Si"),1,IF('SURA Digital Venta'!C118="Parcial",0.5,0))+IF(OR('SURA Digital Venta'!C119="Sí",'SURA Digital Venta'!C119="Si"),1,IF('SURA Digital Venta'!C119="Parcial",0.5,0))+IF(OR('SURA Digital Venta'!C120="Sí",'SURA Digital Venta'!C120="Si"),1,IF('SURA Digital Venta'!C120="Parcial",0.5,0))+IF(OR('SURA Digital Venta'!C121="Sí",'SURA Digital Venta'!C121="Si"),1,IF('SURA Digital Venta'!C121="Parcial",0.5,0)) -> 12.5 | J10: =IF(D10<30%,"Alta",IF(D10<60%,"Media","Baja")) -> Media | K10: =IF(D10=0,"Pendiente",IF(D10>=70%,"Fuerte",IF(D10>=40%,"En desarrollo","Crítica"))) -> En desarrollo
B11: SURA Automatizacion | C11: ='SURA Automatizacion'!C13 -> N2 | D11: =IFERROR('SURA Automatizacion'!E57,0) -> 0.61764706 | E11: =IFERROR('SURA Automatizacion'!C67,0) -> N/D | F11: =IFERROR('SURA Automatizacion'!C69,0) -> 0.98 | G11: =IFERROR('SURA Automatizacion'!C90,0) -> 0 | H11: =IFERROR('SURA Automatizacion'!C73,0) -> 6 | I11: =IF(OR('SURA Automatizacion'!C100="Sí",'SURA Automatizacion'!C100="Si"),1,IF('SURA Automatizacion'!C100="Parcial",0.5,0))+IF(OR('SURA Automatizacion'!C101="Sí",'SURA Automatizacion'!C101="Si"),1,IF('SURA Automatizacion'!C101="Parcial",0.5,0))+IF(OR('SURA Automatizacion'!C102="Sí",'SURA Automatizacion'!C102="Si"),1,IF('SURA Automatizacion'!C102="Parcial",0.5,0))+IF(OR('SURA Automatizacion'!C103="Sí",'SURA Automatizacion'!C103="Si"),1,IF('SURA Automatizacion'!C103="Parcial",0.5,0))+IF(OR('SURA Automatizacion'!C104="Sí",'SURA Automatizacion'!C104="Si"),1,IF('SURA Automatizacion'!C104="Parcial",0.5,0))+IF(OR('SURA Automatizacion'!C105="Sí",'SURA Automatizacion'!C105="Si"),1,IF('SURA Automatizacion'!C105="Parcial",0.5,0))+IF(OR('SURA Automatizacion'!C106="Sí",'SURA Automatizacion'!C106="Si"),1,IF('SURA Automatizacion'!C106="Parcial",0.5,0))+IF(OR('SURA Automatizacion'!C107="Sí",'SURA Automatizacion'!C107="Si"),1,IF('SURA Automatizacion'!C107="Parcial",0.5,0))+IF(OR('SURA Automatizacion'!C108="Sí",'SURA Automatizacion'!C108="Si"),1,IF('SURA Automatizacion'!C108="Parcial",0.5,0))+IF(OR('SURA Automatizacion'!C109="Sí",'SURA Automatizacion'!C109="Si"),1,IF('SURA Automatizacion'!C109="Parcial",0.5,0))+IF(OR('SURA Automatizacion'!C110="Sí",'SURA Automatizacion'!C110="Si"),1,IF('SURA Automatizacion'!C110="Parcial",0.5,0))+IF(OR('SURA Automatizacion'!C111="Sí",'SURA Automatizacion'!C111="Si"),1,IF('SURA Automatizacion'!C111="Parcial",0.5,0))+IF(OR('SURA Automatizacion'!C112="Sí",'SURA Automatizacion'!C112="Si"),1,IF('SURA Automatizacion'!C112="Parcial",0.5,0))+IF(OR('SURA Automatizacion'!C113="Sí",'SURA Automatizacion'!C113="Si"),1,IF('SURA Automatizacion'!C113="Parcial",0.5,0))+IF(OR('SURA Automatizacion'!C114="Sí",'SURA Automatizacion'!C114="Si"),1,IF('SURA Automatizacion'!C114="Parcial",0.5,0))+IF(OR('SURA Automatizacion'!C115="Sí",'SURA Automatizacion'!C115="Si"),1,IF('SURA Automatizacion'!C115="Parcial",0.5,0))+IF(OR('SURA Automatizacion'!C116="Sí",'SURA Automatizacion'!C116="Si"),1,IF('SURA Automatizacion'!C116="Parcial",0.5,0))+IF(OR('SURA Automatizacion'!C117="Sí",'SURA Automatizacion'!C117="Si"),1,IF('SURA Automatizacion'!C117="Parcial",0.5,0))+IF(OR('SURA Automatizacion'!C118="Sí",'SURA Automatizacion'!C118="Si"),1,IF('SURA Automatizacion'!C118="Parcial",0.5,0))+IF(OR('SURA Automatizacion'!C119="Sí",'SURA Automatizacion'!C119="Si"),1,IF('SURA Automatizacion'!C119="Parcial",0.5,0))+IF(OR('SURA Automatizacion'!C120="Sí",'SURA Automatizacion'!C120="Si"),1,IF('SURA Automatizacion'!C120="Parcial",0.5,0))+IF(OR('SURA Automatizacion'!C121="Sí",'SURA Automatizacion'!C121="Si"),1,IF('SURA Automatizacion'!C121="Parcial",0.5,0)) -> 11 | J11: =IF(D11<30%,"Alta",IF(D11<60%,"Media","Baja")) -> Baja | K11: =IF(D11=0,"Pendiente",IF(D11>=70%,"Fuerte",IF(D11>=40%,"En desarrollo","Crítica"))) -> En desarrollo
B12: SURA Canales Masivos | C12: ='SURA Canales Masivos'!C13 -> N2 | D12: =IFERROR('SURA Canales Masivos'!E57,0) -> 0.58823529 | E12: =IFERROR('SURA Canales Masivos'!C67,0) -> 0 | F12: =IFERROR('SURA Canales Masivos'!C69,0) -> 0.72 | G12: =IFERROR('SURA Canales Masivos'!C90,0) -> 0 | H12: =IFERROR('SURA Canales Masivos'!C73,0) -> 1 | I12: =IF(OR('SURA Canales Masivos'!C100="Sí",'SURA Canales Masivos'!C100="Si"),1,IF('SURA Canales Masivos'!C100="Parcial",0.5,0))+IF(OR('SURA Canales Masivos'!C101="Sí",'SURA Canales Masivos'!C101="Si"),1,IF('SURA Canales Masivos'!C101="Parcial",0.5,0))+IF(OR('SURA Canales Masivos'!C102="Sí",'SURA Canales Masivos'!C102="Si"),1,IF('SURA Canales Masivos'!C102="Parcial",0.5,0))+IF(OR('SURA Canales Masivos'!C103="Sí",'SURA Canales Masivos'!C103="Si"),1,IF('SURA Canales Masivos'!C103="Parcial",0.5,0))+IF(OR('SURA Canales Masivos'!C104="Sí",'SURA Canales Masivos'!C104="Si"),1,IF('SURA Canales Masivos'!C104="Parcial",0.5,0))+IF(OR('SURA Canales Masivos'!C105="Sí",'SURA Canales Masivos'!C105="Si"),1,IF('SURA Canales Masivos'!C105="Parcial",0.5,0))+IF(OR('SURA Canales Masivos'!C106="Sí",'SURA Canales Masivos'!C106="Si"),1,IF('SURA Canales Masivos'!C106="Parcial",0.5,0))+IF(OR('SURA Canales Masivos'!C107="Sí",'SURA Canales Masivos'!C107="Si"),1,IF('SURA Canales Masivos'!C107="Parcial",0.5,0))+IF(OR('SURA Canales Masivos'!C108="Sí",'SURA Canales Masivos'!C108="Si"),1,IF('SURA Canales Masivos'!C108="Parcial",0.5,0))+IF(OR('SURA Canales Masivos'!C109="Sí",'SURA Canales Masivos'!C109="Si"),1,IF('SURA Canales Masivos'!C109="Parcial",0.5,0))+IF(OR('SURA Canales Masivos'!C110="Sí",'SURA Canales Masivos'!C110="Si"),1,IF('SURA Canales Masivos'!C110="Parcial",0.5,0))+IF(OR('SURA Canales Masivos'!C111="Sí",'SURA Canales Masivos'!C111="Si"),1,IF('SURA Canales Masivos'!C111="Parcial",0.5,0))+IF(OR('SURA Canales Masivos'!C112="Sí",'SURA Canales Masivos'!C112="Si"),1,IF('SURA Canales Masivos'!C112="Parcial",0.5,0))+IF(OR('SURA Canales Masivos'!C113="Sí",'SURA Canales Masivos'!C113="Si"),1,IF('SURA Canales Masivos'!C113="Parcial",0.5,0))+IF(OR('SURA Canales Masivos'!C114="Sí",'SURA Canales Masivos'!C114="Si"),1,IF('SURA Canales Masivos'!C114="Parcial",0.5,0))+IF(OR('SURA Canales Masivos'!C115="Sí",'SURA Canales Masivos'!C115="Si"),1,IF('SURA Canales Masivos'!C115="Parcial",0.5,0))+IF(OR('SURA Canales Masivos'!C116="Sí",'SURA Canales Masivos'!C116="Si"),1,IF('SURA Canales Masivos'!C116="Parcial",0.5,0))+IF(OR('SURA Canales Masivos'!C117="Sí",'SURA Canales Masivos'!C117="Si"),1,IF('SURA Canales Masivos'!C117="Parcial",0.5,0))+IF(OR('SURA Canales Masivos'!C118="Sí",'SURA Canales Masivos'!C118="Si"),1,IF('SURA Canales Masivos'!C118="Parcial",0.5,0))+IF(OR('SURA Canales Masivos'!C119="Sí",'SURA Canales Masivos'!C119="Si"),1,IF('SURA Canales Masivos'!C119="Parcial",0.5,0))+IF(OR('SURA Canales Masivos'!C120="Sí",'SURA Canales Masivos'!C120="Si"),1,IF('SURA Canales Masivos'!C120="Parcial",0.5,0))+IF(OR('SURA Canales Masivos'!C121="Sí",'SURA Canales Masivos'!C121="Si"),1,IF('SURA Canales Masivos'!C121="Parcial",0.5,0)) -> 13 | J12: =IF(D12<30%,"Alta",IF(D12<60%,"Media","Baja")) -> Media | K12: =IF(D12=0,"Pendiente",IF(D12>=70%,"Fuerte",IF(D12>=40%,"En desarrollo","Crítica"))) -> En desarrollo
B13: BCO COES Integracion | C13: ='BCO COES Integracion'!C13 -> N1 | D13: =IFERROR('BCO COES Integracion'!E58,0) -> 0.73529412 | E13: =IFERROR('BCO COES Integracion'!C68,0) -> Pendiente revisar líderes técnicos | F13: =IFERROR('BCO COES Integracion'!C70,0) -> No aplica SLA- ANS del Banco y de COES | G13: =IFERROR('BCO COES Integracion'!C91,0) -> 0 | H13: =IFERROR('BCO COES Integracion'!C74,0) -> 7 | I13: =IF(OR('BCO COES Integracion'!C101="Sí",'BCO COES Integracion'!C101="Si"),1,IF('BCO COES Integracion'!C101="Parcial",0.5,0))+IF(OR('BCO COES Integracion'!C102="Sí",'BCO COES Integracion'!C102="Si"),1,IF('BCO COES Integracion'!C102="Parcial",0.5,0))+IF(OR('BCO COES Integracion'!C103="Sí",'BCO COES Integracion'!C103="Si"),1,IF('BCO COES Integracion'!C103="Parcial",0.5,0))+IF(OR('BCO COES Integracion'!C104="Sí",'BCO COES Integracion'!C104="Si"),1,IF('BCO COES Integracion'!C104="Parcial",0.5,0))+IF(OR('BCO COES Integracion'!C105="Sí",'BCO COES Integracion'!C105="Si"),1,IF('BCO COES Integracion'!C105="Parcial",0.5,0))+IF(OR('BCO COES Integracion'!C106="Sí",'BCO COES Integracion'!C106="Si"),1,IF('BCO COES Integracion'!C106="Parcial",0.5,0))+IF(OR('BCO COES Integracion'!C107="Sí",'BCO COES Integracion'!C107="Si"),1,IF('BCO COES Integracion'!C107="Parcial",0.5,0))+IF(OR('BCO COES Integracion'!C108="Sí",'BCO COES Integracion'!C108="Si"),1,IF('BCO COES Integracion'!C108="Parcial",0.5,0))+IF(OR('BCO COES Integracion'!C109="Sí",'BCO COES Integracion'!C109="Si"),1,IF('BCO COES Integracion'!C109="Parcial",0.5,0))+IF(OR('BCO COES Integracion'!C110="Sí",'BCO COES Integracion'!C110="Si"),1,IF('BCO COES Integracion'!C110="Parcial",0.5,0))+IF(OR('BCO COES Integracion'!C111="Sí",'BCO COES Integracion'!C111="Si"),1,IF('BCO COES Integracion'!C111="Parcial",0.5,0))+IF(OR('BCO COES Integracion'!C112="Sí",'BCO COES Integracion'!C112="Si"),1,IF('BCO COES Integracion'!C112="Parcial",0.5,0))+IF(OR('BCO COES Integracion'!C113="Sí",'BCO COES Integracion'!C113="Si"),1,IF('BCO COES Integracion'!C113="Parcial",0.5,0))+IF(OR('BCO COES Integracion'!C114="Sí",'BCO COES Integracion'!C114="Si"),1,IF('BCO COES Integracion'!C114="Parcial",0.5,0))+IF(OR('BCO COES Integracion'!C115="Sí",'BCO COES Integracion'!C115="Si"),1,IF('BCO COES Integracion'!C115="Parcial",0.5,0))+IF(OR('BCO COES Integracion'!C116="Sí",'BCO COES Integracion'!C116="Si"),1,IF('BCO COES Integracion'!C116="Parcial",0.5,0))+IF(OR('BCO COES Integracion'!C117="Sí",'BCO COES Integracion'!C117="Si"),1,IF('BCO COES Integracion'!C117="Parcial",0.5,0))+IF(OR('BCO COES Integracion'!C118="Sí",'BCO COES Integracion'!C118="Si"),1,IF('BCO COES Integracion'!C118="Parcial",0.5,0))+IF(OR('BCO COES Integracion'!C119="Sí",'BCO COES Integracion'!C119="Si"),1,IF('BCO COES Integracion'!C119="Parcial",0.5,0))+IF(OR('BCO COES Integracion'!C120="Sí",'BCO COES Integracion'!C120="Si"),1,IF('BCO COES Integracion'!C120="Parcial",0.5,0))+IF(OR('BCO COES Integracion'!C121="Sí",'BCO COES Integracion'!C121="Si"),1,IF('BCO COES Integracion'!C121="Parcial",0.5,0))+IF(OR('BCO COES Integracion'!C122="Sí",'BCO COES Integracion'!C122="Si"),1,IF('BCO COES Integracion'!C122="Parcial",0.5,0)) -> 9.5 | J13: =IF(D13<30%,"Alta",IF(D13<60%,"Media","Baja")) -> Baja | K13: =IF(D13=0,"Pendiente",IF(D13>=70%,"Fuerte",IF(D13>=40%,"En desarrollo","Crítica"))) -> Fuerte
B14: BCO COES Datos | C14: ='BCO COES Datos'!#REF! -> #REF! | D14: =IFERROR('BCO COES Datos'!E58,0) -> 0.73529412 | E14: =IFERROR('BCO COES Datos'!C68,0) -> Pendiente revisar líderes técnicos | F14: =IFERROR('BCO COES Datos'!C70,0) -> No aplica SLA- ANS del Banco y de COES | G14: =IFERROR('BCO COES Datos'!C91,0) -> 0 | H14: =IFERROR('BCO COES Datos'!C74,0) -> 7 | I14: =IF(OR('BCO COES Datos'!C101="Sí",'BCO COES Datos'!C101="Si"),1,IF('BCO COES Datos'!C101="Parcial",0.5,0))+IF(OR('BCO COES Datos'!C102="Sí",'BCO COES Datos'!C102="Si"),1,IF('BCO COES Datos'!C102="Parcial",0.5,0))+IF(OR('BCO COES Datos'!C103="Sí",'BCO COES Datos'!C103="Si"),1,IF('BCO COES Datos'!C103="Parcial",0.5,0))+IF(OR('BCO COES Datos'!C104="Sí",'BCO COES Datos'!C104="Si"),1,IF('BCO COES Datos'!C104="Parcial",0.5,0))+IF(OR('BCO COES Datos'!C105="Sí",'BCO COES Datos'!C105="Si"),1,IF('BCO COES Datos'!C105="Parcial",0.5,0))+IF(OR('BCO COES Datos'!C106="Sí",'BCO COES Datos'!C106="Si"),1,IF('BCO COES Datos'!C106="Parcial",0.5,0))+IF(OR('BCO COES Datos'!C107="Sí",'BCO COES Datos'!C107="Si"),1,IF('BCO COES Datos'!C107="Parcial",0.5,0))+IF(OR('BCO COES Datos'!C108="Sí",'BCO COES Datos'!C108="Si"),1,IF('BCO COES Datos'!C108="Parcial",0.5,0))+IF(OR('BCO COES Datos'!C109="Sí",'BCO COES Datos'!C109="Si"),1,IF('BCO COES Datos'!C109="Parcial",0.5,0))+IF(OR('BCO COES Datos'!C110="Sí",'BCO COES Datos'!C110="Si"),1,IF('BCO COES Datos'!C110="Parcial",0.5,0))+IF(OR('BCO COES Datos'!C111="Sí",'BCO COES Datos'!C111="Si"),1,IF('BCO COES Datos'!C111="Parcial",0.5,0))+IF(OR('BCO COES Datos'!C112="Sí",'BCO COES Datos'!C112="Si"),1,IF('BCO COES Datos'!C112="Parcial",0.5,0))+IF(OR('BCO COES Datos'!C113="Sí",'BCO COES Datos'!C113="Si"),1,IF('BCO COES Datos'!C113="Parcial",0.5,0))+IF(OR('BCO COES Datos'!C114="Sí",'BCO COES Datos'!C114="Si"),1,IF('BCO COES Datos'!C114="Parcial",0.5,0))+IF(OR('BCO COES Datos'!C115="Sí",'BCO COES Datos'!C115="Si"),1,IF('BCO COES Datos'!C115="Parcial",0.5,0))+IF(OR('BCO COES Datos'!C116="Sí",'BCO COES Datos'!C116="Si"),1,IF('BCO COES Datos'!C116="Parcial",0.5,0))+IF(OR('BCO COES Datos'!C117="Sí",'BCO COES Datos'!C117="Si"),1,IF('BCO COES Datos'!C117="Parcial",0.5,0))+IF(OR('BCO COES Datos'!C118="Sí",'BCO COES Datos'!C118="Si"),1,IF('BCO COES Datos'!C118="Parcial",0.5,0))+IF(OR('BCO COES Datos'!C119="Sí",'BCO COES Datos'!C119="Si"),1,IF('BCO COES Datos'!C119="Parcial",0.5,0))+IF(OR('BCO COES Datos'!C120="Sí",'BCO COES Datos'!C120="Si"),1,IF('BCO COES Datos'!C120="Parcial",0.5,0))+IF(OR('BCO COES Datos'!C121="Sí",'BCO COES Datos'!C121="Si"),1,IF('BCO COES Datos'!C121="Parcial",0.5,0))+IF(OR('BCO COES Datos'!C122="Sí",'BCO COES Datos'!C122="Si"),1,IF('BCO COES Datos'!C122="Parcial",0.5,0)) -> 9.5 | J14: =IF(D14<30%,"Alta",IF(D14<60%,"Media","Baja")) -> Baja | K14: =IF(D14=0,"Pendiente",IF(D14>=70%,"Fuerte",IF(D14>=40%,"En desarrollo","Crítica"))) -> Fuerte
B15: BCO Soporte | C15: ='BCO Soporte'!C13 -> N1 | D15: =IFERROR('BCO Soporte'!E58,0) -> 0.73529412 | E15: =IFERROR('BCO Soporte'!C68,0) -> Pendiente revisar líderes técnicos | F15: =IFERROR('BCO Soporte'!C70,0) -> No aplica SLA- ANS del Banco y de COES | G15: =IFERROR('BCO Soporte'!C91,0) -> 0 | H15: =IFERROR('BCO Soporte'!C74,0) -> 13 | I15: =IF(OR('BCO Soporte'!C102="Sí",'BCO Soporte'!C102="Si"),1,IF('BCO Soporte'!C102="Parcial",0.5,0))+IF(OR('BCO Soporte'!C103="Sí",'BCO Soporte'!C103="Si"),1,IF('BCO Soporte'!C103="Parcial",0.5,0))+IF(OR('BCO Soporte'!C104="Sí",'BCO Soporte'!C104="Si"),1,IF('BCO Soporte'!C104="Parcial",0.5,0))+IF(OR('BCO Soporte'!C105="Sí",'BCO Soporte'!C105="Si"),1,IF('BCO Soporte'!C105="Parcial",0.5,0))+IF(OR('BCO Soporte'!C106="Sí",'BCO Soporte'!C106="Si"),1,IF('BCO Soporte'!C106="Parcial",0.5,0))+IF(OR('BCO Soporte'!C107="Sí",'BCO Soporte'!C107="Si"),1,IF('BCO Soporte'!C107="Parcial",0.5,0))+IF(OR('BCO Soporte'!C108="Sí",'BCO Soporte'!C108="Si"),1,IF('BCO Soporte'!C108="Parcial",0.5,0))+IF(OR('BCO Soporte'!C109="Sí",'BCO Soporte'!C109="Si"),1,IF('BCO Soporte'!C109="Parcial",0.5,0))+IF(OR('BCO Soporte'!C110="Sí",'BCO Soporte'!C110="Si"),1,IF('BCO Soporte'!C110="Parcial",0.5,0))+IF(OR('BCO Soporte'!C111="Sí",'BCO Soporte'!C111="Si"),1,IF('BCO Soporte'!C111="Parcial",0.5,0))+IF(OR('BCO Soporte'!C112="Sí",'BCO Soporte'!C112="Si"),1,IF('BCO Soporte'!C112="Parcial",0.5,0))+IF(OR('BCO Soporte'!C113="Sí",'BCO Soporte'!C113="Si"),1,IF('BCO Soporte'!C113="Parcial",0.5,0))+IF(OR('BCO Soporte'!C114="Sí",'BCO Soporte'!C114="Si"),1,IF('BCO Soporte'!C114="Parcial",0.5,0))+IF(OR('BCO Soporte'!C115="Sí",'BCO Soporte'!C115="Si"),1,IF('BCO Soporte'!C115="Parcial",0.5,0))+IF(OR('BCO Soporte'!C116="Sí",'BCO Soporte'!C116="Si"),1,IF('BCO Soporte'!C116="Parcial",0.5,0))+IF(OR('BCO Soporte'!C117="Sí",'BCO Soporte'!C117="Si"),1,IF('BCO Soporte'!C117="Parcial",0.5,0))+IF(OR('BCO Soporte'!C118="Sí",'BCO Soporte'!C118="Si"),1,IF('BCO Soporte'!C118="Parcial",0.5,0))+IF(OR('BCO Soporte'!C119="Sí",'BCO Soporte'!C119="Si"),1,IF('BCO Soporte'!C119="Parcial",0.5,0))+IF(OR('BCO Soporte'!C120="Sí",'BCO Soporte'!C120="Si"),1,IF('BCO Soporte'!C120="Parcial",0.5,0))+IF(OR('BCO Soporte'!C121="Sí",'BCO Soporte'!C121="Si"),1,IF('BCO Soporte'!C121="Parcial",0.5,0))+IF(OR('BCO Soporte'!C123="Sí",'BCO Soporte'!C123="Si"),1,IF('BCO Soporte'!C123="Parcial",0.5,0)) -> 9 | J15: =IF(D15<30%,"Alta",IF(D15<60%,"Media","Baja")) -> Baja | K15: =IF(D15=0,"Pendiente",IF(D15>=70%,"Fuerte",IF(D15>=40%,"En desarrollo","Crítica"))) -> Fuerte
B16: BCO COES Emma | C16: ='BCO COES Emma'!C13 -> N1 | D16: =IFERROR('BCO COES Emma'!E58,0) -> 0.73529412 | E16: =IFERROR('BCO COES Emma'!C68,0) -> 0 | F16: =IFERROR('BCO COES Emma'!C70,0) -> No aplica SLA- ANS del Banco y de COES | G16: =IFERROR('BCO COES Emma'!C91,0) -> 0 | H16: =IFERROR('BCO COES Emma'!C74,0) -> 4 | I16: =IF(OR('BCO COES Emma'!C101="Sí",'BCO COES Emma'!C101="Si"),1,IF('BCO COES Emma'!C101="Parcial",0.5,0))+IF(OR('BCO COES Emma'!C102="Sí",'BCO COES Emma'!C102="Si"),1,IF('BCO COES Emma'!C102="Parcial",0.5,0))+IF(OR('BCO COES Emma'!C103="Sí",'BCO COES Emma'!C103="Si"),1,IF('BCO COES Emma'!C103="Parcial",0.5,0))+IF(OR('BCO COES Emma'!C104="Sí",'BCO COES Emma'!C104="Si"),1,IF('BCO COES Emma'!C104="Parcial",0.5,0))+IF(OR('BCO COES Emma'!C105="Sí",'BCO COES Emma'!C105="Si"),1,IF('BCO COES Emma'!C105="Parcial",0.5,0))+IF(OR('BCO COES Emma'!C106="Sí",'BCO COES Emma'!C106="Si"),1,IF('BCO COES Emma'!C106="Parcial",0.5,0))+IF(OR('BCO COES Emma'!C107="Sí",'BCO COES Emma'!C107="Si"),1,IF('BCO COES Emma'!C107="Parcial",0.5,0))+IF(OR('BCO COES Emma'!C108="Sí",'BCO COES Emma'!C108="Si"),1,IF('BCO COES Emma'!C108="Parcial",0.5,0))+IF(OR('BCO COES Emma'!C109="Sí",'BCO COES Emma'!C109="Si"),1,IF('BCO COES Emma'!C109="Parcial",0.5,0))+IF(OR('BCO COES Emma'!C110="Sí",'BCO COES Emma'!C110="Si"),1,IF('BCO COES Emma'!C110="Parcial",0.5,0))+IF(OR('BCO COES Emma'!C111="Sí",'BCO COES Emma'!C111="Si"),1,IF('BCO COES Emma'!C111="Parcial",0.5,0))+IF(OR('BCO COES Emma'!C112="Sí",'BCO COES Emma'!C112="Si"),1,IF('BCO COES Emma'!C112="Parcial",0.5,0))+IF(OR('BCO COES Emma'!C113="Sí",'BCO COES Emma'!C113="Si"),1,IF('BCO COES Emma'!C113="Parcial",0.5,0))+IF(OR('BCO COES Emma'!C114="Sí",'BCO COES Emma'!C114="Si"),1,IF('BCO COES Emma'!C114="Parcial",0.5,0))+IF(OR('BCO COES Emma'!C115="Sí",'BCO COES Emma'!C115="Si"),1,IF('BCO COES Emma'!C115="Parcial",0.5,0))+IF(OR('BCO COES Emma'!C116="Sí",'BCO COES Emma'!C116="Si"),1,IF('BCO COES Emma'!C116="Parcial",0.5,0))+IF(OR('BCO COES Emma'!C117="Sí",'BCO COES Emma'!C117="Si"),1,IF('BCO COES Emma'!C117="Parcial",0.5,0))+IF(OR('BCO COES Emma'!C118="Sí",'BCO COES Emma'!C118="Si"),1,IF('BCO COES Emma'!C118="Parcial",0.5,0))+IF(OR('BCO COES Emma'!C119="Sí",'BCO COES Emma'!C119="Si"),1,IF('BCO COES Emma'!C119="Parcial",0.5,0))+IF(OR('BCO COES Emma'!C120="Sí",'BCO COES Emma'!C120="Si"),1,IF('BCO COES Emma'!C120="Parcial",0.5,0))+IF(OR('BCO COES Emma'!C121="Sí",'BCO COES Emma'!C121="Si"),1,IF('BCO COES Emma'!C121="Parcial",0.5,0))+IF(OR('BCO COES Emma'!C122="Sí",'BCO COES Emma'!C122="Si"),1,IF('BCO COES Emma'!C122="Parcial",0.5,0)) -> 9.5 | J16: =IF(D16<30%,"Alta",IF(D16<60%,"Media","Baja")) -> Baja | K16: =IF(D16=0,"Pendiente",IF(D16>=70%,"Fuerte",IF(D16>=40%,"En desarrollo","Crítica"))) -> Fuerte
B17: BCO Emma Iseries | C17: ='BCO Emma Iseries'!C13 -> N1 | D17: =IFERROR('BCO Emma Iseries'!E58,0) -> 0.73529412 | E17: =IFERROR('BCO Emma Iseries'!C68,0) -> 0 | F17: =IFERROR('BCO Emma Iseries'!C70,0) -> No aplica SLA- ANS del Banco y de COES | G17: =IFERROR('BCO Emma Iseries'!C91,0) -> 0 | H17: =IFERROR('BCO Emma Iseries'!C74,0) -> 1 | I17: =IF(OR('BCO Emma Iseries'!C101="Sí",'BCO Emma Iseries'!C101="Si"),1,IF('BCO Emma Iseries'!C101="Parcial",0.5,0))+IF(OR('BCO Emma Iseries'!C102="Sí",'BCO Emma Iseries'!C102="Si"),1,IF('BCO Emma Iseries'!C102="Parcial",0.5,0))+IF(OR('BCO Emma Iseries'!C103="Sí",'BCO Emma Iseries'!C103="Si"),1,IF('BCO Emma Iseries'!C103="Parcial",0.5,0))+IF(OR('BCO Emma Iseries'!C104="Sí",'BCO Emma Iseries'!C104="Si"),1,IF('BCO Emma Iseries'!C104="Parcial",0.5,0))+IF(OR('BCO Emma Iseries'!C105="Sí",'BCO Emma Iseries'!C105="Si"),1,IF('BCO Emma Iseries'!C105="Parcial",0.5,0))+IF(OR('BCO Emma Iseries'!C106="Sí",'BCO Emma Iseries'!C106="Si"),1,IF('BCO Emma Iseries'!C106="Parcial",0.5,0))+IF(OR('BCO Emma Iseries'!C107="Sí",'BCO Emma Iseries'!C107="Si"),1,IF('BCO Emma Iseries'!C107="Parcial",0.5,0))+IF(OR('BCO Emma Iseries'!C108="Sí",'BCO Emma Iseries'!C108="Si"),1,IF('BCO Emma Iseries'!C108="Parcial",0.5,0))+IF(OR('BCO Emma Iseries'!C109="Sí",'BCO Emma Iseries'!C109="Si"),1,IF('BCO Emma Iseries'!C109="Parcial",0.5,0))+IF(OR('BCO Emma Iseries'!C110="Sí",'BCO Emma Iseries'!C110="Si"),1,IF('BCO Emma Iseries'!C110="Parcial",0.5,0))+IF(OR('BCO Emma Iseries'!C111="Sí",'BCO Emma Iseries'!C111="Si"),1,IF('BCO Emma Iseries'!C111="Parcial",0.5,0))+IF(OR('BCO Emma Iseries'!C112="Sí",'BCO Emma Iseries'!C112="Si"),1,IF('BCO Emma Iseries'!C112="Parcial",0.5,0))+IF(OR('BCO Emma Iseries'!C113="Sí",'BCO Emma Iseries'!C113="Si"),1,IF('BCO Emma Iseries'!C113="Parcial",0.5,0))+IF(OR('BCO Emma Iseries'!C114="Sí",'BCO Emma Iseries'!C114="Si"),1,IF('BCO Emma Iseries'!C114="Parcial",0.5,0))+IF(OR('BCO Emma Iseries'!C115="Sí",'BCO Emma Iseries'!C115="Si"),1,IF('BCO Emma Iseries'!C115="Parcial",0.5,0))+IF(OR('BCO Emma Iseries'!C116="Sí",'BCO Emma Iseries'!C116="Si"),1,IF('BCO Emma Iseries'!C116="Parcial",0.5,0))+IF(OR('BCO Emma Iseries'!C117="Sí",'BCO Emma Iseries'!C117="Si"),1,IF('BCO Emma Iseries'!C117="Parcial",0.5,0))+IF(OR('BCO Emma Iseries'!C118="Sí",'BCO Emma Iseries'!C118="Si"),1,IF('BCO Emma Iseries'!C118="Parcial",0.5,0))+IF(OR('BCO Emma Iseries'!C119="Sí",'BCO Emma Iseries'!C119="Si"),1,IF('BCO Emma Iseries'!C119="Parcial",0.5,0))+IF(OR('BCO Emma Iseries'!C120="Sí",'BCO Emma Iseries'!C120="Si"),1,IF('BCO Emma Iseries'!C120="Parcial",0.5,0))+IF(OR('BCO Emma Iseries'!C121="Sí",'BCO Emma Iseries'!C121="Si"),1,IF('BCO Emma Iseries'!C121="Parcial",0.5,0))+IF(OR('BCO Emma Iseries'!C122="Sí",'BCO Emma Iseries'!C122="Si"),1,IF('BCO Emma Iseries'!C122="Parcial",0.5,0)) -> 2 | J17: =IF(D17<30%,"Alta",IF(D17<60%,"Media","Baja")) -> Baja | K17: =IF(D17=0,"Pendiente",IF(D17>=70%,"Fuerte",IF(D17>=40%,"En desarrollo","Crítica"))) -> Fuerte
B18: AES | C18: =AES!C13 -> N1 | D18: =IFERROR(AES!E57,0) -> 0.29411765 | E18: =IFERROR(AES!C62,0) -> 0 | F18: =IFERROR(AES!C64,0) -> 0 | G18: =IFERROR(AES!C85,0) -> 0 | H18: =IFERROR(AES!C11,0) -> 4 | I18: =ChartData!AT12 -> 7 | J18: =IF(D18<30%,"Alta",IF(D18<60%,"Media","Baja")) -> Alta | K18: =IF(D18=0,"Pendiente",IF(D18>=70%,"Fuerte",IF(D18>=40%,"En desarrollo","Crítica"))) -> Crítica
B19: XM | C19: =XM!C13 -> N2 | D19: =IFERROR(XM!E57,0) -> 0.5 | E19: =IFERROR(XM!C68,0) -> 0 | F19: =IFERROR(XM!C70,0) -> 0 | G19: =IFERROR(XM!C91,0) -> 0 | H19: =IFERROR(XM!C11,0) -> 4 | I19: =ChartData!AT13 -> 16 | J19: =IF(D19<30%,"Alta",IF(D19<60%,"Media","Baja")) -> Media | K19: =IF(D19=0,"Pendiente",IF(D19>=70%,"Fuerte",IF(D19>=40%,"En desarrollo","Crítica"))) -> En desarrollo
B20: MEDICARTE | C20: =MEDICARTE!C13 -> 0 | D20: =IFERROR(MEDICARTE!E57,0) -> 0 | E20: =IFERROR(MEDICARTE!C62,0) -> 0 | F20: =IFERROR(MEDICARTE!C64,0) -> 0 | G20: =IFERROR(MEDICARTE!C85,0) -> 0 | H20: =IFERROR(MEDICARTE!C11,0) -> 0 | I20: =ChartData!AT14 -> 1 | J20: =IF(D20<30%,"Alta",IF(D20<60%,"Media","Baja")) -> Alta | K20: =IF(D20=0,"Pendiente",IF(D20>=70%,"Fuerte",IF(D20>=40%,"En desarrollo","Crítica"))) -> Pendiente
B22: ESTADÍSTICAS DE CONSOLIDADO
B23: Promedio Score Prácticas ITIL: | E23: =AVERAGE(D9:D19) -> 0.61497326
B24: Score Mínimo: | E24: =MIN(D9:D19) -> 0.29411765
B25: Score Máximo: | E25: =MAX(D9:D19) -> 0.73529412
B26: Total FTEs evaluados: | E26: =SUM(H9:H19) -> 57
B27: Mesas evaluadas: | E27: =COUNTA(B9:B19) -> 11
B28: Mesas pendientes / sin datos: | E28: =COUNTIF(K9:K19,"Pendiente") -> 0
B31: SEMÁFORO DE MADUREZ — ESTADO POR MESA
B32: MESA | C32: Nivel | D32: Descripción del Nivel | E32: Score Prácticas | F32: Fortaleza Identificada | G32: Brecha Principal | H32: Acción Recomendada Mesas de Nueva Generación
B33: =B9 -> SURA Cotizadores | C33: =C9 -> N2 | D33: {=_xlfn.SWITCH(C33,"N0","Reactivo / Sin estructura","N1","Inicial / Ad hoc","N2","Definido","N3","Gestionado","N4","Optimizado","N5","Innovador / Diferenciador","— Por definir")} -> Definido | E33: =D9 -> 0.52941176 | F33: =IF(E33>=70%,"Buenas prácticas ITIL consolidadas",IF(E33>=40%,"Base operativa existente","Información o práctica incompleta")) -> Base operativa existente | G33: =IF(E33<40%,"Bajo cumplimiento / datos pendientes",IF(E33<70%,"Estandarización y medición","Escalamiento a automatización")) -> Estandarización y medición | H33: =IF(E33<40%,"Completar levantamiento y priorizar quick wins",IF(E33<70%,"Formalizar procesos, métricas y gobierno","Escalar autoservicio, analítica e IA")) -> Formalizar procesos, métricas y gobierno
B34: =B10 -> SURA Digital Venta | C34: =C10 -> N2 | D34: {=_xlfn.SWITCH(C34,"N0","Reactivo / Sin estructura","N1","Inicial / Ad hoc","N2","Definido","N3","Gestionado","N4","Optimizado","N5","Innovador / Diferenciador","— Por definir")} -> Definido | E34: =D10 -> 0.55882353 | F34: =IF(E34>=70%,"Buenas prácticas ITIL consolidadas",IF(E34>=40%,"Base operativa existente","Información o práctica incompleta")) -> Base operativa existente | G34: =IF(E34<40%,"Bajo cumplimiento / datos pendientes",IF(E34<70%,"Estandarización y medición","Escalamiento a automatización")) -> Estandarización y medición | H34: =IF(E34<40%,"Completar levantamiento y priorizar quick wins",IF(E34<70%,"Formalizar procesos, métricas y gobierno","Escalar autoservicio, analítica e IA")) -> Formalizar procesos, métricas y gobierno
B35: =B11 -> SURA Automatizacion | C35: =C11 -> N2 | D35: {=_xlfn.SWITCH(C35,"N0","Reactivo / Sin estructura","N1","Inicial / Ad hoc","N2","Definido","N3","Gestionado","N4","Optimizado","N5","Innovador / Diferenciador","— Por definir")} -> Definido | E35: =D11 -> 0.61764706 | F35: =IF(E35>=70%,"Buenas prácticas ITIL consolidadas",IF(E35>=40%,"Base operativa existente","Información o práctica incompleta")) -> Base operativa existente | G35: =IF(E35<40%,"Bajo cumplimiento / datos pendientes",IF(E35<70%,"Estandarización y medición","Escalamiento a automatización")) -> Estandarización y medición | H35: =IF(E35<40%,"Completar levantamiento y priorizar quick wins",IF(E35<70%,"Formalizar procesos, métricas y gobierno","Escalar autoservicio, analítica e IA")) -> Formalizar procesos, métricas y gobierno
B36: =B12 -> SURA Canales Masivos | C36: =C12 -> N2 | D36: {=_xlfn.SWITCH(C36,"N0","Reactivo / Sin estructura","N1","Inicial / Ad hoc","N2","Definido","N3","Gestionado","N4","Optimizado","N5","Innovador / Diferenciador","— Por definir")} -> Definido | E36: =D12 -> 0.58823529 | F36: =IF(E36>=70%,"Buenas prácticas ITIL consolidadas",IF(E36>=40%,"Base operativa existente","Información o práctica incompleta")) -> Base operativa existente | G36: =IF(E36<40%,"Bajo cumplimiento / datos pendientes",IF(E36<70%,"Estandarización y medición","Escalamiento a automatización")) -> Estandarización y medición | H36: =IF(E36<40%,"Completar levantamiento y priorizar quick wins",IF(E36<70%,"Formalizar procesos, métricas y gobierno","Escalar autoservicio, analítica e IA")) -> Formalizar procesos, métricas y gobierno
B37: =B13 -> BCO COES Integracion | C37: =C13 -> N1 | D37: {=_xlfn.SWITCH(C37,"N0","Reactivo / Sin estructura","N1","Inicial / Ad hoc","N2","Definido","N3","Gestionado","N4","Optimizado","N5","Innovador / Diferenciador","— Por definir")} -> Inicial / Ad hoc | E37: =D13 -> 0.73529412 | F37: =IF(E37>=70%,"Buenas prácticas ITIL consolidadas",IF(E37>=40%,"Base operativa existente","Información o práctica incompleta")) -> Buenas prácticas ITIL consolidadas | G37: =IF(E37<40%,"Bajo cumplimiento / datos pendientes",IF(E37<70%,"Estandarización y medición","Escalamiento a automatización")) -> Escalamiento a automatización | H37: =IF(E37<40%,"Completar levantamiento y priorizar quick wins",IF(E37<70%,"Formalizar procesos, métricas y gobierno","Escalar autoservicio, analítica e IA")) -> Escalar autoservicio, analítica e IA
B38: =B14 -> BCO COES Datos | C38: =C14 -> #REF! | D38: {=_xlfn.SWITCH(C38,"N0","Reactivo / Sin estructura","N1","Inicial / Ad hoc","N2","Definido","N3","Gestionado","N4","Optimizado","N5","Innovador / Diferenciador","— Por definir")} -> #REF! | E38: =D14 -> 0.73529412 | F38: =IF(E38>=70%,"Buenas prácticas ITIL consolidadas",IF(E38>=40%,"Base operativa existente","Información o práctica incompleta")) -> Buenas prácticas ITIL consolidadas | G38: =IF(E38<40%,"Bajo cumplimiento / datos pendientes",IF(E38<70%,"Estandarización y medición","Escalamiento a automatización")) -> Escalamiento a automatización | H38: =IF(E38<40%,"Completar levantamiento y priorizar quick wins",IF(E38<70%,"Formalizar procesos, métricas y gobierno","Escalar autoservicio, analítica e IA")) -> Escalar autoservicio, analítica e IA
B39: =B15 -> BCO Soporte | C39: =C15 -> N1 | D39: {=_xlfn.SWITCH(C39,"N0","Reactivo / Sin estructura","N1","Inicial / Ad hoc","N2","Definido","N3","Gestionado","N4","Optimizado","N5","Innovador / Diferenciador","— Por definir")} -> Inicial / Ad hoc | E39: =D15 -> 0.73529412 | F39: =IF(E39>=70%,"Buenas prácticas ITIL consolidadas",IF(E39>=40%,"Base operativa existente","Información o práctica incompleta")) -> Buenas prácticas ITIL consolidadas | G39: =IF(E39<40%,"Bajo cumplimiento / datos pendientes",IF(E39<70%,"Estandarización y medición","Escalamiento a automatización")) -> Escalamiento a automatización | H39: =IF(E39<40%,"Completar levantamiento y priorizar quick wins",IF(E39<70%,"Formalizar procesos, métricas y gobierno","Escalar autoservicio, analítica e IA")) -> Escalar autoservicio, analítica e IA
B40: =B16 -> BCO COES Emma | C40: =C16 -> N1 | D40: {=_xlfn.SWITCH(C40,"N0","Reactivo / Sin estructura","N1","Inicial / Ad hoc","N2","Definido","N3","Gestionado","N4","Optimizado","N5","Innovador / Diferenciador","— Por definir")} -> Inicial / Ad hoc | E40: =D16 -> 0.73529412 | F40: =IF(E40>=70%,"Buenas prácticas ITIL consolidadas",IF(E40>=40%,"Base operativa existente","Información o práctica incompleta")) -> Buenas prácticas ITIL consolidadas | G40: =IF(E40<40%,"Bajo cumplimiento / datos pendientes",IF(E40<70%,"Estandarización y medición","Escalamiento a automatización")) -> Escalamiento a automatización | H40: =IF(E40<40%,"Completar levantamiento y priorizar quick wins",IF(E40<70%,"Formalizar procesos, métricas y gobierno","Escalar autoservicio, analítica e IA")) -> Escalar autoservicio, analítica e IA
B41: =B17 -> BCO Emma Iseries | C41: =C17 -> N1 | D41: {=_xlfn.SWITCH(C41,"N0","Reactivo / Sin estructura","N1","Inicial / Ad hoc","N2","Definido","N3","Gestionado","N4","Optimizado","N5","Innovador / Diferenciador","— Por definir")} -> Inicial / Ad hoc | E41: =D17 -> 0.73529412 | F41: =IF(E41>=70%,"Buenas prácticas ITIL consolidadas",IF(E41>=40%,"Base operativa existente","Información o práctica incompleta")) -> Buenas prácticas ITIL consolidadas | G41: =IF(E41<40%,"Bajo cumplimiento / datos pendientes",IF(E41<70%,"Estandarización y medición","Escalamiento a automatización")) -> Escalamiento a automatización | H41: =IF(E41<40%,"Completar levantamiento y priorizar quick wins",IF(E41<70%,"Formalizar procesos, métricas y gobierno","Escalar autoservicio, analítica e IA")) -> Escalar autoservicio, analítica e IA
B42: =B18 -> AES | C42: =C18 -> N1 | D42: {=_xlfn.SWITCH(C42,"N0","Reactivo / Sin estructura","N1","Inicial / Ad hoc","N2","Definido","N3","Gestionado","N4","Optimizado","N5","Innovador / Diferenciador","— Por definir")} -> Inicial / Ad hoc | E42: =D18 -> 0.29411765 | F42: =IF(E42>=70%,"Buenas prácticas ITIL consolidadas",IF(E42>=40%,"Base operativa existente","Información o práctica incompleta")) -> Información o práctica incompleta | G42: =IF(E42<40%,"Bajo cumplimiento / datos pendientes",IF(E42<70%,"Estandarización y medición","Escalamiento a automatización")) -> Bajo cumplimiento / datos pendientes | H42: =IF(E42<40%,"Completar levantamiento y priorizar quick wins",IF(E42<70%,"Formalizar procesos, métricas y gobierno","Escalar autoservicio, analítica e IA")) -> Completar levantamiento y priorizar quick wins
B43: =B19 -> XM | C43: =C19 -> N2 | D43: {=_xlfn.SWITCH(C43,"N0","Reactivo / Sin estructura","N1","Inicial / Ad hoc","N2","Definido","N3","Gestionado","N4","Optimizado","N5","Innovador / Diferenciador","— Por definir")} -> Definido | E43: =D19 -> 0.5 | F43: =IF(E43>=70%,"Buenas prácticas ITIL consolidadas",IF(E43>=40%,"Base operativa existente","Información o práctica incompleta")) -> Base operativa existente | G43: =IF(E43<40%,"Bajo cumplimiento / datos pendientes",IF(E43<70%,"Estandarización y medición","Escalamiento a automatización")) -> Estandarización y medición | H43: =IF(E43<40%,"Completar levantamiento y priorizar quick wins",IF(E43<70%,"Formalizar procesos, métricas y gobierno","Escalar autoservicio, analítica e IA")) -> Formalizar procesos, métricas y gobierno
B45: DOLORES ACTIVOS POR MESA — D1–D23 (✓=Sí · ~=Parcial)
B46: DOLOR | C46: SURA Cotiz. | D46: SURA Venta D. | E46: SURA Autom. | F46: SURA Canales | G46: BCO COES Int. | H46: BCO Datos | I46: BCO Soporte | J46: BCO Emma | K46: BCO Iseries | L46: AES | M46: XM | N46: MEDICARTE | O46: TOTAL
B47: D1 | C47: =IF(OR('SURA Cotizadores'!C99="Sí",'SURA Cotizadores'!C99="Si"),"✓",IF('SURA Cotizadores'!C99="Parcial","~","")) -> ~ | D47: =IF(OR('SURA Digital Venta'!C100="Sí",'SURA Digital Venta'!C100="Si"),"✓",IF('SURA Digital Venta'!C100="Parcial","~","")) -> ~ | E47: =IF(OR('SURA Automatizacion'!C100="Sí",'SURA Automatizacion'!C100="Si"),"✓",IF('SURA Automatizacion'!C100="Parcial","~","")) -> ~ | F47: =IF(OR('SURA Canales Masivos'!C100="Sí",'SURA Canales Masivos'!C100="Si"),"✓",IF('SURA Canales Masivos'!C100="Parcial","~","")) -> ~ | G47: =IF(OR('BCO COES Integracion'!C101="Sí",'BCO COES Integracion'!C101="Si"),"✓",IF('BCO COES Integracion'!C101="Parcial","~","")) -> ~ | H47: =IF(OR('BCO COES Datos'!C101="Sí",'BCO COES Datos'!C101="Si"),"✓",IF('BCO COES Datos'!C101="Parcial","~","")) -> ~ | I47: =IF(OR('BCO Soporte'!C102="Sí",'BCO Soporte'!C102="Si"),"✓",IF('BCO Soporte'!C102="Parcial","~","")) | J47: =IF(OR('BCO COES Emma'!C101="Sí",'BCO COES Emma'!C101="Si"),"✓",IF('BCO COES Emma'!C101="Parcial","~","")) -> ~ | K47: =IF(OR('BCO Emma Iseries'!C101="Sí",'BCO Emma Iseries'!C101="Si"),"✓",IF('BCO Emma Iseries'!C101="Parcial","~","")) | L47: =IF(OR(AES!C98="Sí",AES!C98="Si"),"✓",IF(AES!C98="Parcial","~","")) | M47: =IF(OR(XM!C100="Sí",XM!C100="Si"),"✓",IF(XM!C100="Parcial","~","")) -> ~ | N47: =IF(OR(MEDICARTE!C101="Sí",MEDICARTE!C101="Si"),"✓",IF(MEDICARTE!C101="Parcial","~","")) | O47: =COUNTIF(C47:N47,"✓")+0.5*COUNTIF(C47:N47,"~") -> 4
...

Sheet Graficas
E2: ANÁLISIS VISUAL— MESA DE SERVICIOS DE NUEVA GENERACIÓN | N2: Fecha: 2026/07/03 Clasificación: Interna
E3: Dashboard de madurez · prácticas · dolores · industria vs benchmark · Gen Next
E5: Versión: 1.0
B7: GRÁFICAS POR BLOQUE DE EVALUACIÓN — 11 DIMENSIONES + ④b

Sheet ChartData
A1: TABLA 1 — MADUREZ NUMÉRICA (N0-N5) | K1: HELPERS PARA GRÁFICAS | X1: ① Identificación general — completitud | AA1: ② Nivel de madurez actual | AE1: ③ Prácticas ITIL — score global | AH1: ④ Volumetría y KPIs — FCR/SLA | AM1: ④b Incidentes por categoría — tickets/mes | AP1: ⑤ XLA / DEX — NPS | AS1: ⑥ Dolores críticos — total activo D1–D23 | AV1: ⑦ Rotación y talento — completitud | AY1: ⑧ Tecnología y herramientas — herramientas registradas | BB1: ⑨ Modelo económico — completitud | BE1: ⑩ Visión nuevo servicio — completitud | BH1: ⑪ Casos de éxito — completitud | BK1: RESUMEN PROMEDIO POR DIMENSIÓN | BO1: DOLORES CONSOLIDADOS D1–D23
A2: Mesa | B2: Nivel Madurez (texto) | C2: Madurez Numérica (0-5) | D2: Meta (N3) | K2: Mesa | L2: Madurez | M2: Meta | X2: Mesa | Y2: Completitud | AA2: Mesa | AB2: Madurez | AC2: Meta N3 | AE2: Mesa | AF2: Score ITIL | AH2: Mesa | AI2: FCR | AJ2: SLA | AM2: Mesa | AN2: Tickets categorizados | AP2: Mesa | AQ2: NPS | AS2: Mesa | AT2: Dolores activos D1–D23 | AV2: Mesa | AW2: Completitud | AY2: Mesa | AZ2: Herramientas registradas | BB2: Mesa | BC2: Completitud | BE2: Mesa | BF2: Completitud | BH2: Mesa | BI2: Completitud | BK2: Dimensión | BL2: Promedio | BM2: Meta | BO2: Dolor | BP2: Total ponderado
A3: SURA Cotizadores | B3: ='SURA Cotizadores'!C12 -> N2 | C3: =IFERROR(VALUE(SUBSTITUTE(B3,"N","")),0) -> 2 | D3: 3 | K3: =A3 -> SURA Cotizadores | L3: =C3 -> 2 | M3: 3 | X3: =A3 -> SURA Cotizadores | Y3: =IFERROR(COUNTA('SURA Cotizadores'!C5:C24)/15,0) -> 1.2666667 | AA3: =A3 -> SURA Cotizadores | AB3: =C3 -> 2 | AC3: 3 | AE3: SURA Cotizadores | AF3: =IFERROR('SURA Cotizadores'!E56,0) -> 0.52941176 | AH3: =A3 -> SURA Cotizadores | AI3: =IFERROR('SURA Cotizadores'!C66,0) -> N/D | AJ3: =IFERROR('SURA Cotizadores'!C68,0) -> 0.7 | AM3: =A3 -> SURA Cotizadores | AN3: =IFERROR('SURA Cotizadores'!C82,0) -> 0 | AP3: =A3 -> SURA Cotizadores | AQ3: =IFERROR('SURA Cotizadores'!C89,0) -> 0 | AS3: =A3 -> SURA Cotizadores | AT3: =IF(OR('SURA Cotizadores'!C99="Sí",'SURA Cotizadores'!C99="Si"),1,IF('SURA Cotizadores'!C99="Parcial",0.5,0))+IF(OR('SURA Cotizadores'!C100="Sí",'SURA Cotizadores'!C100="Si"),1,IF('SURA Cotizadores'!C100="Parcial",0.5,0))+IF(OR('SURA Cotizadores'!C101="Sí",'SURA Cotizadores'!C101="Si"),1,IF('SURA Cotizadores'!C101="Parcial",0.5,0))+IF(OR('SURA Cotizadores'!C102="Sí",'SURA Cotizadores'!C102="Si"),1,IF('SURA Cotizadores'!C102="Parcial",0.5,0))+IF(OR('SURA Cotizadores'!C103="Sí",'SURA Cotizadores'!C103="Si"),1,IF('SURA Cotizadores'!C103="Parcial",0.5,0))+IF(OR('SURA Cotizadores'!C104="Sí",'SURA Cotizadores'!C104="Si"),1,IF('SURA Cotizadores'!C104="Parcial",0.5,0))+IF(OR('SURA Cotizadores'!C105="Sí",'SURA Cotizadores'!C105="Si"),1,IF('SURA Cotizadores'!C105="Parcial",0.5,0))+IF(OR('SURA Cotizadores'!C106="Sí",'SURA Cotizadores'!C106="Si"),1,IF('SURA Cotizadores'!C106="Parcial",0.5,0))+IF(OR('SURA Cotizadores'!C107="Sí",'SURA Cotizadores'!C107="Si"),1,IF('SURA Cotizadores'!C107="Parcial",0.5,0))+IF(OR('SURA Cotizadores'!C108="Sí",'SURA Cotizadores'!C108="Si"),1,IF('SURA Cotizadores'!C108="Parcial",0.5,0))+IF(OR('SURA Cotizadores'!C109="Sí",'SURA Cotizadores'!C109="Si"),1,IF('SURA Cotizadores'!C109="Parcial",0.5,0))+IF(OR('SURA Cotizadores'!C110="Sí",'SURA Cotizadores'!C110="Si"),1,IF('SURA Cotizadores'!C110="Parcial",0.5,0))+IF(OR('SURA Cotizadores'!C111="Sí",'SURA Cotizadores'!C111="Si"),1,IF('SURA Cotizadores'!C111="Parcial",0.5,0))+IF(OR('SURA Cotizadores'!C112="Sí",'SURA Cotizadores'!C112="Si"),1,IF('SURA Cotizadores'!C112="Parcial",0.5,0))+IF(OR('SURA Cotizadores'!C113="Sí",'SURA Cotizadores'!C113="Si"),1,IF('SURA Cotizadores'!C113="Parcial",0.5,0))+IF(OR('SURA Cotizadores'!C114="Sí",'SURA Cotizadores'!C114="Si"),1,IF('SURA Cotizadores'!C114="Parcial",0.5,0))+IF(OR('SURA Cotizadores'!C115="Sí",'SURA Cotizadores'!C115="Si"),1,IF('SURA Cotizadores'!C115="Parcial",0.5,0))+IF(OR('SURA Cotizadores'!C116="Sí",'SURA Cotizadores'!C116="Si"),1,IF('SURA Cotizadores'!C116="Parcial",0.5,0))+IF(OR('SURA Cotizadores'!C117="Sí",'SURA Cotizadores'!C117="Si"),1,IF('SURA Cotizadores'!C117="Parcial",0.5,0))+IF(OR('SURA Cotizadores'!C118="Sí",'SURA Cotizadores'!C118="Si"),1,IF('SURA Cotizadores'!C118="Parcial",0.5,0))+IF(OR('SURA Cotizadores'!C119="Sí",'SURA Cotizadores'!C119="Si"),1,IF('SURA Cotizadores'!C119="Parcial",0.5,0))+IF(OR('SURA Cotizadores'!C120="Sí",'SURA Cotizadores'!C120="Si"),1,IF('SURA Cotizadores'!C120="Parcial",0.5,0))+IF(OR('SURA Cotizadores'!C121="Sí",'SURA Cotizadores'!C121="Si"),1,IF('SURA Cotizadores'!C121="Parcial",0.5,0)) -> 13 | AV3: =A3 -> SURA Cotizadores | AW3: =IFERROR(COUNTA('SURA Cotizadores'!C126:C133)/8,0) -> 0.375 | AY3: =A3 -> SURA Cotizadores | AZ3: =IFERROR(COUNTA('SURA Cotizadores'!C137:C146),0) -> 3 | BB3: =A3 -> SURA Cotizadores | BC3: =IFERROR(COUNTA('SURA Cotizadores'!C150:C156)/7,0) -> 0.85714286 | BE3: =A3 -> SURA Cotizadores | BF3: =IFERROR(COUNTA('SURA Cotizadores'!C160:C168)/9,0) -> 0.88888889 | BH3: =A3 -> SURA Cotizadores | BI3: =IFERROR(COUNTA('SURA Cotizadores'!C172:C182)/10,0) -> 0.1 | BK3: ① Identificación general | BL3: =AVERAGE(Y3:Y13) -> 1.1454545 | BM3: =100% -> 1 | BO3: D1 | BP3: =Dashboard!O47 -> 4
A4: SURA Digital Venta | B4: ='SURA Digital Venta'!C13 -> N2 | C4: =IFERROR(VALUE(SUBSTITUTE(B4,"N","")),0) -> 2 | D4: 3 | K4: =A4 -> SURA Digital Venta | L4: =C4 -> 2 | M4: 3 | X4: =A4 -> SURA Digital Venta | Y4: =IFERROR(COUNTA('SURA Digital Venta'!C5:C24)/15,0) -> 1.2 | AA4: =A4 -> SURA Digital Venta | AB4: =C4 -> 2 | AC4: 3 | AE4: SURA Digital Venta | AF4: =IFERROR('SURA Digital Venta'!E57,0) -> 0.55882353 | AH4: =A4 -> SURA Digital Venta | AI4: =IFERROR('SURA Digital Venta'!C67,0) -> N/D | AJ4: =IFERROR('SURA Digital Venta'!C69,0) -> 0.74 | AM4: =A4 -> SURA Digital Venta | AN4: =IFERROR('SURA Digital Venta'!C82,0) -> 0 | AP4: =A4 -> SURA Digital Venta | AQ4: =IFERROR('SURA Digital Venta'!C89,0) -> Valor Actual | AS4: =A4 -> SURA Digital Venta | AT4: =IF(OR('SURA Digital Venta'!C100="Sí",'SURA Digital Venta'!C100="Si"),1,IF('SURA Digital Venta'!C100="Parcial",0.5,0))+IF(OR('SURA Digital Venta'!C101="Sí",'SURA Digital Venta'!C101="Si"),1,IF('SURA Digital Venta'!C101="Parcial",0.5,0))+IF(OR('SURA Digital Venta'!C102="Sí",'SURA Digital Venta'!C102="Si"),1,IF('SURA Digital Venta'!C102="Parcial",0.5,0))+IF(OR('SURA Digital Venta'!C103="Sí",'SURA Digital Venta'!C103="Si"),1,IF('SURA Digital Venta'!C103="Parcial",0.5,0))+IF(OR('SURA Digital Venta'!C104="Sí",'SURA Digital Venta'!C104="Si"),1,IF('SURA Digital Venta'!C104="Parcial",0.5,0))+IF(OR('SURA Digital Venta'!C105="Sí",'SURA Digital Venta'!C105="Si"),1,IF('SURA Digital Venta'!C105="Parcial",0.5,0))+IF(OR('SURA Digital Venta'!C106="Sí",'SURA Digital Venta'!C106="Si"),1,IF('SURA Digital Venta'!C106="Parcial",0.5,0))+IF(OR('SURA Digital Venta'!C107="Sí",'SURA Digital Venta'!C107="Si"),1,IF('SURA Digital Venta'!C107="Parcial",0.5,0))+IF(OR('SURA Digital Venta'!C108="Sí",'SURA Digital Venta'!C108="Si"),1,IF('SURA Digital Venta'!C108="Parcial",0.5,0))+IF(OR('SURA Digital Venta'!C109="Sí",'SURA Digital Venta'!C109="Si"),1,IF('SURA Digital Venta'!C109="Parcial",0.5,0))+IF(OR('SURA Digital Venta'!C110="Sí",'SURA Digital Venta'!C110="Si"),1,IF('SURA Digital Venta'!C110="Parcial",0.5,0))+IF(OR('SURA Digital Venta'!C111="Sí",'SURA Digital Venta'!C111="Si"),1,IF('SURA Digital Venta'!C111="Parcial",0.5,0))+IF(OR('SURA Digital Venta'!C112="Sí",'SURA Digital Venta'!C112="Si"),1,IF('SURA Digital Venta'!C112="Parcial",0.5,0))+IF(OR('SURA Digital Venta'!C113="Sí",'SURA Digital Venta'!C113="Si"),1,IF('SURA Digital Venta'!C113="Parcial",0.5,0))+IF(OR('SURA Digital Venta'!C114="Sí",'SURA Digital Venta'!C114="Si"),1,IF('SURA Digital Venta'!C114="Parcial",0.5,0))+IF(OR('SURA Digital Venta'!C115="Sí",'SURA Digital Venta'!C115="Si"),1,IF('SURA Digital Venta'!C115="Parcial",0.5,0))+IF(OR('SURA Digital Venta'!C116="Sí",'SURA Digital Venta'!C116="Si"),1,IF('SURA Digital Venta'!C116="Parcial",0.5,0))+IF(OR('SURA Digital Venta'!C117="Sí",'SURA Digital Venta'!C117="Si"),1,IF('SURA Digital Venta'!C117="Parcial",0.5,0))+IF(OR('SURA Digital Venta'!C118="Sí",'SURA Digital Venta'!C118="Si"),1,IF('SURA Digital Venta'!C118="Parcial",0.5,0))+IF(OR('SURA Digital Venta'!C119="Sí",'SURA Digital Venta'!C119="Si"),1,IF('SURA Digital Venta'!C119="Parcial",0.5,0))+IF(OR('SURA Digital Venta'!C120="Sí",'SURA Digital Venta'!C120="Si"),1,IF('SURA Digital Venta'!C120="Parcial",0.5,0))+IF(OR('SURA Digital Venta'!C121="Sí",'SURA Digital Venta'!C121="Si"),1,IF('SURA Digital Venta'!C121="Parcial",0.5,0)) -> 12.5 | AV4: =A4 -> SURA Digital Venta | AW4: =IFERROR(COUNTA('SURA Digital Venta'!C126:C133)/8,0) -> 0.375 | AY4: =A4 -> SURA Digital Venta | AZ4: =IFERROR(COUNTA('SURA Digital Venta'!C137:C146),0) -> 3 | BB4: =A4 -> SURA Digital Venta | BC4: =IFERROR(COUNTA('SURA Digital Venta'!C150:C156)/7,0) -> 0.85714286 | BE4: =A4 -> SURA Digital Venta | BF4: =IFERROR(COUNTA('SURA Digital Venta'!C160:C168)/9,0) -> 0.88888889 | BH4: =A4 -> SURA Digital Venta | BI4: =IFERROR(COUNTA('SURA Digital Venta'!C172:C182)/10,0) -> 0.1 | BK4: ② Madurez (normalizada) | BL4: =AVERAGE(AB3:AB13)/5 -> 0.27272727 | BM4: =60% -> 0.6 | BO4: D2 | BP4: =Dashboard!O48 -> 3.5
A5: SURA Automatizacion | B5: ='SURA Automatizacion'!C13 -> N2 | C5: =IFERROR(VALUE(SUBSTITUTE(B5,"N","")),0) -> 2 | D5: 3 | K5: =A5 -> SURA Automatizacion | L5: =C5 -> 2 | M5: 3 | X5: =A5 -> SURA Automatizacion | Y5: =IFERROR(COUNTA('SURA Automatizacion'!C5:C24)/15,0) -> 1.2 | AA5: =A5 -> SURA Automatizacion | AB5: =C5 -> 2 | AC5: 3 | AE5: SURA Automatizacion | AF5: =IFERROR('SURA Automatizacion'!E57,0) -> 0.61764706 | AH5: =A5 -> SURA Automatizacion | AI5: =IFERROR('SURA Automatizacion'!C67,0) -> N/D | AJ5: =IFERROR('SURA Automatizacion'!C69,0) -> 0.98 | AM5: =A5 -> SURA Automatizacion | AN5: =IFERROR('SURA Automatizacion'!C82,0) -> 0 | AP5: =A5 -> SURA Automatizacion | AQ5: =IFERROR('SURA Automatizacion'!C89,0) -> Valor Actual | AS5: =A5 -> SURA Automatizacion | AT5: =IF(OR('SURA Automatizacion'!C100="Sí",'SURA Automatizacion'!C100="Si"),1,IF('SURA Automatizacion'!C100="Parcial",0.5,0))+IF(OR('SURA Automatizacion'!C101="Sí",'SURA Automatizacion'!C101="Si"),1,IF('SURA Automatizacion'!C101="Parcial",0.5,0))+IF(OR('SURA Automatizacion'!C102="Sí",'SURA Automatizacion'!C102="Si"),1,IF('SURA Automatizacion'!C102="Parcial",0.5,0))+IF(OR('SURA Automatizacion'!C103="Sí",'SURA Automatizacion'!C103="Si"),1,IF('SURA Automatizacion'!C103="Parcial",0.5,0))+IF(OR('SURA Automatizacion'!C104="Sí",'SURA Automatizacion'!C104="Si"),1,IF('SURA Automatizacion'!C104="Parcial",0.5,0))+IF(OR('SURA Automatizacion'!C105="Sí",'SURA Automatizacion'!C105="Si"),1,IF('SURA Automatizacion'!C105="Parcial",0.5,0))+IF(OR('SURA Automatizacion'!C106="Sí",'SURA Automatizacion'!C106="Si"),1,IF('SURA Automatizacion'!C106="Parcial",0.5,0))+IF(OR('SURA Automatizacion'!C107="Sí",'SURA Automatizacion'!C107="Si"),1,IF('SURA Automatizacion'!C107="Parcial",0.5,0))+IF(OR('SURA Automatizacion'!C108="Sí",'SURA Automatizacion'!C108="Si"),1,IF('SURA Automatizacion'!C108="Parcial",0.5,0))+IF(OR('SURA Automatizacion'!C109="Sí",'SURA Automatizacion'!C109="Si"),1,IF('SURA Automatizacion'!C109="Parcial",0.5,0))+IF(OR('SURA Automatizacion'!C110="Sí",'SURA Automatizacion'!C110="Si"),1,IF('SURA Automatizacion'!C110="Parcial",0.5,0))+IF(OR('SURA Automatizacion'!C111="Sí",'SURA Automatizacion'!C111="Si"),1,IF('SURA Automatizacion'!C111="Parcial",0.5,0))+IF(OR('SURA Automatizacion'!C112="Sí",'SURA Automatizacion'!C112="Si"),1,IF('SURA Automatizacion'!C112="Parcial",0.5,0))+IF(OR('SURA Automatizacion'!C113="Sí",'SURA Automatizacion'!C113="Si"),1,IF('SURA Automatizacion'!C113="Parcial",0.5,0))+IF(OR('SURA Automatizacion'!C114="Sí",'SURA Automatizacion'!C114="Si"),1,IF('SURA Automatizacion'!C114="Parcial",0.5,0))+IF(OR('SURA Automatizacion'!C115="Sí",'SURA Automatizacion'!C115="Si"),1,IF('SURA Automatizacion'!C115="Parcial",0.5,0))+IF(OR('SURA Automatizacion'!C116="Sí",'SURA Automatizacion'!C116="Si"),1,IF('SURA Automatizacion'!C116="Parcial",0.5,0))+IF(OR('SURA Automatizacion'!C117="Sí",'SURA Automatizacion'!C117="Si"),1,IF('SURA Automatizacion'!C117="Parcial",0.5,0))+IF(OR('SURA Automatizacion'!C118="Sí",'SURA Automatizacion'!C118="Si"),1,IF('SURA Automatizacion'!C118="Parcial",0.5,0))+IF(OR('SURA Automatizacion'!C119="Sí",'SURA Automatizacion'!C119="Si"),1,IF('SURA Automatizacion'!C119="Parcial",0.5,0))+IF(OR('SURA Automatizacion'!C120="Sí",'SURA Automatizacion'!C120="Si"),1,IF('SURA Automatizacion'!C120="Parcial",0.5,0))+IF(OR('SURA Automatizacion'!C121="Sí",'SURA Automatizacion'!C121="Si"),1,IF('SURA Automatizacion'!C121="Parcial",0.5,0)) -> 11 | AV5: =A5 -> SURA Automatizacion | AW5: =IFERROR(COUNTA('SURA Automatizacion'!C126:C133)/8,0) -> 0.375 | AY5: =A5 -> SURA Automatizacion | AZ5: =IFERROR(COUNTA('SURA Automatizacion'!C137:C146),0) -> 5 | BB5: =A5 -> SURA Automatizacion | BC5: =IFERROR(COUNTA('SURA Automatizacion'!C150:C156)/7,0) -> 0.85714286 | BE5: =A5 -> SURA Automatizacion | BF5: =IFERROR(COUNTA('SURA Automatizacion'!C160:C168)/9,0) -> 0.88888889 | BH5: =A5 -> SURA Automatizacion | BI5: =IFERROR(COUNTA('SURA Automatizacion'!C172:C182)/10,0) -> 0.1 | BK5: ③ ITIL | BL5: =AVERAGE(AF3:AF13) -> 0.61497326 | BM5: =70% -> 0.7 | BO5: D3 | BP5: =Dashboard!O49 -> 6.5
