Workbook

Sheet Control de Cambios
D3: LEVANTAMIENTO DE MESA DE SERVICIOS
D5: Caracterización y Diagnóstico de Mesas de Servicio Operación Actual | G5: Fecha: 2026/07/03
D6: Versión: | E6: 1.0 | G6: Clasificación: Interna
B9: Elaboró | D9: Revisó | F9: Aprobó
B10: Natalia Zartha Junior Architect
B11: Fecha | D11: Fecha | F11: Fecha
B12: 46206
B14: Fecha | C14: Versión | D14: Descripción
B15: 2026/07/03 | C15: 1 | D15: Versión inicial; levantamiento de información actual de las mesas de servicio
C16: 2
C17: 3
C18: 4
C19: 5

Sheet Instrucciones
D2: LECCIONES APRENDIDAS — MESA DE SERVICIOS DE NUEVA GENERACIÓN
D4: Esta herramienta permite caracterizar la mesa de servicios actual en todas sus dimensiones para diseñar el futuro servicio Gen Next | F4: Fecha: 2026/07/03
D5: Versión: 1.0 | F5: Clasificación: Interna
B8: AGENDA DE LA SESIÓN DE LECCIONES APRENDIDAS (~60 minutos)
B9: # | C9: BLOQUE | D9: TIEMPO | E9: DESCRIPCIÓN
B10: ① | C10: INFORMACIÓN GENERAL | D10: 5 min | E10: Registrar datos básicos de la mesa: cliente, nombre del servicio, líder, ubicación, modalidad, contrato, herramientas y participantes.
B11: ② | C11: IDENTIFICAR NIVEL DE MADUREZ ACTUAL | D11: 5 min | E11: Identificar el nivel de madurez actual de la mesa de servicio de TI en una escala N0–N5, identificando el punto de partida operativo.
B12: ③ | C12: 17 PRÁCTICAS ITIL v4 + DIMENSIONES | D12: 5 min | E12: Revisar el cumplimiento de las prácticas ITIL v4 por las 4 dimensiones: organización/personas, información/tecnología, socios/proveedores y valor/mejora.
B13: ④ | C13: VOLUMETRÍA Y KPIs OPERATIVOS | D13: 5 min | E13: Levantar métricas operativas clave: volumen de tickets, FCR, SLA, backlog, tiempos de atención, escalamiento y desempeño general.
B14: ④b | C14: ④b DISTRIBUCIÓN DE INCIDENTES POR CATEGORÍA | D14: 5 min | E14: Analizar la distribución de incidentes por categoría para identificar patrones, servicios críticos, causas recurrentes y oportunidades de mejora.
B15: ⑤ | C15: EXPERIENCIA DEL USUARIO — XLA / DEX | D15: 5 min | E15: Evaluar la experiencia del usuario final mediante indicadores XLA/DEX, satisfacción, percepción del servicio, puntos de dolor y canales de atención.
B16: ⑥ | C16: DOLORES CRÍTICOS DE LA MESA (D1–D18) | D16: 5 min | E16: Identificar y priorizar los dolores críticos de la mesa, su impacto operativo, evidencias disponibles y nivel de urgencia para intervención.
B17: ⑦ | C17: ROTACIÓN Y TALENTO | D17: 5 min | E17: Revisar rotación, perfiles críticos, capacidades del equipo, clima laboral, brechas de conocimiento y necesidades de formación.
B18: ⑧ | C18: TECNOLOGÍA Y HERRAMIENTAS | D18: 5 min | E18: Evaluar herramientas tecnológicas actuales: ITSM, monitoreo, autoservicio, base de conocimiento, automatización, integraciones y reportes.
B19: ⑨ | C19: MODELO ECONÓMICO ACTUAL | D19: 5 min | E19: Analizar el modelo económico actual: FTEs, costos, esquema contractual, capacidad instalada, eficiencia operativa y posibles oportunidades de optimización.
B20: ⑩ | C20: VISIÓN PARA EL NUEVO SERVICIO — ¿QUÉ DEBERÍA CAMBIAR? | D20: 5 min | E20: Definir la visión objetivo del nuevo servicio: cambios esperados, capacidades Gen Next, automatización, experiencia deseada y prioridades de transformación.
B21: ⑪ | C21: CASOS DE EXITO | D21: 5 min | E21: Documentar casos de éxito, buenas prácticas, aprendizajes reutilizables y elementos que deben conservarse o escalarse en el nuevo modelo.
B23: ESCALA DE MADUREZ — N0 a N5
B24: NIVEL | C24: NOMBRE | D24: DESCRIPCIÓN
B25: N0 | C25: Reactivo / Sin estructura | D25: No existe proceso formal. Todo es manual y reactivo. Sin CMDB ni catálogo.
B26: N1 | C26: Inicial / Ad hoc/ Operación reactiva | D26: Procesos básicos documentados. Herramientas mínimas. Cumplimiento inconsistente.
B27: N2 | C27: Definido / Organización funcional | D27: Procesos ITIL definidos y seguidos. Métricas básicas (SLA (Service Level Agreement), FCR (Fondo de Capital Riesgo)). Equipo estable.
B28: N3 | C28: Gestionado / Gestión por servicios | D28: Métricas avanzadas. Automatización parcial. Gestión proactiva de problemas.
B29: N4 | C29: Optimizado / Gestión integrada | D29: Autoservicio maduro. IA/ML básico. XLA (Experience Level Agreement) medidos. Mejora continua activa.
B30: N5 | C30: Innovador / Diferenciador | D30: IA generativa, predicción, hiper-automatización. Referente del sector.
B32: LEYENDA DE RESPUESTAS — PRÁCTICAS ITIL
B33: RESPUESTA | C33: SIGNIFICADO | D33: COLOR | E33: PUNTAJE
B34: Sí | C34: Cumplimiento completo y documentado | D34: 1F7A4D | E34: 1.0
B35: Parcial | C35: Cumplimiento parcial o en proceso | D35: E07B26 | E35: 0.5
B36: No | C36: No existe o no se cumple | D36: C0392B | E36: 0.0
B37: N/A | C37: No aplica a esta mesa | D37: D9D9D9 | E37: —

Sheet Dashboard
C2: DASHBOARD — MESA DE SERVICIOS DE NUEVA GENERACIÓN | I2: Fecha: 2026/07/03 Clasificación: Interna
C3: Resumen consolidado · Julio 2026 · PersonalSoft
C5: Versión: 1.0
B7: RESUMEN POR MESA DE SERVICIOS — 11 MESAS
B8: MESA | C8: Nivel Madurez | D8: Score Prácticas | E8: FCR (%) | F8: SLA (%) | G8: NPS | H8: FTEs | I8: Dolores Activos | J8: Prioridad Global | K8: Estado
B9: SURA Cotizadores | C9: ='SURA Cotizadores'!C12 -> N2 | D9: =IFERROR('SURA Cotizadores'!E54,0) -> 0.52941176 | E9: =IFERROR('SURA Cotizadores'!C62,0) -> N/D | F9: =IFERROR('SURA Cotizadores'!C64,0) -> 0.7 | G9: =IFERROR('SURA Cotizadores'!C85,0) -> 0 | H9: =IFERROR('SURA Cotizadores'!C68,0) -> 8 | I9: =COUNTIF('SURA Cotizadores'!C95:C112,"Sí")+COUNTIF('SURA Cotizadores'!C95:C112,"Si")+0.5*COUNTIF('SURA Cotizadores'!C95:C112,"Parcial") -> 11 | J9: =IF(D9<30%,"Alta",IF(D9<60%,"Media","Baja")) -> Media | K9: =IF(D9=0,"Pendiente",IF(D9>=70%,"Fuerte",IF(D9>=40%,"En desarrollo","Crítica"))) -> En desarrollo
B10: SURA Digital Venta | C10: =IF('SURA Digital Venta'!C13="","0",'SURA Digital Venta'!C13) -> N2 | D10: =IFERROR('SURA Digital Venta'!E55,0) -> 0.55882353 | E10: =IFERROR('SURA Digital Venta'!C63,0) -> N/D | F10: =IFERROR('SURA Digital Venta'!C65,0) -> 0.74 | G10: =IFERROR('SURA Digital Venta'!C86,0) -> 0 | H10: =IFERROR('SURA Digital Venta'!C69,0) -> 2 | I10: =COUNTIF('SURA Digital Venta'!C95:C112,"Sí")+COUNTIF('SURA Digital Venta'!C95:C112,"Si")+0.5*COUNTIF('SURA Digital Venta'!C95:C112,"Parcial") -> 11 | J10: =IF(D10<30%,"Alta",IF(D10<60%,"Media","Baja")) -> Media | K10: =IF(D10=0,"Pendiente",IF(D10>=70%,"Fuerte",IF(D10>=40%,"En desarrollo","Crítica"))) -> En desarrollo
B11: SURA Automatizacion | C11: =IF('SURA Automatizacion'!C13="","0",'SURA Automatizacion'!C13) -> N2 | D11: =IFERROR('SURA Automatizacion'!E55,0) -> 0.61764706 | E11: =IFERROR('SURA Automatizacion'!C63,0) -> N/D | F11: =IFERROR('SURA Automatizacion'!C65,0) -> 0.98 | G11: =IFERROR('SURA Automatizacion'!C86,0) -> 0 | H11: =IFERROR('SURA Automatizacion'!C69,0) -> 6 | I11: =COUNTIF('SURA Automatizacion'!C95:C112,"Sí")+COUNTIF('SURA Automatizacion'!C95:C112,"Si")+0.5*COUNTIF('SURA Automatizacion'!C95:C112,"Parcial") -> 9.5 | J11: =IF(D11<30%,"Alta",IF(D11<60%,"Media","Baja")) -> Baja | K11: =IF(D11=0,"Pendiente",IF(D11>=70%,"Fuerte",IF(D11>=40%,"En desarrollo","Crítica"))) -> En desarrollo
B12: SURA Canales Masivos | C12: =IF('SURA Canales Masivos'!C13="","0",'SURA Canales Masivos'!C13) -> N2 | D12: =IFERROR('SURA Canales Masivos'!E55,0) -> 0.58823529 | E12: =IFERROR('SURA Canales Masivos'!C63,0) -> N/D | F12: =IFERROR('SURA Canales Masivos'!C65,0) -> 0.72 | G12: =IFERROR('SURA Canales Masivos'!C86,0) -> 0 | H12: =IFERROR('SURA Canales Masivos'!C69,0) -> 1 | I12: =COUNTIF('SURA Canales Masivos'!C95:C112,"Sí")+COUNTIF('SURA Canales Masivos'!C95:C112,"Si")+0.5*COUNTIF('SURA Canales Masivos'!C95:C112,"Parcial") -> 11.5 | J12: =IF(D12<30%,"Alta",IF(D12<60%,"Media","Baja")) -> Media | K12: =IF(D12=0,"Pendiente",IF(D12>=70%,"Fuerte",IF(D12>=40%,"En desarrollo","Crítica"))) -> En desarrollo
B13: BCO Gioti 1 | C13: =IF('BCO Gioti 1'!C14="","0",'BCO Gioti 1'!C14) -> N1 | D13: =IFERROR('BCO Gioti 1'!E56,0) -> 0.79411765 | E13: =IFERROR('BCO Gioti 1'!C64,0) -> 0.68 | F13: =IFERROR('BCO Gioti 1'!C66,0) -> 0.89 | G13: =IFERROR('BCO Gioti 1'!C87,0) -> 0 | H13: =IFERROR('BCO Gioti 1'!C70,0) -> 12 | I13: =COUNTIF('BCO Gioti 1'!C96:C113,"Sí")+COUNTIF('BCO Gioti 1'!C96:C113,"Si")+0.5*COUNTIF('BCO Gioti 1'!C96:C113,"Parcial") -> 1 | J13: =IF(D13<30%,"Alta",IF(D13<60%,"Media","Baja")) -> Baja | K13: =IF(D13=0,"Pendiente",IF(D13>=70%,"Fuerte",IF(D13>=40%,"En desarrollo","Crítica"))) -> Fuerte
B14: BCO Gioti 2 | C14: =IF('BCO Gioti 2'!C14="","0",'BCO Gioti 2'!C14) -> N1 | D14: =IFERROR('BCO Gioti 2'!E56,0) -> 0 | E14: =IFERROR('BCO Gioti 2'!C64,0) -> 0.68 | F14: =IFERROR('BCO Gioti 2'!C66,0) -> 0.89 | G14: =IFERROR('BCO Gioti 2'!C87,0) -> 0 | H14: =IFERROR('BCO Gioti 2'!C70,0) -> 12 | I14: =COUNTIF('BCO Gioti 2'!C96:C113,"Sí")+COUNTIF('BCO Gioti 2'!C96:C113,"Si")+0.5*COUNTIF('BCO Gioti 2'!C96:C113,"Parcial") -> 1 | J14: =IF(D14<30%,"Alta",IF(D14<60%,"Media","Baja")) -> Alta | K14: =IF(D14=0,"Pendiente",IF(D14>=70%,"Fuerte",IF(D14>=40%,"En desarrollo","Crítica"))) -> Pendiente
B15: BCO Gioti 3 | C15: =IF('BCO Gioti 3'!C14="","0",'BCO Gioti 3'!C14) -> N1 | D15: =IFERROR('BCO Gioti 3'!E56,0) -> 0 | E15: =IFERROR('BCO Gioti 3'!C64,0) -> 0.68 | F15: =IFERROR('BCO Gioti 3'!C66,0) -> 0.89 | G15: =IFERROR('BCO Gioti 3'!C87,0) -> 0 | H15: =IFERROR('BCO Gioti 3'!C70,0) -> 12 | I15: =COUNTIF('BCO Gioti 3'!C97:C114,"Sí")+COUNTIF('BCO Gioti 3'!C97:C114,"Si")+0.5*COUNTIF('BCO Gioti 3'!C97:C114,"Parcial") -> 0 | J15: =IF(D15<30%,"Alta",IF(D15<60%,"Media","Baja")) -> Alta | K15: =IF(D15=0,"Pendiente",IF(D15>=70%,"Fuerte",IF(D15>=40%,"En desarrollo","Crítica"))) -> Pendiente
B16: BCO Gioti 4 | C16: =IF('BCO Gioti 4'!C14="","0",'BCO Gioti 4'!C14) -> N1 | D16: =IFERROR('BCO Gioti 4'!E56,0) -> 0 | E16: =IFERROR('BCO Gioti 4'!C64,0) -> 0.68 | F16: =IFERROR('BCO Gioti 4'!C66,0) -> 0.89 | G16: =IFERROR('BCO Gioti 4'!C87,0) -> 0 | H16: =IFERROR('BCO Gioti 4'!C70,0) -> 12 | I16: =COUNTIF('BCO Gioti 4'!C96:C113,"Sí")+COUNTIF('BCO Gioti 4'!C96:C113,"Si")+0.5*COUNTIF('BCO Gioti 4'!C96:C113,"Parcial") -> 0 | J16: =IF(D16<30%,"Alta",IF(D16<60%,"Media","Baja")) -> Alta | K16: =IF(D16=0,"Pendiente",IF(D16>=70%,"Fuerte",IF(D16>=40%,"En desarrollo","Crítica"))) -> Pendiente
B17: AES | C17: =IF(AES!C13="","0",AES!C13) -> N1 | D17: =IFERROR(AES!E54,0) -> 0.29411765 | E17: =IFERROR(AES!C62,0) -> 0 | F17: =IFERROR(AES!C64,0) -> 0 | G17: =IFERROR(AES!C85,0) -> 0 | H17: =IFERROR(AES!C68,0) -> 4 | I17: =COUNTIF(AES!C94:C111,"Sí")+COUNTIF(AES!C94:C111,"Si")+0.5*COUNTIF(AES!C94:C111,"Parcial") -> 6 | J17: =IF(D17<30%,"Alta",IF(D17<60%,"Media","Baja")) -> Alta | K17: =IF(D17=0,"Pendiente",IF(D17>=70%,"Fuerte",IF(D17>=40%,"En desarrollo","Crítica"))) -> Crítica
B18: XM | C18: =IF(XM!C14="","0",XM!C14) -> N1 | D18: =IFERROR(XM!E56,0) -> 0 | E18: =IFERROR(XM!C64,0) -> 0 | F18: =IFERROR(XM!C66,0) -> 0 | G18: =IFERROR(XM!C87,0) -> 0 | H18: =IFERROR(XM!C70,0) -> 0 | I18: =COUNTIF(XM!C96:C113,"Sí")+COUNTIF(XM!C96:C113,"Si")+0.5*COUNTIF(XM!C96:C113,"Parcial") -> 0 | J18: =IF(D18<30%,"Alta",IF(D18<60%,"Media","Baja")) -> Alta | K18: =IF(D18=0,"Pendiente",IF(D18>=70%,"Fuerte",IF(D18>=40%,"En desarrollo","Crítica"))) -> Pendiente
B19: MEDICARTE | C19: =IF(MEDICARTE!C14="","0",MEDICARTE!C14) -> N1 | D19: =IFERROR(MEDICARTE!E56,0) -> 0 | E19: =IFERROR(MEDICARTE!C64,0) -> 0.68 | F19: =IFERROR(MEDICARTE!C66,0) -> 0.89 | G19: =IFERROR(MEDICARTE!C87,0) -> 0 | H19: =IFERROR(MEDICARTE!C70,0) -> 12 | I19: =COUNTIF(MEDICARTE!C96:C113,"Sí")+COUNTIF(MEDICARTE!C96:C113,"Si")+0.5*COUNTIF(MEDICARTE!C96:C113,"Parcial") -> 0 | J19: =IF(D19<30%,"Alta",IF(D19<60%,"Media","Baja")) -> Alta | K19: =IF(D19=0,"Pendiente",IF(D19>=70%,"Fuerte",IF(D19>=40%,"En desarrollo","Crítica"))) -> Pendiente
B22: ESTADÍSTICAS DE CONSOLIDADO
B23: Promedio Score Prácticas ITIL: | E23: =AVERAGE(D9:D19) -> 0.30748663
B24: Score Mínimo: | E24: =MIN(D9:D19) -> 0
B25: Score Máximo: | E25: =MAX(D9:D19) -> 0.79411765
B26: Total FTEs evaluados: | E26: =SUM(H9:H19) -> 81
B27: Mesas evaluadas: | E27: =COUNTA(B9:B19) -> 11
B28: Mesas pendientes / sin datos: | E28: =COUNTIF(K9:K19,"Pendiente") -> 5
B31: SEMÁFORO DE MADUREZ — ESTADO POR MESA
B32: MESA | C32: Nivel | D32: Descripción del Nivel | E32: Score Prácticas | F32: Fortaleza Identificada | G32: Brecha Principal | H32: Acción Recomendada Mesas de Nueva Generación
B33: =B9 -> SURA Cotizadores | C33: =C9 -> N2 | D33: {=_xlfn.SWITCH(C33,"N0","Reactivo / Sin estructura","N1","Inicial / Ad hoc","N2","Definido","N3","Gestionado","N4","Optimizado","N5","Innovador / Diferenciador","— Por definir")} -> Definido | E33: =D9 -> 0.52941176 | F33: =IF(E33>=70%,"Buenas prácticas ITIL consolidadas",IF(E33>=40%,"Base operativa existente","Información o práctica incompleta")) -> Base operativa existente | G33: =IF(E33<40%,"Bajo cumplimiento / datos pendientes",IF(E33<70%,"Estandarización y medición","Escalamiento a automatización")) -> Estandarización y medición | H33: =IF(E33<40%,"Completar levantamiento y priorizar quick wins",IF(E33<70%,"Formalizar procesos, métricas y gobierno","Escalar autoservicio, analítica e IA")) -> Formalizar procesos, métricas y gobierno
B34: =B10 -> SURA Digital Venta | C34: =C10 -> N2 | D34: {=_xlfn.SWITCH(C34,"N0","Reactivo / Sin estructura","N1","Inicial / Ad hoc","N2","Definido","N3","Gestionado","N4","Optimizado","N5","Innovador / Diferenciador","— Por definir")} -> Definido | E34: =D10 -> 0.55882353 | F34: =IF(E34>=70%,"Buenas prácticas ITIL consolidadas",IF(E34>=40%,"Base operativa existente","Información o práctica incompleta")) -> Base operativa existente | G34: =IF(E34<40%,"Bajo cumplimiento / datos pendientes",IF(E34<70%,"Estandarización y medición","Escalamiento a automatización")) -> Estandarización y medición | H34: =IF(E34<40%,"Completar levantamiento y priorizar quick wins",IF(E34<70%,"Formalizar procesos, métricas y gobierno","Escalar autoservicio, analítica e IA")) -> Formalizar procesos, métricas y gobierno
B35: =B11 -> SURA Automatizacion | C35: =C11 -> N2 | D35: {=_xlfn.SWITCH(C35,"N0","Reactivo / Sin estructura","N1","Inicial / Ad hoc","N2","Definido","N3","Gestionado","N4","Optimizado","N5","Innovador / Diferenciador","— Por definir")} -> Definido | E35: =D11 -> 0.61764706 | F35: =IF(E35>=70%,"Buenas prácticas ITIL consolidadas",IF(E35>=40%,"Base operativa existente","Información o práctica incompleta")) -> Base operativa existente | G35: =IF(E35<40%,"Bajo cumplimiento / datos pendientes",IF(E35<70%,"Estandarización y medición","Escalamiento a automatización")) -> Estandarización y medición | H35: =IF(E35<40%,"Completar levantamiento y priorizar quick wins",IF(E35<70%,"Formalizar procesos, métricas y gobierno","Escalar autoservicio, analítica e IA")) -> Formalizar procesos, métricas y gobierno
B36: =B12 -> SURA Canales Masivos | C36: =C12 -> N2 | D36: {=_xlfn.SWITCH(C36,"N0","Reactivo / Sin estructura","N1","Inicial / Ad hoc","N2","Definido","N3","Gestionado","N4","Optimizado","N5","Innovador / Diferenciador","— Por definir")} -> Definido | E36: =D12 -> 0.58823529 | F36: =IF(E36>=70%,"Buenas prácticas ITIL consolidadas",IF(E36>=40%,"Base operativa existente","Información o práctica incompleta")) -> Base operativa existente | G36: =IF(E36<40%,"Bajo cumplimiento / datos pendientes",IF(E36<70%,"Estandarización y medición","Escalamiento a automatización")) -> Estandarización y medición | H36: =IF(E36<40%,"Completar levantamiento y priorizar quick wins",IF(E36<70%,"Formalizar procesos, métricas y gobierno","Escalar autoservicio, analítica e IA")) -> Formalizar procesos, métricas y gobierno
B37: =B13 -> BCO Gioti 1 | C37: =C13 -> N1 | D37: {=_xlfn.SWITCH(C37,"N0","Reactivo / Sin estructura","N1","Inicial / Ad hoc","N2","Definido","N3","Gestionado","N4","Optimizado","N5","Innovador / Diferenciador","— Por definir")} -> Inicial / Ad hoc | E37: =D13 -> 0.79411765 | F37: =IF(E37>=70%,"Buenas prácticas ITIL consolidadas",IF(E37>=40%,"Base operativa existente","Información o práctica incompleta")) -> Buenas prácticas ITIL consolidadas | G37: =IF(E37<40%,"Bajo cumplimiento / datos pendientes",IF(E37<70%,"Estandarización y medición","Escalamiento a automatización")) -> Escalamiento a automatización | H37: =IF(E37<40%,"Completar levantamiento y priorizar quick wins",IF(E37<70%,"Formalizar procesos, métricas y gobierno","Escalar autoservicio, analítica e IA")) -> Escalar autoservicio, analítica e IA
B38: =B14 -> BCO Gioti 2 | C38: =C14 -> N1 | D38: {=_xlfn.SWITCH(C38,"N0","Reactivo / Sin estructura","N1","Inicial / Ad hoc","N2","Definido","N3","Gestionado","N4","Optimizado","N5","Innovador / Diferenciador","— Por definir")} -> Inicial / Ad hoc | E38: =D14 -> 0 | F38: =IF(E38>=70%,"Buenas prácticas ITIL consolidadas",IF(E38>=40%,"Base operativa existente","Información o práctica incompleta")) -> Información o práctica incompleta | G38: =IF(E38<40%,"Bajo cumplimiento / datos pendientes",IF(E38<70%,"Estandarización y medición","Escalamiento a automatización")) -> Bajo cumplimiento / datos pendientes | H38: =IF(E38<40%,"Completar levantamiento y priorizar quick wins",IF(E38<70%,"Formalizar procesos, métricas y gobierno","Escalar autoservicio, analítica e IA")) -> Completar levantamiento y priorizar quick wins
B39: =B15 -> BCO Gioti 3 | C39: =C15 -> N1 | D39: {=_xlfn.SWITCH(C39,"N0","Reactivo / Sin estructura","N1","Inicial / Ad hoc","N2","Definido","N3","Gestionado","N4","Optimizado","N5","Innovador / Diferenciador","— Por definir")} -> Inicial / Ad hoc | E39: =D15 -> 0 | F39: =IF(E39>=70%,"Buenas prácticas ITIL consolidadas",IF(E39>=40%,"Base operativa existente","Información o práctica incompleta")) -> Información o práctica incompleta | G39: =IF(E39<40%,"Bajo cumplimiento / datos pendientes",IF(E39<70%,"Estandarización y medición","Escalamiento a automatización")) -> Bajo cumplimiento / datos pendientes | H39: =IF(E39<40%,"Completar levantamiento y priorizar quick wins",IF(E39<70%,"Formalizar procesos, métricas y gobierno","Escalar autoservicio, analítica e IA")) -> Completar levantamiento y priorizar quick wins
B40: =B16 -> BCO Gioti 4 | C40: =C16 -> N1 | D40: {=_xlfn.SWITCH(C40,"N0","Reactivo / Sin estructura","N1","Inicial / Ad hoc","N2","Definido","N3","Gestionado","N4","Optimizado","N5","Innovador / Diferenciador","— Por definir")} -> Inicial / Ad hoc | E40: =D16 -> 0 | F40: =IF(E40>=70%,"Buenas prácticas ITIL consolidadas",IF(E40>=40%,"Base operativa existente","Información o práctica incompleta")) -> Información o práctica incompleta | G40: =IF(E40<40%,"Bajo cumplimiento / datos pendientes",IF(E40<70%,"Estandarización y medición","Escalamiento a automatización")) -> Bajo cumplimiento / datos pendientes | H40: =IF(E40<40%,"Completar levantamiento y priorizar quick wins",IF(E40<70%,"Formalizar procesos, métricas y gobierno","Escalar autoservicio, analítica e IA")) -> Completar levantamiento y priorizar quick wins
B41: =B17 -> AES | C41: =C17 -> N1 | D41: {=_xlfn.SWITCH(C41,"N0","Reactivo / Sin estructura","N1","Inicial / Ad hoc","N2","Definido","N3","Gestionado","N4","Optimizado","N5","Innovador / Diferenciador","— Por definir")} -> Inicial / Ad hoc | E41: =D17 -> 0.29411765 | F41: =IF(E41>=70%,"Buenas prácticas ITIL consolidadas",IF(E41>=40%,"Base operativa existente","Información o práctica incompleta")) -> Información o práctica incompleta | G41: =IF(E41<40%,"Bajo cumplimiento / datos pendientes",IF(E41<70%,"Estandarización y medición","Escalamiento a automatización")) -> Bajo cumplimiento / datos pendientes | H41: =IF(E41<40%,"Completar levantamiento y priorizar quick wins",IF(E41<70%,"Formalizar procesos, métricas y gobierno","Escalar autoservicio, analítica e IA")) -> Completar levantamiento y priorizar quick wins
B42: =B18 -> XM | C42: =C18 -> N1 | D42: {=_xlfn.SWITCH(C42,"N0","Reactivo / Sin estructura","N1","Inicial / Ad hoc","N2","Definido","N3","Gestionado","N4","Optimizado","N5","Innovador / Diferenciador","— Por definir")} -> Inicial / Ad hoc | E42: =D18 -> 0 | F42: =IF(E42>=70%,"Buenas prácticas ITIL consolidadas",IF(E42>=40%,"Base operativa existente","Información o práctica incompleta")) -> Información o práctica incompleta | G42: =IF(E42<40%,"Bajo cumplimiento / datos pendientes",IF(E42<70%,"Estandarización y medición","Escalamiento a automatización")) -> Bajo cumplimiento / datos pendientes | H42: =IF(E42<40%,"Completar levantamiento y priorizar quick wins",IF(E42<70%,"Formalizar procesos, métricas y gobierno","Escalar autoservicio, analítica e IA")) -> Completar levantamiento y priorizar quick wins
B43: =B19 -> MEDICARTE | C43: =C19 -> N1 | D43: {=_xlfn.SWITCH(C43,"N0","Reactivo / Sin estructura","N1","Inicial / Ad hoc","N2","Definido","N3","Gestionado","N4","Optimizado","N5","Innovador / Diferenciador","— Por definir")} -> Inicial / Ad hoc | E43: =D19 -> 0 | F43: =IF(E43>=70%,"Buenas prácticas ITIL consolidadas",IF(E43>=40%,"Base operativa existente","Información o práctica incompleta")) -> Información o práctica incompleta | G43: =IF(E43<40%,"Bajo cumplimiento / datos pendientes",IF(E43<70%,"Estandarización y medición","Escalamiento a automatización")) -> Bajo cumplimiento / datos pendientes | H43: =IF(E43<40%,"Completar levantamiento y priorizar quick wins",IF(E43<70%,"Formalizar procesos, métricas y gobierno","Escalar autoservicio, analítica e IA")) -> Completar levantamiento y priorizar quick wins
B45: DOLORES ACTIVOS POR MESA — D1–D18 (✓=Sí · ~=Parcial)
B46: DOLOR | C46: SURA Cotiz. | D46: SURA Venta D. | E46: SURA Torre | F46: SURA Mesa 4 | G46: BCO Gioti 1 | H46: BCO Gioti 2 | I46: BCO Gioti 3 | J46: BCO Gioti 4 | K46: AES | L46: XM | M46: MEDICARTE | N46: TOTAL
B47: D1: Sí | C47: =IF(OR('SURA Cotizadores'!C95="Sí",'SURA Cotizadores'!C95="Si"),"✓",IF('SURA Cotizadores'!C95="Parcial","~","")) -> ~ | D47: =IF(OR('SURA Digital Venta'!C95="Sí",'SURA Digital Venta'!C95="Si"),"✓",IF('SURA Digital Venta'!C95="Parcial","~","")) | E47: =IF(OR('SURA Automatizacion'!C95="Sí",'SURA Automatizacion'!C95="Si"),"✓",IF('SURA Automatizacion'!C95="Parcial","~","")) | F47: =IF(OR('SURA Canales Masivos'!C95="Sí",'SURA Canales Masivos'!C95="Si"),"✓",IF('SURA Canales Masivos'!C95="Parcial","~","")) | G47: =IF(OR('BCO Gioti 1'!C96="Sí",'BCO Gioti 1'!C96="Si"),"✓",IF('BCO Gioti 1'!C96="Parcial","~","")) | H47: =IF(OR('BCO Gioti 2'!C96="Sí",'BCO Gioti 2'!C96="Si"),"✓",IF('BCO Gioti 2'!C96="Parcial","~","")) | I47: =IF(OR('BCO Gioti 3'!C97="Sí",'BCO Gioti 3'!C97="Si"),"✓",IF('BCO Gioti 3'!C97="Parcial","~","")) | J47: =IF(OR('BCO Gioti 4'!C96="Sí",'BCO Gioti 4'!C96="Si"),"✓",IF('BCO Gioti 4'!C96="Parcial","~","")) | K47: =IF(OR(AES!C94="Sí",AES!C94="Si"),"✓",IF(AES!C94="Parcial","~","")) | L47: =IF(OR(XM!C96="Sí",XM!C96="Si"),"✓",IF(XM!C96="Parcial","~","")) | M47: =IF(OR(MEDICARTE!C96="Sí",MEDICARTE!C96="Si"),"✓",IF(MEDICARTE!C96="Parcial","~","")) | N47: =COUNTIF(C47:M47,"✓")+0.5*COUNTIF(C47:M47,"~") -> 0.5
B48: D2: Parcial | C48: =IF(OR('SURA Cotizadores'!C96="Sí",'SURA Cotizadores'!C96="Si"),"✓",IF('SURA Cotizadores'!C96="Parcial","~","")) -> ✓ | D48: =IF(OR('SURA Digital Venta'!C96="Sí",'SURA Digital Venta'!C96="Si"),"✓",IF('SURA Digital Venta'!C96="Parcial","~","")) -> ~ | E48: =IF(OR('SURA Automatizacion'!C96="Sí",'SURA Automatizacion'!C96="Si"),"✓",IF('SURA Automatizacion'!C96="Parcial","~","")) -> ~ | F48: =IF(OR('SURA Canales Masivos'!C96="Sí",'SURA Canales Masivos'!C96="Si"),"✓",IF('SURA Canales Masivos'!C96="Parcial","~","")) -> ~ | G48: =IF(OR('BCO Gioti 1'!C97="Sí",'BCO Gioti 1'!C97="Si"),"✓",IF('BCO Gioti 1'!C97="Parcial","~","")) -> ~ | H48: =IF(OR('BCO Gioti 2'!C97="Sí",'BCO Gioti 2'!C97="Si"),"✓",IF('BCO Gioti 2'!C97="Parcial","~","")) | I48: =IF(OR('BCO Gioti 3'!C98="Sí",'BCO Gioti 3'!C98="Si"),"✓",IF('BCO Gioti 3'!C98="Parcial","~","")) | J48: =IF(OR('BCO Gioti 4'!C97="Sí",'BCO Gioti 4'!C97="Si"),"✓",IF('BCO Gioti 4'!C97="Parcial","~","")) | K48: =IF(OR(AES!C95="Sí",AES!C95="Si"),"✓",IF(AES!C95="Parcial","~","")) | L48: =IF(OR(XM!C97="Sí",XM!C97="Si"),"✓",IF(XM!C97="Parcial","~","")) | M48: =IF(OR(MEDICARTE!C97="Sí",MEDICARTE!C97="Si"),"✓",IF(MEDICARTE!C97="Parcial","~","")) | N48: =COUNTIF(C48:M48,"✓")+0.5*COUNTIF(C48:M48,"~") -> 3
...

Sheet Graficas
E2: ANÁLISIS VISUAL— MESA DE SERVICIOS DE NUEVA GENERACIÓN | N2: Fecha: 2026/07/03 Clasificación: Interna
E3: Dashboard de madurez · prácticas · dolores · industria vs benchmark · Gen Next
E5: Versión: 1.0
B7: GRÁFICAS POR BLOQUE DE EVALUACIÓN — 11 DIMENSIONES + ④b

Sheet ChartData
A1: TABLA 1 — MADUREZ NUMÉRICA (N0-N5) | K1: HELPERS PARA GRÁFICAS | X1: ① Identificación general — completitud | AA1: ② Nivel de madurez actual | AE1: ③ Prácticas ITIL — score global | AH1: ④ Volumetría y KPIs — FCR/SLA | AM1: ④b Incidentes por categoría — tickets/mes | AP1: ⑤ XLA / DEX — NPS | AS1: ⑥ Dolores críticos — total activo D1–D18 | AV1: ⑦ Rotación y talento — completitud | AY1: ⑧ Tecnología y herramientas — herramientas registradas | BB1: ⑨ Modelo económico — completitud | BE1: ⑩ Visión nuevo servicio — completitud | BH1: ⑪ Casos de éxito — completitud | BK1: RESUMEN PROMEDIO POR DIMENSIÓN | BO1: DOLORES CONSOLIDADOS D1–D18
A2: Mesa | B2: Nivel Madurez (texto) | C2: Madurez Numérica (0-5) | D2: Meta (N3) | K2: Mesa | L2: Madurez | M2: Meta | X2: Mesa | Y2: Completitud | AA2: Mesa | AB2: Madurez | AC2: Meta N3 | AE2: Mesa | AF2: Score ITIL | AH2: Mesa | AI2: FCR | AJ2: SLA | AM2: Mesa | AN2: Tickets categorizados | AP2: Mesa | AQ2: NPS | AS2: Mesa | AT2: Dolores activos D1–D18 | AV2: Mesa | AW2: Completitud | AY2: Mesa | AZ2: Herramientas registradas | BB2: Mesa | BC2: Completitud | BE2: Mesa | BF2: Completitud | BH2: Mesa | BI2: Completitud | BK2: Dimensión | BL2: Promedio | BM2: Meta | BO2: Dolor | BP2: Total ponderado
A3: SURA Cotizadores | B3: ='SURA Cotizadores'!C12 -> N2 | C3: =VALUE(SUBSTITUTE(B3,"N","")) -> 2 | D3: 3 | K3: SURA Cotizadores | L3: =C3 -> 2 | M3: =D3 -> 3 | X3: SURA Cotizadores | Y3: =IFERROR(COUNTA('SURA Cotizadores'!C4:C17)/15,0) -> 0.86666667 | AA3: SURA Cotizadores | AB3: =C3 -> 2 | AC3: =3 -> 3 | AE3: SURA Cotizadores | AF3: =IFERROR((COUNTIF('SURA Cotizadores'!D30:D52,"Sí")+COUNTIF('SURA Cotizadores'!D30:D52,"Si")+0.5*COUNTIF('SURA Cotizadores'!D30:D52,"Parcial"))/(COUNTIF('SURA Cotizadores'!D30:D52,"Sí")+COUNTIF('SURA Cotizadores'!D30:D52,"Si")+COUNTIF('SURA Cotizadores'!D30:D52,"Parcial")+COUNTIF('SURA Cotizadores'!D30:D52,"No")),0) -> 0.52941176 | AH3: SURA Cotizadores | AI3: =IFERROR('SURA Cotizadores'!C62,0) -> N/D | AJ3: =IFERROR('SURA Cotizadores'!C64,0) -> 0.7 | AM3: SURA Cotizadores | AN3: =IFERROR(SUM('SURA Cotizadores'!C73:C81),0) -> 668 | AP3: SURA Cotizadores | AQ3: =IFERROR('SURA Cotizadores'!C85,0) -> 0 | AS3: SURA Cotizadores | AT3: =COUNTIF('SURA Cotizadores'!C95:C112,"Sí")+COUNTIF('SURA Cotizadores'!C95:C112,"Si")+0.5*COUNTIF('SURA Cotizadores'!C95:C112,"Parcial") -> 11 | AV3: SURA Cotizadores | AW3: =IFERROR(COUNTA('SURA Cotizadores'!C119:C126)/8,0) -> 0.5 | AY3: SURA Cotizadores | AZ3: =IFERROR(COUNTA('SURA Cotizadores'!C130:C139),0) -> 4 | BB3: SURA Cotizadores | BC3: =IFERROR(COUNTA('SURA Cotizadores'!C143:C149)/7,0) -> 1 | BE3: SURA Cotizadores | BF3: =IFERROR(COUNTA('SURA Cotizadores'!C153:C161)/9,0) -> 1 | BH3: SURA Cotizadores | BI3: =IFERROR(COUNTA('SURA Cotizadores'!C165:G175)/20,0) -> 0.35 | BK3: ① Identificación general | BL3: =AVERAGE(Y3:Y13) -> 0.64242424 | BM3: =100% -> 1 | BO3: D1: Sí | BP3: =Dashboard!N47 -> 0.5
A4: SURA Digital Venta | B4: =IF('SURA Digital Venta'!C13="","0",'SURA Digital Venta'!C13) -> N2 | C4: =IFERROR(VALUE(RIGHT(B4,1)),0) -> 2 | D4: 3 | K4: SURA Digital Venta | L4: =C4 -> 2 | M4: =D4 -> 3 | X4: SURA Digital Venta | Y4: =IFERROR(COUNTA('SURA Digital Venta'!C4:C18)/15,0) -> 0.86666667 | AA4: SURA Digital Venta | AB4: =IFERROR(VALUE(RIGHT('SURA Digital Venta'!C13,1)),0) -> 2 | AC4: =3 -> 3 | AE4: SURA Digital Venta | AF4: =IFERROR((COUNTIF('SURA Digital Venta'!D31:D53,"Sí")+COUNTIF('SURA Digital Venta'!D31:D53,"Si")+0.5*COUNTIF('SURA Digital Venta'!D31:D53,"Parcial"))/(COUNTIF('SURA Digital Venta'!D31:D53,"Sí")+COUNTIF('SURA Digital Venta'!D31:D53,"Si")+COUNTIF('SURA Digital Venta'!D31:D53,"Parcial")+COUNTIF('SURA Digital Venta'!D31:D53,"No")),0) -> 0.55882353 | AH4: SURA Digital Venta | AI4: =IFERROR('SURA Digital Venta'!C63,0) -> N/D | AJ4: =IFERROR('SURA Digital Venta'!C65,0) -> 0.74 | AM4: SURA Digital Venta | AN4: =IFERROR(SUM('SURA Digital Venta'!C74:C82),0) -> 174 | AP4: SURA Digital Venta | AQ4: =IFERROR('SURA Digital Venta'!C86,0) -> 0 | AS4: SURA Digital Venta | AT4: =COUNTIF('SURA Digital Venta'!C95:C112,"Sí")+COUNTIF('SURA Digital Venta'!C95:C112,"Si")+0.5*COUNTIF('SURA Digital Venta'!C95:C112,"Parcial") -> 11 | AV4: SURA Digital Venta | AW4: =IFERROR(COUNTA('SURA Digital Venta'!C119:C126)/8,0) -> 0.5 | AY4: SURA Digital Venta | AZ4: =IFERROR(COUNTA('SURA Digital Venta'!C130:C139),0) -> 4 | BB4: SURA Digital Venta | BC4: =IFERROR(COUNTA('SURA Digital Venta'!C143:C149)/7,0) -> 1 | BE4: SURA Digital Venta | BF4: =IFERROR(COUNTA('SURA Digital Venta'!C153:C161)/9,0) -> 1 | BH4: SURA Digital Venta | BI4: =IFERROR(COUNTA('SURA Digital Venta'!C165:G175)/20,0) -> 0.35 | BK4: ② Madurez (normalizada) | BL4: =AVERAGE(AB3:AB13)/5 -> 0.27272727 | BM4: =60% -> 0.6 | BO4: D2: Parcial | BP4: =Dashboard!N48 -> 3
A5: SURA Automatizacion | B5: =IF('SURA Automatizacion'!C13="","0",'SURA Automatizacion'!C13) -> N2 | C5: =IFERROR(VALUE(RIGHT(B5,1)),0) -> 2 | D5: 3 | K5: SURA Automatizacion | L5: =C5 -> 2 | M5: =D5 -> 3 | X5: SURA Automatizacion | Y5: =IFERROR(COUNTA('SURA Automatizacion'!C4:C18)/15,0) -> 0.86666667 | AA5: SURA Automatizacion | AB5: =IFERROR(VALUE(RIGHT('SURA Automatizacion'!C13,1)),0) -> 2 | AC5: =3 -> 3 | AE5: SURA Automatizacion | AF5: =IFERROR((COUNTIF('SURA Automatizacion'!D31:D53,"Sí")+COUNTIF('SURA Automatizacion'!D31:D53,"Si")+0.5*COUNTIF('SURA Automatizacion'!D31:D53,"Parcial"))/(COUNTIF('SURA Automatizacion'!D31:D53,"Sí")+COUNTIF('SURA Automatizacion'!D31:D53,"Si")+COUNTIF('SURA Automatizacion'!D31:D53,"Parcial")+COUNTIF('SURA Automatizacion'!D31:D53,"No")),0) -> 0.61764706 | AH5: SURA Automatizacion | AI5: =IFERROR('SURA Automatizacion'!C63,0) -> N/D | AJ5: =IFERROR('SURA Automatizacion'!C65,0) -> 0.98 | AM5: SURA Automatizacion | AN5: =IFERROR(SUM('SURA Automatizacion'!C74:C82),0) -> 512 | AP5: SURA Automatizacion | AQ5: =IFERROR('SURA Automatizacion'!C86,0) -> 0 | AS5: SURA Automatizacion | AT5: =COUNTIF('SURA Automatizacion'!C95:C112,"Sí")+COUNTIF('SURA Automatizacion'!C95:C112,"Si")+0.5*COUNTIF('SURA Automatizacion'!C95:C112,"Parcial") -> 9.5 | AV5: SURA Automatizacion | AW5: =IFERROR(COUNTA('SURA Automatizacion'!C119:C126)/8,0) -> 0.5 | AY5: SURA Automatizacion | AZ5: =IFERROR(COUNTA('SURA Automatizacion'!C130:C139),0) -> 6 | BB5: SURA Automatizacion | BC5: =IFERROR(COUNTA('SURA Automatizacion'!C143:C149)/7,0) -> 1 | BE5: SURA Automatizacion | BF5: =IFERROR(COUNTA('SURA Automatizacion'!C153:C161)/9,0) -> 1 | BH5: SURA Automatizacion | BI5: =IFERROR(COUNTA('SURA Automatizacion'!C165:G175)/20,0) -> 0.35 | BK5: ③ ITIL | BL5: =AVERAGE(AF3:AF13) -> 0.31283422 | BM5: =70% -> 0.7 | BO5: D3: Sí | BP5: =Dashboard!N49 -> 3
A6: SURA Canales Masivos | B6: =IF('SURA Canales Masivos'!C13="","0",'SURA Canales Masivos'!C13) -> N2 | C6: =IFERROR(VALUE(RIGHT(B6,1)),0) -> 2 | D6: 3 | K6: SURA Canales Masivos | L6: =C6 -> 2 | M6: =D6 -> 3 | X6: SURA Canales Masivos | Y6: =IFERROR(COUNTA('SURA Canales Masivos'!C4:C18)/15,0) -> 0.86666667 | AA6: SURA Canales Masivos | AB6: =IFERROR(VALUE(RIGHT('SURA Canales Masivos'!C13,1)),0) -> 2 | AC6: =3 -> 3 | AE6: SURA Canales Masivos | AF6: =IFERROR((COUNTIF('SURA Canales Masivos'!D31:D53,"Sí")+COUNTIF('SURA Canales Masivos'!D31:D53,"Si")+0.5*COUNTIF('SURA Canales Masivos'!D31:D53,"Parcial"))/(COUNTIF('SURA Canales Masivos'!D31:D53,"Sí")+COUNTIF('SURA Canales Masivos'!D31:D53,"Si")+COUNTIF('SURA Canales Masivos'!D31:D53,"Parcial")+COUNTIF('SURA Canales Masivos'!D31:D53,"No")),0) -> 0.58823529 | AH6: SURA Canales Masivos | AI6: =IFERROR('SURA Canales Masivos'!C63,0) -> N/D | AJ6: =IFERROR('SURA Canales Masivos'!C65,0) -> 0.72 | AM6: SURA Canales Masivos | AN6: =IFERROR(SUM('SURA Canales Masivos'!C74:C82),0) -> 171 | AP6: SURA Canales Masivos | AQ6: =IFERROR('SURA Canales Masivos'!C86,0) -> 0 | AS6: SURA Canales Masivos | AT6: =COUNTIF('SURA Canales Masivos'!C95:C112,"Sí")+COUNTIF('SURA Canales Masivos'!C95:C112,"Si")+0.5*COUNTIF('SURA Canales Masivos'!C95:C112,"Parcial") -> 11.5 | AV6: SURA Canales Masivos | AW6: =IFERROR(COUNTA('SURA Canales Masivos'!C119:C126)/8,0) -> 0.5 | AY6: SURA Canales Masivos | AZ6: =IFERROR(COUNTA('SURA Canales Masivos'!C130:C139),0) -> 5 | BB6: SURA Canales Masivos | BC6: =IFERROR(COUNTA('SURA Canales Masivos'!C143:C149)/7,0) -> 1 | BE6: SURA Canales Masivos | BF6: =IFERROR(COUNTA('SURA Canales Masivos'!C153:C161)/9,0) -> 1 | BH6: SURA Canales Masivos | BI6: =IFERROR(COUNTA('SURA Canales Masivos'!C165:G175)/20,0) -> 0.35 | BK6: ④ KPIs FCR/SLA | BL6: =AVERAGE(AI3:AJ13) -> 0.61055556 | BM6: =85% -> 0.85 | BO6: D4: Sí | BP6: =Dashboard!N50 -> 4
A7: BCO Gioti1 | B7: =IF('BCO Gioti 1'!C14="","0",'BCO Gioti 1'!C14) -> N1 | C7: =IFERROR(VALUE(RIGHT(B7,1)),0) -> 1 | D7: 3 | K7: =A7 -> BCO Gioti1 | L7: =C7 -> 1 | M7: =D7 -> 3 | X7: BCO Gioti1 | Y7: =IFERROR(COUNTA('BCO Gioti 1'!C4:C19)/15,0) -> 0.46666667 | AA7: BCO Gioti1 | AB7: =IFERROR(VALUE(RIGHT('BCO Gioti 1'!C14,1)),0) -> 1 | AC7: =3 -> 3 | AE7: BCO Gioti1 | AF7: =IFERROR((COUNTIF('BCO Gioti 1'!D32:D54,"Sí")+COUNTIF('BCO Gioti 1'!D32:D54,"Si")+0.5*COUNTIF('BCO Gioti 1'!D32:D54,"Parcial"))/(COUNTIF('BCO Gioti 1'!D32:D54,"Sí")+COUNTIF('BCO Gioti 1'!D32:D54,"Si")+COUNTIF('BCO Gioti 1'!D32:D54,"Parcial")+COUNTIF('BCO Gioti 1'!D32:D54,"No")),0) -> 0.79411765 | AH7: BCO Gioti1 | AI7: =IFERROR('BCO Gioti 1'!C64,0) -> 0.68 | AJ7: =IFERROR('BCO Gioti 1'!C66,0) -> 0.89 | AM7: BCO Gioti1 | AN7: =IFERROR(SUM('BCO Gioti 1'!C75:C83),0) -> 0 | AP7: BCO Gioti1 | AQ7: =IFERROR('BCO Gioti 1'!C87,0) -> 0 | AS7: BCO Gioti1 | AT7: =COUNTIF('BCO Gioti 1'!C96:C113,"Sí")+COUNTIF('BCO Gioti 1'!C96:C113,"Si")+0.5*COUNTIF('BCO Gioti 1'!C96:C113,"Parcial") -> 1 | AV7: BCO Gioti1 | AW7: =IFERROR(COUNTA('BCO Gioti 1'!C120:C127)/8,0) -> 0 | AY7: BCO Gioti1 | AZ7: =IFERROR(COUNTA('BCO Gioti 1'!C131:C140),0) -> 0 | BB7: BCO Gioti1 | BC7: =IFERROR(COUNTA('BCO Gioti 1'!C144:C150)/7,0) -> 0 | BE7: BCO Gioti1 | BF7: =IFERROR(COUNTA('BCO Gioti 1'!C154:C162)/9,0) -> 0.11111111 | BH7: BCO Gioti1 | BI7: =IFERROR(COUNTA('BCO Gioti 1'!C166:G176)/20,0) -> 0.35 | BK7: ④b Incidentes categorizados | BL7: =IFERROR(AVERAGE(AN3:AN13),0) -> 138.63636 | BM7: =0 -> 0 | BO7: D5: Sí | BP7: =Dashboard!N51 -> 2
A8: BCO Gioti2 | B8: =IF('BCO Gioti 2'!C14="","0",'BCO Gioti 2'!C14) -> N1 | C8: =IFERROR(VALUE(RIGHT(B8,1)),0) -> 1 | D8: 3 | K8: =A8 -> BCO Gioti2 | L8: =C8 -> 1 | M8: =D8 -> 3 | X8: BCO Gioti2 | Y8: =IFERROR(COUNTA('BCO Gioti 2'!C4:C19)/15,0) -> 0.46666667 | AA8: BCO Gioti2 | AB8: =IFERROR(VALUE(RIGHT('BCO Gioti 2'!C14,1)),0) -> 1 | AC8: =3 -> 3 | AE8: BCO Gioti2 | AF8: =IFERROR((COUNTIF('BCO Gioti 2'!D32:D54,"Sí")+COUNTIF('BCO Gioti 2'!D32:D54,"Si")+0.5*COUNTIF('BCO Gioti 2'!D32:D54,"Parcial"))/(COUNTIF('BCO Gioti 2'!D32:D54,"Sí")+COUNTIF('BCO Gioti 2'!D32:D54,"Si")+COUNTIF('BCO Gioti 2'!D32:D54,"Parcial")+COUNTIF('BCO Gioti 2'!D32:D54,"No")),0) -> 0 | AH8: BCO Gioti2 | AI8: =IFERROR('BCO Gioti 2'!C64,0) -> 0.68 | AJ8: =IFERROR('BCO Gioti 2'!C66,0) -> 0.89 | AM8: BCO Gioti2 | AN8: =IFERROR(SUM('BCO Gioti 2'!C75:C83),0) -> 0 | AP8: BCO Gioti2 | AQ8: =IFERROR('BCO Gioti 2'!C87,0) -> 0 | AS8: BCO Gioti2 | AT8: =COUNTIF('BCO Gioti 2'!C96:C113,"Sí")+COUNTIF('BCO Gioti 2'!C96:C113,"Si")+0.5*COUNTIF('BCO Gioti 2'!C96:C113,"Parcial") -> 1 | AV8: BCO Gioti2 | AW8: =IFERROR(COUNTA('BCO Gioti 2'!C120:C127)/8,0) -> 0 | AY8: BCO Gioti2 | AZ8: =IFERROR(COUNTA('BCO Gioti 2'!C131:C140),0) -> 0 | BB8: BCO Gioti2 | BC8: =IFERROR(COUNTA('BCO Gioti 2'!C144:C150)/7,0) -> 0 | BE8: BCO Gioti2 | BF8: =IFERROR(COUNTA('BCO Gioti 2'!C154:C162)/9,0) -> 0.11111111 | BH8: BCO Gioti2 | BI8: =IFERROR(COUNTA('BCO Gioti 2'!C166:G176)/20,0) -> 0.35 | BK8: ⑤ XLA/DEX NPS | BL8: =IFERROR(AVERAGE(AQ3:AQ13)/100,0) -> 0 | BM8: =65% -> 0.65 | BO8: D6: Parcial | BP8: =Dashboard!N52 -> 0.5
A9: BCO Gioti3 | B9: =IF('BCO Gioti 3'!C14="","0",'BCO Gioti 3'!C14) -> N1 | C9: =IFERROR(VALUE(RIGHT(B9,1)),0) -> 1 | D9: 3 | K9: =A9 -> BCO Gioti3 | L9: =C9 -> 1 | M9: =D9 -> 3 | X9: BCO Gioti3 | Y9: =IFERROR(COUNTA('BCO Gioti 3'!C4:C19)/15,0) -> 0.46666667 | AA9: BCO Gioti3 | AB9: =IFERROR(VALUE(RIGHT('BCO Gioti 3'!C14,1)),0) -> 1 | AC9: =3 -> 3 | AE9: BCO Gioti3 | AF9: =IFERROR((COUNTIF('BCO Gioti 3'!D32:D54,"Sí")+COUNTIF('BCO Gioti 3'!D32:D54,"Si")+0.5*COUNTIF('BCO Gioti 3'!D32:D54,"Parcial"))/(COUNTIF('BCO Gioti 3'!D32:D54,"Sí")+COUNTIF('BCO Gioti 3'!D32:D54,"Si")+COUNTIF('BCO Gioti 3'!D32:D54,"Parcial")+COUNTIF('BCO Gioti 3'!D32:D54,"No")),0) -> 0 | AH9: BCO Gioti3 | AI9: =IFERROR('BCO Gioti 3'!C64,0) -> 0.68 | AJ9: =IFERROR('BCO Gioti 3'!C66,0) -> 0.89 | AM9: BCO Gioti3 | AN9: =IFERROR(SUM('BCO Gioti 3'!C75:C83),0) -> 0 | AP9: BCO Gioti3 | AQ9: =IFERROR('BCO Gioti 3'!C87,0) -> 0 | AS9: BCO Gioti3 | AT9: =COUNTIF('BCO Gioti 3'!C97:C114,"Sí")+COUNTIF('BCO Gioti 3'!C97:C114,"Si")+0.5*COUNTIF('BCO Gioti 3'!C97:C114,"Parcial") -> 0 | AV9: BCO Gioti3 | AW9: =IFERROR(COUNTA('BCO Gioti 3'!C121:C128)/8,0) -> 0 | AY9: BCO Gioti3 | AZ9: =IFERROR(COUNTA('BCO Gioti 3'!C132:C141),0) -> 0 | BB9: BCO Gioti3 | BC9: =IFERROR(COUNTA('BCO Gioti 3'!C145:C151)/7,0) -> 0 | BE9: BCO Gioti3 | BF9: =IFERROR(COUNTA('BCO Gioti 3'!C155:C163)/9,0) -> 0.11111111 | BH9: BCO Gioti3 | BI9: =IFERROR(COUNTA('BCO Gioti 3'!C167:G177)/20,0) -> 0.35 | BK9: ⑥ Dolores activos | BL9: =IFERROR(AVERAGE(AT3:AT13)/7,0) -> 0.66233766 | BM9: =0 -> 0 | BO9: D7: No | BP9: =Dashboard!N53 -> 2.5
A10: BCO Gioti4 | B10: =IF('BCO Gioti 4'!C14="","0",'BCO Gioti 4'!C14) -> N1 | C10: =IFERROR(VALUE(RIGHT(B10,1)),0) -> 1 | D10: 3 | K10: =A10 -> BCO Gioti4 | L10: =C10 -> 1 | M10: =D10 -> 3 | X10: BCO Gioti4 | Y10: =IFERROR(COUNTA('BCO Gioti 4'!C4:C19)/15,0) -> 0.46666667 | AA10: BCO Gioti4 | AB10: =IFERROR(VALUE(RIGHT('BCO Gioti 4'!C14,1)),0) -> 1 | AC10: =3 -> 3 | AE10: BCO Gioti4 | AF10: =IFERROR((COUNTIF('BCO Gioti 4'!D32:D54,"Sí")+COUNTIF('BCO Gioti 4'!D32:D54,"Si")+0.5*COUNTIF('BCO Gioti 4'!D32:D54,"Parcial"))/(COUNTIF('BCO Gioti 4'!D32:D54,"Sí")+COUNTIF('BCO Gioti 4'!D32:D54,"Si")+COUNTIF('BCO Gioti 4'!D32:D54,"Parcial")+COUNTIF('BCO Gioti 4'!D32:D54,"No")),0) -> 0 | AH10: BCO Gioti4 | AI10: =IFERROR('BCO Gioti 4'!C64,0) -> 0.68 | AJ10: =IFERROR('BCO Gioti 4'!C66,0) -> 0.89 | AM10: BCO Gioti4 | AN10: =IFERROR(SUM('BCO Gioti 4'!C75:C83),0) -> 0 | AP10: BCO Gioti4 | AQ10: =IFERROR('BCO Gioti 4'!C87,0) -> 0 | AS10: BCO Gioti4 | AT10: =COUNTIF('BCO Gioti 4'!C96:C113,"Sí")+COUNTIF('BCO Gioti 4'!C96:C113,"Si")+0.5*COUNTIF('BCO Gioti 4'!C96:C113,"Parcial") -> 0 | AV10: BCO Gioti4 | AW10: =IFERROR(COUNTA('BCO Gioti 4'!C120:C127)/8,0) -> 0 | AY10: BCO Gioti4 | AZ10: =IFERROR(COUNTA('BCO Gioti 4'!C131:C140),0) -> 0 | BB10: BCO Gioti4 | BC10: =IFERROR(COUNTA('BCO Gioti 4'!C144:C150)/7,0) -> 0 | BE10: BCO Gioti4 | BF10: =IFERROR(COUNTA('BCO Gioti 4'!C154:C162)/9,0) -> 0.11111111 | BH10: BCO Gioti4 | BI10: =IFERROR(COUNTA('BCO Gioti 4'!C166:G176)/20,0) -> 0.35 | BK10: ⑦ Talento | BL10: =AVERAGE(AW3:AW13) -> 0.19318182 | BM10: =100% -> 1 | BO10: D8: | BP10: =Dashboard!N54 -> 3
A11: AES | B11: =IF(AES!C13="","0",AES!C13) -> N1 | C11: =IFERROR(VALUE(RIGHT(B11,1)),0) -> 1 | D11: 3 | K11: =A11 -> AES | L11: =C11 -> 1 | M11: =D11 -> 3 | X11: AES | Y11: =IFERROR(COUNTA(AES!C4:C19)/15,0) -> 1 | AA11: AES | AB11: =IFERROR(VALUE(RIGHT(AES!C13,1)),0) -> 1 | AC11: =3 -> 3 | AE11: AES | AF11: =IFERROR((COUNTIF(AES!D30:D52,"Sí")+COUNTIF(AES!D30:D52,"Si")+0.5*COUNTIF(AES!D30:D52,"Parcial"))/(COUNTIF(AES!D30:D52,"Sí")+COUNTIF(AES!D30:D52,"Si")+COUNTIF(AES!D30:D52,"Parcial")+COUNTIF(AES!D30:D52,"No")),0) -> 0.35294118 | AH11: AES | AI11: =IFERROR(AES!C62,0) -> 0 | AJ11: =IFERROR(AES!C64,0) -> 0 | AM11: AES | AN11: =IFERROR(SUM(AES!C73:C81),0) -> 0 | AP11: AES | AQ11: =IFERROR(AES!C85,0) -> 0 | AS11: AES | AT11: =COUNTIF(AES!C94:C111,"Sí")+COUNTIF(AES!C94:C111,"Si")+0.5*COUNTIF(AES!C94:C111,"Parcial") -> 6 | AV11: AES | AW11: =IFERROR(COUNTA(AES!C118:C125)/8,0) -> 0.125 | AY11: AES | AZ11: =IFERROR(COUNTA(AES!C129:C138),0) -> 2 | BB11: AES | BC11: =IFERROR(COUNTA(AES!C142:C148)/7,0) -> 0.42857143 | BE11: AES | BF11: =IFERROR(COUNTA(AES!C152:C160)/9,0) -> 0.88888889 | BH11: AES | BI11: =IFERROR(COUNTA(AES!C164:G174)/20,0) -> 0.35 | BK11: ⑧ Tecnología | BL11: =IFERROR(AVERAGE(AZ3:AZ13)/10,0) -> 0.19090909 | BM11: =100% -> 1 | BO11: D9: | BP11: =Dashboard!N55 -> 2.5
A12: XM | B12: =IF(XM!C14="","0",XM!C14) -> N1 | C12: =IFERROR(VALUE(RIGHT(B12,1)),0) -> 1 | D12: 3 | K12: =A12 -> XM | L12: =C12 -> 1 | M12: =D12 -> 3 | X12: XM | Y12: =IFERROR(COUNTA(XM!C4:C19)/15,0) -> 0.4 | AA12: XM | AB12: =IFERROR(VALUE(RIGHT(XM!C14,1)),0) -> 1 | AC12: =3 -> 3 | AE12: XM | AF12: =IFERROR((COUNTIF(XM!D32:D54,"Sí")+COUNTIF(XM!D32:D54,"Si")+0.5*COUNTIF(XM!D32:D54,"Parcial"))/(COUNTIF(XM!D32:D54,"Sí")+COUNTIF(XM!D32:D54,"Si")+COUNTIF(XM!D32:D54,"Parcial")+COUNTIF(XM!D32:D54,"No")),0) -> 0 | AH12: XM | AI12: =IFERROR(XM!C64,0) -> 0 | AJ12: =IFERROR(XM!C66,0) -> 0 | AM12: XM | AN12: =IFERROR(SUM(XM!C75:C83),0) -> 0 | AP12: XM | AQ12: =IFERROR(XM!C87,0) -> 0 | AS12: XM | AT12: =COUNTIF(XM!C96:C113,"Sí")+COUNTIF(XM!C96:C113,"Si")+0.5*COUNTIF(XM!C96:C113,"Parcial") -> 0 | AV12: XM | AW12: =IFERROR(COUNTA(XM!C120:C127)/8,0) -> 0 | AY12: XM | AZ12: =IFERROR(COUNTA(XM!C131:C140),0) -> 0 | BB12: XM | BC12: =IFERROR(COUNTA(XM!C144:C150)/7,0) -> 0 | BE12: XM | BF12: =IFERROR(COUNTA(XM!C154:C162)/9,0) -> 0.11111111 | BH12: XM | BI12: =IFERROR(COUNTA(XM!C166:G176)/20,0) -> 0.35 | BK12: ⑨ Económico | BL12: =AVERAGE(BC3:BC13) -> 0.4025974 | BM12: =100% -> 1 | BO12: D10: Sí | BP12: =Dashboard!N56 -> 4
A13: MEDICARTE | B13: =IF(MEDICARTE!C14="","0",MEDICARTE!C14) -> N1 | C13: =IFERROR(VALUE(RIGHT(B13,1)),0) -> 1 | D13: 3 | K13: =A13 -> MEDICARTE | L13: =C13 -> 1 | M13: =D13 -> 3 | X13: MEDICARTE | Y13: =IFERROR(COUNTA(MEDICARTE!C4:C19)/15,0) -> 0.33333333 | AA13: MEDICARTE | AB13: =IFERROR(VALUE(RIGHT(MEDICARTE!C14,1)),0) -> 1 | AC13: =3 -> 3 | AE13: MEDICARTE | AF13: =IFERROR((COUNTIF(MEDICARTE!D32:D54,"Sí")+COUNTIF(MEDICARTE!D32:D54,"Si")+0.5*COUNTIF(MEDICARTE!D32:D54,"Parcial"))/(COUNTIF(MEDICARTE!D32:D54,"Sí")+COUNTIF(MEDICARTE!D32:D54,"Si")+COUNTIF(MEDICARTE!D32:D54,"Parcial")+COUNTIF(MEDICARTE!D32:D54,"No")),0) -> 0 | AH13: MEDICARTE | AI13: =IFERROR(MEDICARTE!C64,0) -> 0.68 | AJ13: =IFERROR(MEDICARTE!C66,0) -> 0.89 | AM13: MEDICARTE | AN13: =IFERROR(SUM(MEDICARTE!C75:C83),0) -> 0 | AP13: MEDICARTE | AQ13: =IFERROR(MEDICARTE!C87,0) -> 0 | AS13: MEDICARTE | AT13: =COUNTIF(MEDICARTE!C96:C113,"Sí")+COUNTIF(MEDICARTE!C96:C113,"Si")+0.5*COUNTIF(MEDICARTE!C96:C113,"Parcial") -> 0 | AV13: MEDICARTE | AW13: =IFERROR(COUNTA(MEDICARTE!C120:C127)/8,0) -> 0 | AY13: MEDICARTE | AZ13: =IFERROR(COUNTA(MEDICARTE!C131:C140),0) -> 0 | BB13: MEDICARTE | BC13: =IFERROR(COUNTA(MEDICARTE!C144:C150)/7,0) -> 0 | BE13: MEDICARTE | BF13: =IFERROR(COUNTA(MEDICARTE!C154:C162)/9,0) -> 0.11111111 | BH13: MEDICARTE | BI13: =IFERROR(COUNTA(MEDICARTE!C166:G176)/20,0) -> 0.35 | BK13: ⑩ Visión | BL13: =AVERAGE(BF3:BF13) -> 0.50505051 | BM13: =100% -> 1 | BO13: D11: | BP13: =Dashboard!N57 -> 2.5
BK14: ⑪ Casos éxito | BL14: =AVERAGE(BI3:BI13) -> 0.35 | BM14: =100% -> 1 | BO14: D12: | BP14: =Dashboard!N58 -> 3
A15: TABLA 2 — SCORE PRÁCTICAS POR DIMENSIÓN (%) | BO15: D13: No | BP15: =Dashboard!N59 -> 3
A16: Mesa | B16: D1 Org/Personas | C16: D2 Info/Tecnología | D16: D3 Socios/Proveed. | E16: D4 Valor/Mejora | F16: Score Global | K16: Mesa | L16: D1 Org/Personas | N16: Mesa | O16: D2 Info/Tecnología | Q16: Mesa | R16: D3 Socios/Proveed. | T16: Mesa | U16: Score Global | BO16: D14: | BP16: =Dashboard!N60 -> 4
A17: SURA Cotizadores | B17: =IFERROR((COUNTIF('SURA Cotizadores'!D30:D34,"Sí")+COUNTIF('SURA Cotizadores'!D30:D34,"Si")+0.5*COUNTIF('SURA Cotizadores'!D30:D34,"Parcial"))/(COUNTIF('SURA Cotizadores'!D30:D34,"Sí")+COUNTIF('SURA Cotizadores'!D30:D34,"Si")+COUNTIF('SURA Cotizadores'!D30:D34,"Parcial")+COUNTIF('SURA Cotizadores'!D30:D34,"No")),0) -> 0.3 | C17: =IFERROR((COUNTIF('SURA Cotizadores'!D37:D43,"Sí")+COUNTIF('SURA Cotizadores'!D37:D43,"Si")+0.5*COUNTIF('SURA Cotizadores'!D37:D43,"Parcial"))/(COUNTIF('SURA Cotizadores'!D37:D43,"Sí")+COUNTIF('SURA Cotizadores'!D37:D43,"Si")+COUNTIF('SURA Cotizadores'!D37:D43,"Parcial")+COUNTIF('SURA Cotizadores'!D37:D43,"No")),0) -> 0.57142857 | D17: =IFERROR((COUNTIF('SURA Cotizadores'!D46:D48,"Sí")+COUNTIF('SURA Cotizadores'!D46:D48,"Si")+0.5*COUNTIF('SURA Cotizadores'!D46:D48,"Parcial"))/(COUNTIF('SURA Cotizadores'!D46:D48,"Sí")+COUNTIF('SURA Cotizadores'!D46:D48,"Si")+COUNTIF('SURA Cotizadores'!D46:D48,"Parcial")+COUNTIF('SURA Cotizadores'!D46:D48,"No")),0) -> 0.83333333 | E17: =IFERROR((COUNTIF('SURA Cotizadores'!D51:D52,"Sí")+COUNTIF('SURA Cotizadores'!D51:D52,"Si")+0.5*COUNTIF('SURA Cotizadores'!D51:D52,"Parcial"))/(COUNTIF('SURA Cotizadores'!D51:D52,"Sí")+COUNTIF('SURA Cotizadores'!D51:D52,"Si")+COUNTIF('SURA Cotizadores'!D51:D52,"Parcial")+COUNTIF('SURA Cotizadores'!D51:D52,"No")),0) -> 0.5 | F17: =IFERROR('SURA Cotizadores'!E54,0) -> 0.52941176 | K17: =A17 -> SURA Cotizadores | L17: =B17 -> 0.3 | N17: =A17 -> SURA Cotizadores | O17: =C17 -> 0.57142857 | Q17: =A17 -> SURA Cotizadores | R17: =D17 -> 0.83333333 | T17: =A17 -> SURA Cotizadores | U17: =F17 -> 0.52941176 | BO17: D15: No | BP17: =Dashboard!N61 -> 2
A18: SURA Digital Venta | B18: =IFERROR((COUNTIF('SURA Digital Venta'!D31:D35,"Sí")+COUNTIF('SURA Digital Venta'!D31:D35,"Si")+0.5*COUNTIF('SURA Digital Venta'!D31:D35,"Parcial"))/(COUNTIF('SURA Digital Venta'!D31:D35,"Sí")+COUNTIF('SURA Digital Venta'!D31:D35,"Si")+COUNTIF('SURA Digital Venta'!D31:D35,"Parcial")+COUNTIF('SURA Digital Venta'!D31:D35,"No")),0) -> 0.4 | C18: =IFERROR((COUNTIF('SURA Digital Venta'!D38:D44,"Sí")+COUNTIF('SURA Digital Venta'!D38:D44,"Si")+0.5*COUNTIF('SURA Digital Venta'!D38:D44,"Parcial"))/(COUNTIF('SURA Digital Venta'!D38:D44,"Sí")+COUNTIF('SURA Digital Venta'!D38:D44,"Si")+COUNTIF('SURA Digital Venta'!D38:D44,"Parcial")+COUNTIF('SURA Digital Venta'!D38:D44,"No")),0) -> 0.57142857 | D18: =IFERROR((COUNTIF('SURA Digital Venta'!D47:D49,"Sí")+COUNTIF('SURA Digital Venta'!D47:D49,"Si")+0.5*COUNTIF('SURA Digital Venta'!D47:D49,"Parcial"))/(COUNTIF('SURA Digital Venta'!D47:D49,"Sí")+COUNTIF('SURA Digital Venta'!D47:D49,"Si")+COUNTIF('SURA Digital Venta'!D47:D49,"Parcial")+COUNTIF('SURA Digital Venta'!D47:D49,"No")),0) -> 0.83333333 | E18: =IFERROR((COUNTIF('SURA Digital Venta'!D52:D53,"Sí")+COUNTIF('SURA Digital Venta'!D52:D53,"Si")+0.5*COUNTIF('SURA Digital Venta'!D52:D53,"Parcial"))/(COUNTIF('SURA Digital Venta'!D52:D53,"Sí")+COUNTIF('SURA Digital Venta'!D52:D53,"Si")+COUNTIF('SURA Digital Venta'!D52:D53,"Parcial")+COUNTIF('SURA Digital Venta'!D52:D53,"No")),0) -> 0.5 | F18: =IFERROR('SURA Digital Venta'!E55,0) -> 0.55882353 | K18: =A18 -> SURA Digital Venta | L18: =B18 -> 0.4 | N18: =A18 -> SURA Digital Venta | O18: =C18 -> 0.57142857 | Q18: =A18 -> SURA Digital Venta | R18: =D18 -> 0.83333333 | T18: =A18 -> SURA Digital Venta | U18: =F18 -> 0.55882353 | BO18: D16: | BP18: =Dashboard!N62 -> 2.5
A19: SURA Automatizacion | B19: =IFERROR((COUNTIF('SURA Automatizacion'!D31:D35,"Sí")+COUNTIF('SURA Automatizacion'!D31:D35,"Si")+0.5*COUNTIF('SURA Automatizacion'!D31:D35,"Parcial"))/(COUNTIF('SURA Automatizacion'!D31:D35,"Sí")+COUNTIF('SURA Automatizacion'!D31:D35,"Si")+COUNTIF('SURA Automatizacion'!D31:D35,"Parcial")+COUNTIF('SURA Automatizacion'!D31:D35,"No")),0) -> 0.4 | C19: =IFERROR((COUNTIF('SURA Automatizacion'!D38:D44,"Sí")+COUNTIF('SURA Automatizacion'!D38:D44,"Si")+0.5*COUNTIF('SURA Automatizacion'!D38:D44,"Parcial"))/(COUNTIF('SURA Automatizacion'!D38:D44,"Sí")+COUNTIF('SURA Automatizacion'!D38:D44,"Si")+COUNTIF('SURA Automatizacion'!D38:D44,"Parcial")+COUNTIF('SURA Automatizacion'!D38:D44,"No")),0) -> 0.71428571 | D19: =IFERROR((COUNTIF('SURA Automatizacion'!D47:D49,"Sí")+COUNTIF('SURA Automatizacion'!D47:D49,"Si")+0.5*COUNTIF('SURA Automatizacion'!D47:D49,"Parcial"))/(COUNTIF('SURA Automatizacion'!D47:D49,"Sí")+COUNTIF('SURA Automatizacion'!D47:D49,"Si")+COUNTIF('SURA Automatizacion'!D47:D49,"Parcial")+COUNTIF('SURA Automatizacion'!D47:D49,"No")),0) -> 0.83333333 | E19: =IFERROR((COUNTIF('SURA Automatizacion'!D52:D53,"Sí")+COUNTIF('SURA Automatizacion'!D52:D53,"Si")+0.5*COUNTIF('SURA Automatizacion'!D52:D53,"Parcial"))/(COUNTIF('SURA Automatizacion'!D52:D53,"Sí")+COUNTIF('SURA Automatizacion'!D52:D53,"Si")+COUNTIF('SURA Automatizacion'!D52:D53,"Parcial")+COUNTIF('SURA Automatizacion'!D52:D53,"No")),0) -> 0.5 | F19: =IFERROR('SURA Automatizacion'!E55,0) -> 0.61764706 | K19: =A19 -> SURA Automatizacion | L19: =B19 -> 0.4 | N19: =A19 -> SURA Automatizacion | O19: =C19 -> 0.71428571 | Q19: =A19 -> SURA Automatizacion | R19: =D19 -> 0.83333333 | T19: =A19 -> SURA Automatizacion | U19: =F19 -> 0.61764706 | BO19: D17: | BP19: =Dashboard!N63 -> 5.5
A20: SURA Canales Masivos | B20: =IFERROR((COUNTIF('SURA Canales Masivos'!D31:D35,"Sí")+COUNTIF('SURA Canales Masivos'!D31:D35,"Si")+0.5*COUNTIF('SURA Canales Masivos'!D31:D35,"Parcial"))/(COUNTIF('SURA Canales Masivos'!D31:D35,"Sí")+COUNTIF('SURA Canales Masivos'!D31:D35,"Si")+COUNTIF('SURA Canales Masivos'!D31:D35,"Parcial")+COUNTIF('SURA Canales Masivos'!D31:D35,"No")),0) -> 0.4 | C20: =IFERROR((COUNTIF('SURA Canales Masivos'!D38:D44,"Sí")+COUNTIF('SURA Canales Masivos'!D38:D44,"Si")+0.5*COUNTIF('SURA Canales Masivos'!D38:D44,"Parcial"))/(COUNTIF('SURA Canales Masivos'!D38:D44,"Sí")+COUNTIF('SURA Canales Masivos'!D38:D44,"Si")+COUNTIF('SURA Canales Masivos'!D38:D44,"Parcial")+COUNTIF('SURA Canales Masivos'!D38:D44,"No")),0) -> 0.64285714 | D20: =IFERROR((COUNTIF('SURA Canales Masivos'!D47:D49,"Sí")+COUNTIF('SURA Canales Masivos'!D47:D49,"Si")+0.5*COUNTIF('SURA Canales Masivos'!D47:D49,"Parcial"))/(COUNTIF('SURA Canales Masivos'!D47:D49,"Sí")+COUNTIF('SURA Canales Masivos'!D47:D49,"Si")+COUNTIF('SURA Canales Masivos'!D47:D49,"Parcial")+COUNTIF('SURA Canales Masivos'!D47:D49,"No")),0) -> 0.83333333 | E20: =IFERROR((COUNTIF('SURA Canales Masivos'!D52:D53,"Sí")+COUNTIF('SURA Canales Masivos'!D52:D53,"Si")+0.5*COUNTIF('SURA Canales Masivos'!D52:D53,"Parcial"))/(COUNTIF('SURA Canales Masivos'!D52:D53,"Sí")+COUNTIF('SURA Canales Masivos'!D52:D53,"Si")+COUNTIF('SURA Canales Masivos'!D52:D53,"Parcial")+COUNTIF('SURA Canales Masivos'!D52:D53,"No")),0) -> 0.5 | F20: =IFERROR('SURA Canales Masivos'!E55,0) -> 0.58823529 | K20: =A20 -> SURA Canales Masivos | L20: =B20 -> 0.4 | N20: =A20 -> SURA Canales Masivos | O20: =C20 -> 0.64285714 | Q20: =A20 -> SURA Canales Masivos | R20: =D20 -> 0.83333333 | T20: =A20 -> SURA Canales Masivos | U20: =F20 -> 0.58823529 | BO20: D18: Sí | BP20: =Dashboard!N64 -> 3.5
A21: BCO Gioti1 | B21: =IFERROR((COUNTIF('BCO Gioti 1'!D32:D36,"Sí")+COUNTIF('BCO Gioti 1'!D32:D36,"Si")+0.5*COUNTIF('BCO Gioti 1'!D32:D36,"Parcial"))/(COUNTIF('BCO Gioti 1'!D32:D36,"Sí")+COUNTIF('BCO Gioti 1'!D32:D36,"Si")+COUNTIF('BCO Gioti 1'!D32:D36,"Parcial")+COUNTIF('BCO Gioti 1'!D32:D36,"No")),0) -> 0.8 | C21: =IFERROR((COUNTIF('BCO Gioti 1'!D39:D45,"Sí")+COUNTIF('BCO Gioti 1'!D39:D45,"Si")+0.5*COUNTIF('BCO Gioti 1'!D39:D45,"Parcial"))/(COUNTIF('BCO Gioti 1'!D39:D45,"Sí")+COUNTIF('BCO Gioti 1'!D39:D45,"Si")+COUNTIF('BCO Gioti 1'!D39:D45,"Parcial")+COUNTIF('BCO Gioti 1'!D39:D45,"No")),0) -> 0.78571429 | D21: =IFERROR((COUNTIF('BCO Gioti 1'!D48:D50,"Sí")+COUNTIF('BCO Gioti 1'!D48:D50,"Si")+0.5*COUNTIF('BCO Gioti 1'!D48:D50,"Parcial"))/(COUNTIF('BCO Gioti 1'!D48:D50,"Sí")+COUNTIF('BCO Gioti 1'!D48:D50,"Si")+COUNTIF('BCO Gioti 1'!D48:D50,"Parcial")+COUNTIF('BCO Gioti 1'!D48:D50,"No")),0) -> 0.83333333 | E21: =IFERROR((COUNTIF('BCO Gioti 1'!D53:D54,"Sí")+COUNTIF('BCO Gioti 1'!D53:D54,"Si")+0.5*COUNTIF('BCO Gioti 1'!D53:D54,"Parcial"))/(COUNTIF('BCO Gioti 1'!D53:D54,"Sí")+COUNTIF('BCO Gioti 1'!D53:D54,"Si")+COUNTIF('BCO Gioti 1'!D53:D54,"Parcial")+COUNTIF('BCO Gioti 1'!D53:D54,"No")),0) -> 0.75 | F21: =IFERROR('BCO Gioti 1'!E56,0) -> 0.79411765 | K21: =A21 -> BCO Gioti1 | L21: =B21 -> 0.8 | N21: =A21 -> BCO Gioti1 | O21: =C21 -> 0.78571429 | Q21: =A21 -> BCO Gioti1 | R21: =D21 -> 0.83333333 | T21: =A21 -> BCO Gioti1 | U21: =F21 -> 0.79411765
A22: BCO Gioti2 | B22: =IFERROR((COUNTIF('BCO Gioti 2'!D32:D36,"Sí")+COUNTIF('BCO Gioti 2'!D32:D36,"Si")+0.5*COUNTIF('BCO Gioti 2'!D32:D36,"Parcial"))/(COUNTIF('BCO Gioti 2'!D32:D36,"Sí")+COUNTIF('BCO Gioti 2'!D32:D36,"Si")+COUNTIF('BCO Gioti 2'!D32:D36,"Parcial")+COUNTIF('BCO Gioti 2'!D32:D36,"No")),0) -> 0 | C22: =IFERROR((COUNTIF('BCO Gioti 2'!D39:D45,"Sí")+COUNTIF('BCO Gioti 2'!D39:D45,"Si")+0.5*COUNTIF('BCO Gioti 2'!D39:D45,"Parcial"))/(COUNTIF('BCO Gioti 2'!D39:D45,"Sí")+COUNTIF('BCO Gioti 2'!D39:D45,"Si")+COUNTIF('BCO Gioti 2'!D39:D45,"Parcial")+COUNTIF('BCO Gioti 2'!D39:D45,"No")),0) -> 0 | D22: =IFERROR((COUNTIF('BCO Gioti 2'!D48:D50,"Sí")+COUNTIF('BCO Gioti 2'!D48:D50,"Si")+0.5*COUNTIF('BCO Gioti 2'!D48:D50,"Parcial"))/(COUNTIF('BCO Gioti 2'!D48:D50,"Sí")+COUNTIF('BCO Gioti 2'!D48:D50,"Si")+COUNTIF('BCO Gioti 2'!D48:D50,"Parcial")+COUNTIF('BCO Gioti 2'!D48:D50,"No")),0) -> 0 | E22: =IFERROR((COUNTIF('BCO Gioti 2'!D53:D54,"Sí")+COUNTIF('BCO Gioti 2'!D53:D54,"Si")+0.5*COUNTIF('BCO Gioti 2'!D53:D54,"Parcial"))/(COUNTIF('BCO Gioti 2'!D53:D54,"Sí")+COUNTIF('BCO Gioti 2'!D53:D54,"Si")+COUNTIF('BCO Gioti 2'!D53:D54,"Parcial")+COUNTIF('BCO Gioti 2'!D53:D54,"No")),0) -> 0 | F22: =IFERROR('BCO Gioti 2'!E56,0) -> 0 | K22: =A22 -> BCO Gioti2 | L22: =B22 -> 0 | N22: =A22 -> BCO Gioti2 | O22: =C22 -> 0 | Q22: =A22 -> BCO Gioti2 | R22: =D22 -> 0 | T22: =A22 -> BCO Gioti2 | U22: =F22 -> 0
A23: BCO Gioti3 | B23: =IFERROR((COUNTIF('BCO Gioti 3'!D32:D36,"Sí")+COUNTIF('BCO Gioti 3'!D32:D36,"Si")+0.5*COUNTIF('BCO Gioti 3'!D32:D36,"Parcial"))/(COUNTIF('BCO Gioti 3'!D32:D36,"Sí")+COUNTIF('BCO Gioti 3'!D32:D36,"Si")+COUNTIF('BCO Gioti 3'!D32:D36,"Parcial")+COUNTIF('BCO Gioti 3'!D32:D36,"No")),0) -> 0 | C23: =IFERROR((COUNTIF('BCO Gioti 3'!D39:D45,"Sí")+COUNTIF('BCO Gioti 3'!D39:D45,"Si")+0.5*COUNTIF('BCO Gioti 3'!D39:D45,"Parcial"))/(COUNTIF('BCO Gioti 3'!D39:D45,"Sí")+COUNTIF('BCO Gioti 3'!D39:D45,"Si")+COUNTIF('BCO Gioti 3'!D39:D45,"Parcial")+COUNTIF('BCO Gioti 3'!D39:D45,"No")),0) -> 0 | D23: =IFERROR((COUNTIF('BCO Gioti 3'!D48:D50,"Sí")+COUNTIF('BCO Gioti 3'!D48:D50,"Si")+0.5*COUNTIF('BCO Gioti 3'!D48:D50,"Parcial"))/(COUNTIF('BCO Gioti 3'!D48:D50,"Sí")+COUNTIF('BCO Gioti 3'!D48:D50,"Si")+COUNTIF('BCO Gioti 3'!D48:D50,"Parcial")+COUNTIF('BCO Gioti 3'!D48:D50,"No")),0) -> 0 | E23: =IFERROR((COUNTIF('BCO Gioti 3'!D53:D54,"Sí")+COUNTIF('BCO Gioti 3'!D53:D54,"Si")+0.5*COUNTIF('BCO Gioti 3'!D53:D54,"Parcial"))/(COUNTIF('BCO Gioti 3'!D53:D54,"Sí")+COUNTIF('BCO Gioti 3'!D53:D54,"Si")+COUNTIF('BCO Gioti 3'!D53:D54,"Parcial")+COUNTIF('BCO Gioti 3'!D53:D54,"No")),0) -> 0 | F23: =IFERROR('BCO Gioti 3'!E56,0) -> 0 | K23: =A23 -> BCO Gioti3 | L23: =B23 -> 0 | N23: =A23 -> BCO Gioti3 | O23: =C23 -> 0 | Q23: =A23 -> BCO Gioti3 | R23: =D23 -> 0 | T23: =A23 -> BCO Gioti3 | U23: =F23 -> 0
A24: BCO Gioti4 | B24: =IFERROR((COUNTIF('BCO Gioti 4'!D32:D36,"Sí")+COUNTIF('BCO Gioti 4'!D32:D36,"Si")+0.5*COUNTIF('BCO Gioti 4'!D32:D36,"Parcial"))/(COUNTIF('BCO Gioti 4'!D32:D36,"Sí")+COUNTIF('BCO Gioti 4'!D32:D36,"Si")+COUNTIF('BCO Gioti 4'!D32:D36,"Parcial")+COUNTIF('BCO Gioti 4'!D32:D36,"No")),0) -> 0 | C24: =IFERROR((COUNTIF('BCO Gioti 4'!D39:D45,"Sí")+COUNTIF('BCO Gioti 4'!D39:D45,"Si")+0.5*COUNTIF('BCO Gioti 4'!D39:D45,"Parcial"))/(COUNTIF('BCO Gioti 4'!D39:D45,"Sí")+COUNTIF('BCO Gioti 4'!D39:D45,"Si")+COUNTIF('BCO Gioti 4'!D39:D45,"Parcial")+COUNTIF('BCO Gioti 4'!D39:D45,"No")),0) -> 0 | D24: =IFERROR((COUNTIF('BCO Gioti 4'!D48:D50,"Sí")+COUNTIF('BCO Gioti 4'!D48:D50,"Si")+0.5*COUNTIF('BCO Gioti 4'!D48:D50,"Parcial"))/(COUNTIF('BCO Gioti 4'!D48:D50,"Sí")+COUNTIF('BCO Gioti 4'!D48:D50,"Si")+COUNTIF('BCO Gioti 4'!D48:D50,"Parcial")+COUNTIF('BCO Gioti 4'!D48:D50,"No")),0) -> 0 | E24: =IFERROR((COUNTIF('BCO Gioti 4'!D53:D54,"Sí")+COUNTIF('BCO Gioti 4'!D53:D54,"Si")+0.5*COUNTIF('BCO Gioti 4'!D53:D54,"Parcial"))/(COUNTIF('BCO Gioti 4'!D53:D54,"Sí")+COUNTIF('BCO Gioti 4'!D53:D54,"Si")+COUNTIF('BCO Gioti 4'!D53:D54,"Parcial")+COUNTIF('BCO Gioti 4'!D53:D54,"No")),0) -> 0 | F24: =IFERROR('BCO Gioti 4'!E56,0) -> 0 | K24: =A24 -> BCO Gioti4 | L24: =B24 -> 0 | N24: =A24 -> BCO Gioti4 | O24: =C24 -> 0 | Q24: =A24 -> BCO Gioti4 | R24: =D24 -> 0 | T24: =A24 -> BCO Gioti4 | U24: =F24 -> 0
A25: AES | B25: =IFERROR((COUNTIF(AES!D30:D34,"Sí")+COUNTIF(AES!D30:D34,"Si")+0.5*COUNTIF(AES!D30:D34,"Parcial"))/(COUNTIF(AES!D30:D34,"Sí")+COUNTIF(AES!D30:D34,"Si")+COUNTIF(AES!D30:D34,"Parcial")+COUNTIF(AES!D30:D34,"No")),0) -> 0.4 | C25: =IFERROR((COUNTIF(AES!D37:D43,"Sí")+COUNTIF(AES!D37:D43,"Si")+0.5*COUNTIF(AES!D37:D43,"Parcial"))/(COUNTIF(AES!D37:D43,"Sí")+COUNTIF(AES!D37:D43,"Si")+COUNTIF(AES!D37:D43,"Parcial")+COUNTIF(AES!D37:D43,"No")),0) -> 0.42857143 | D25: =IFERROR((COUNTIF(AES!D46:D48,"Sí")+COUNTIF(AES!D46:D48,"Si")+0.5*COUNTIF(AES!D46:D48,"Parcial"))/(COUNTIF(AES!D46:D48,"Sí")+COUNTIF(AES!D46:D48,"Si")+COUNTIF(AES!D46:D48,"Parcial")+COUNTIF(AES!D46:D48,"No")),0) -> 0.16666667 | E25: =IFERROR((COUNTIF(AES!D51:D52,"Sí")+COUNTIF(AES!D51:D52,"Si")+0.5*COUNTIF(AES!D51:D52,"Parcial"))/(COUNTIF(AES!D51:D52,"Sí")+COUNTIF(AES!D51:D52,"Si")+COUNTIF(AES!D51:D52,"Parcial")+COUNTIF(AES!D51:D52,"No")),0) -> 0.25 | F25: =IFERROR(AES!E54,0) -> 0.29411765 | K25: =A25 -> AES | L25: =B25 -> 0.4 | N25: =A25 -> AES | O25: =C25 -> 0.42857143 | Q25: =A25 -> AES | R25: =D25 -> 0.16666667 | T25: =A25 -> AES | U25: =F25 -> 0.29411765
A26: XM | B26: =IFERROR((COUNTIF(XM!D32:D36,"Sí")+COUNTIF(XM!D32:D36,"Si")+0.5*COUNTIF(XM!D32:D36,"Parcial"))/(COUNTIF(XM!D32:D36,"Sí")+COUNTIF(XM!D32:D36,"Si")+COUNTIF(XM!D32:D36,"Parcial")+COUNTIF(XM!D32:D36,"No")),0) -> 0 | C26: =IFERROR((COUNTIF(XM!D39:D45,"Sí")+COUNTIF(XM!D39:D45,"Si")+0.5*COUNTIF(XM!D39:D45,"Parcial"))/(COUNTIF(XM!D39:D45,"Sí")+COUNTIF(XM!D39:D45,"Si")+COUNTIF(XM!D39:D45,"Parcial")+COUNTIF(XM!D39:D45,"No")),0) -> 0 | D26: =IFERROR((COUNTIF(XM!D48:D50,"Sí")+COUNTIF(XM!D48:D50,"Si")+0.5*COUNTIF(XM!D48:D50,"Parcial"))/(COUNTIF(XM!D48:D50,"Sí")+COUNTIF(XM!D48:D50,"Si")+COUNTIF(XM!D48:D50,"Parcial")+COUNTIF(XM!D48:D50,"No")),0) -> 0 | E26: =IFERROR((COUNTIF(XM!D53:D54,"Sí")+COUNTIF(XM!D53:D54,"Si")+0.5*COUNTIF(XM!D53:D54,"Parcial"))/(COUNTIF(XM!D53:D54,"Sí")+COUNTIF(XM!D53:D54,"Si")+COUNTIF(XM!D53:D54,"Parcial")+COUNTIF(XM!D53:D54,"No")),0) -> 0 | F26: =IFERROR(XM!E56,0) -> 0 | K26: =A26 -> XM | L26: =B26 -> 0 | N26: =A26 -> XM | O26: =C26 -> 0 | Q26: =A26 -> XM | R26: =D26 -> 0 | T26: =A26 -> XM | U26: =F26 -> 0
